Workbook
Name pricetable: #REF!
Name pricetable: #REF!
Name pricetable: #REF!
Name pricetable: #REF!
Name pricetable: #REF!
Name pricetable: #REF!

Sheet shipper master
A1: 1 | B1: S/CODE | C1: SHIPPER NAME
A2: =A1+1 -> 2 | B2: SHIPPER | C2: SHUNYA CO., LTD.
A3: =A2+1 -> 3 | B3: SHIPPER ADDRESS 1 | C3: KENSHIN BLDG., 1F, 1-22-10 DOUGENZAKA,
A4: =A3+1 -> 4 | B4: SHIPPER ADDRESS 2 | C4: SHIBUYA-KU 150-0043
A5: =A4+1 -> 5 | B5: SHIPPER ADDRESS 3 | C5: TEL : +81(0)3-5459-1177
A6: =A5+1 -> 6 | B6: TEL
A7: =A6+1 -> 7 | B7: FAX
A8: =A7+1 -> 8 | B8: ATTN OR VAT NO.
A9: =A8+1 -> 9 | B9: BUYER | C9: VIVAN GARMENTS VIET NAM COMPANY LIMITED
A10: =A9+1 -> 10 | B10: BUYER ADDRESS1 | C10: No.10 , D17 Street , Sai Gon South Residential Area
A11: =A10+1 -> 11 | B11: BUYER ADDRESS2 | C11: Hamlet 3 , Long Hau Commune , Can Giuoc District,
A12: =A11+1 -> 12 | B12: BUYER ADDRESS3 | C12: Long An Province , VietNam
A13: =A12+1 -> 13 | B13: TEL/FAX | C13: TEL : : ( 084 ) 097 22 00 798 ATTN : MR. TUAN
A14: =A13+1 -> 14 | B14: ATTN
A15: =A14+1 -> 15 | B15: CONSIGNEE : | C15: - SAME AS BUYER -
A16: =A15+1 -> 16 | B16: CONSIGNEE ADDRESS1
A17: =A16+1 -> 17 | B17: CONSIGNEE ADDRESS2
A18: =A17+1 -> 18 | B18: CONSIGNEE ADDRESS3
A19: =A18+1 -> 19 | B19: TEL
A20: =A19+1 -> 20 | B20: FAX
A21: =A20+1 -> 21 | B21: ATTN | C21: NO COMMERCIAL
A22: =A21+1 -> 22 | B22: PAYMENT 1
A23: =A22+1 -> 23 | B23: PAYMENT 2
A24: =A23+1 -> 24 | B24: SHIPPER PER | C24: AIRCRAFT
A25: =A24+1 -> 25 | B25: INVOICE DATE | C25: May,26 2022
A26: =A25+1 -> 26 | B26: INVOICE NO. | C26: SY-430518-VT-DD-01
A27: =A26+1 -> 27 | B27: CONTRACT NO. | C27: =C26 -> SY-430518-VT-DD-01
A28: =A27+1 -> 28 | B28: CONTRACT DATE
A29: =A28+1 -> 29 | B29: ORDER DATE
A30: =A29+1 -> 30 | B30: ORDER NO.
A31: =A30+1 -> 31 | B31: L/C DATE
A32: =A31+1 -> 32 | B32: FROM | C32: TOKYO, JAPAN
A33: =A32+1 -> 33 | B33: TO | C33: HOCHIMINH-CITY, VIETNAM
A34: =A33+1 -> 34 | B34: VIA
A35: =A34+1 -> 35 | B35: SHIPPING TERMS | C35: F.O.B. TOKYO IN YEN
A36: =A35+1 -> 36 | B36: TITTLE 1 | C36: FABRIC & PARTS FOR WEAR
A37: =A36+1 -> 37 | B37: TITTLE 2
A38: =A37+1 -> 38 | B38: ATTACHE | C38: - DETAILS AS PER ATTACHED SHEET -
A39: =A38+1 -> 39 | B39: C/NO.
A40: =A39+1 -> 40 | B40: STYLE NO.
...

Sheet invoice
A1: INVOICE
A2: ='shipper master'!C2 -> SHUNYA CO., LTD.
A3: ='shipper master'!C3 -> KENSHIN BLDG., 1F, 1-22-10 DOUGENZAKA,
A4: ='shipper master'!C4 -> SHIBUYA-KU 150-0043 | K4: ='shipper master'!C6 -> 0
A5: ='shipper master'!C5 -> TEL : +81(0)3-5459-1177 | K5: ='shipper master'!C7 -> 0
A6: IMPORTER | E6: INVOICE NO. | K6: CASE MARK
A7: ='shipper master'!C9 -> VIVAN GARMENTS VIET NAM COMPANY LIMITED | E7: ='shipper master'!C26 -> SY-430518-VT-DD-01
A8: ='shipper master'!C10 -> No.10 , D17 Street , Sai Gon South Residential Area | E8: INVOICE DATE | K8: ='[1]shipper master'!C49 -> SYVI-011201-VT-DD-01
A9: ='shipper master'!C11 -> Hamlet 3 , Long Hau Commune , Can Giuoc District, | E9: ='shipper master'!C25 -> May,26 2022 | K9: ='[1]shipper master'!C50 -> VIVAN GARMENTS VIET NAM
A10: ='shipper master'!C12 -> Long An Province , VietNam | E10: CONTRACT NO. | K10: ='[1]shipper master'!C51 -> COMPANY LIMITED
A11: ='shipper master'!C13 -> TEL : : ( 084 ) 097 22 00 798 ATTN : MR. TUAN | E11: ='shipper master'!C27 -> SY-430518-VT-DD-01 | K11: ='[1]shipper master'!C52 -> HOCHIMINH-CITY, VIETNAM
A12: CONSIGNEE | E12: ORDER NO. | K12: C/NO. 1-
A13: ='shipper master'!C15 -> - SAME AS BUYER - | E13: ='shipper master'!C30 -> 0 | K13: ='shipper master'!C54 -> MADE IN JAPAN
A14: ='shipper master'!C16 -> 0 | E14: ORDER DATE
A15: ='shipper master'!C17 -> 0 | E15: ='shipper master'!C29 -> 0
A16: ='shipper master'!C18 -> 0 | E16: L/C NO.
A17: ='shipper master'!C19 -> 0
A18: PAYMENT METHOD
A19: ='shipper master'!C21 -> NO COMMERCIAL
A20: SHIPPED PER | C20: FROM | E20: TO | K20: VIA
A21: ='shipper master'!C24 -> AIRCRAFT | C21: ='shipper master'!C32 -> TOKYO, JAPAN | F21: ='shipper master'!C33 -> HOCHIMINH-CITY, VIETNAM
A22: C/NO. | B22: ART NO. | C22: DESCRIPTION OF GOODS | D22: COLOR | G22: SIZE | J22: Q'TY | K22: U/PRICE | L22: AMOUNT
B24: ='shipper master'!C36 -> FABRIC & PARTS FOR WEAR | K24: ='shipper master'!C48 -> F.O.B. TOKYO IN YEN
B26: ='shipper master'!C37 -> 0
B28: ='shipper master'!C38 -> - DETAILS AS PER ATTACHED SHEET - | J28: =NARITA!E23+'NARITA (2)'!E33 -> 1034 | K28: =NARITA!F23 -> M. | L28: =NARITA!H23+'NARITA (2)'!H33 -> 322280
J29: ='NARITA (2)'!E34 -> 709 | K29: =NARITA!F24 -> PCS. | L29: ='NARITA (2)'!H34 -> 11050
B32: TOTAL : | C32: =J28 -> 1034 | D32: M. | E32: =J29 -> 709 | H32: =H29 -> 0 | I32: PCS | J32: =J30 -> 0 | L32: =SUM(L27:L30) -> 333330
A35: ='shipper master'!C63 -> " THESE GOODS WILL BE RETURN TO JAPAN | H35: " NO COMMER VALUE | J35: " NO COMMERCIAL VALUE
A36: ='shipper master'!C64 -> AFTER MANUFACTURED AT VIET NAM " | H36: VALUE FOR CUSTOMS PURPOSE ONLY " | J36: VALUE FOR CUSTOMS PURPOSE ONLY "
C37: ='shipper master'!C58 -> 0
A38: ='shipper master'!C60 -> COUNTRY OF ORIGIN : JAPAN
A40: TOTAL CARTONS : | C40: 8CARTONS
A41: TOTAL GROSS WEIGHT :

Sheet case mark (2)
A2: ='[1]shipper master'!C49 -> SYVI-011201-VT-DD-01 | I2: ='[1]shipper master'!C49 -> SYVI-011201-VT-DD-01
A3: ='[1]shipper master'!C50 -> VIVAN GARMENTS VIET NAM | I3: ='[1]shipper master'!C50 -> VIVAN GARMENTS VIET NAM
A4: ='[1]shipper master'!C51 -> COMPANY LIMITED | I4: ='[1]shipper master'!C51 -> COMPANY LIMITED
A5: ='[1]shipper master'!C52 -> HOCHIMINH-CITY, VIETNAM | I5: ='[1]shipper master'!C52 -> HOCHIMINH-CITY, VIETNAM
A6: C/NO. | C6: 1 | I6: C/NO. | K6: 2
A7: ='[1]shipper master'!C54 -> MADE IN JAPAN | I7: ='[1]shipper master'!C54 -> MADE IN JAPAN
A13: ='[1]shipper master'!C49 -> SYVI-011201-VT-DD-01 | I13: ='[1]shipper master'!C49 -> SYVI-011201-VT-DD-01
A14: ='[1]shipper master'!C50 -> VIVAN GARMENTS VIET NAM | I14: ='[1]shipper master'!C50 -> VIVAN GARMENTS VIET NAM
A15: ='[1]shipper master'!C51 -> COMPANY LIMITED | I15: ='[1]shipper master'!C51 -> COMPANY LIMITED
A16: ='[1]shipper master'!C52 -> HOCHIMINH-CITY, VIETNAM | I16: ='[1]shipper master'!C52 -> HOCHIMINH-CITY, VIETNAM
A17: C/NO. | C17: 3 | I17: C/NO. | K17: 4
A18: ='[1]shipper master'!C54 -> MADE IN JAPAN | I18: ='[1]shipper master'!C54 -> MADE IN JAPAN

Sheet NARITA
A2: - ATTACHED SHEET -
A4: C/NO. | B4: ART NO. | C4: COLOR | D4: DESCRIPTION OF GOODS | E4: Q'TY | F4: U/PRICE | H4: AMOUNT | I4: 佐川伝票・明細 | J4: 搬入日 | K4: 伝票NO | L4: 搬入内容 | M4: 数量 | N4: 箱数
B6: (H.S. CODE) | D6: ='[2]shipper master'!C36 -> FABRIC & PARTS FOR WEAR | G6: ='[2]shipper master'!C48 -> F.O.B. TOKYO IN YEN
D7: MADE IN JAPAN
D8: STYLE、22SY-65
A9: 1-3 | B9: SB2030 | C9: C/#5 BLACK | D9: WOVEN FABRIC | E9: 158 | F9: M. | G9: 980 | H9: =E9*G9 -> 154840 | I9: 22051837 | J9: 45063
B10: WOVEN FABRIC | D10: cotton60% polyester40%
B11: ツイル生地 後染め 短繊維 | D11: WIDTH:128CM (260ｇ/㎡ )
D13: STYLE、22SY-53
A14: 4 | B14: M-6543ST | C14: c/#018 BEIGE | D14: WOVEN FABRIC | E14: 40 | F14: M. | G14: 1030 | H14: =E14*G14 -> 41200 | I14: 22051479
B15: WOVEN FABRIC | D15: NYLON100% | J15: 4/28
B16: 後染め 長繊維 | D16: WIDTH:115CM (370ｇ/㎡ )
D18: STYLE、22SY-66
A19: 5 | B19: TAN-ST23150 | C19: C/#0 INDIGO | D19: WOVEN FABRIC | E19: 60 | F19: M. | G19: 1030 | H19: =E19*G19 -> 61800 | I19: 22051735
B20: WOVEN FABRIC | D20: cotton70% polyester30% | J20: 5/15
B21: デニム生地 先染め 短繊維 | D21: WIDTH:118CM (208ｇ/㎡ )
B23: TOTAL : | C23: 5CARTONS | E23: =SUMIF($F$9:$F$21,"M.",$E$9:$E$21) -> 258 | F23: M. | H23: =SUMIF($F$9:$F$20,"M.",$H$9:$H$20) -> 257840
E24: =SUMIF($F$9:$F$12,"PCS.",$E$9:$E$12) -> 0 | F24: PCS. | H24: =SUMIF($F$9:$F$12,"PCS.",$H$9:$H$12) -> 0
H25: =SUM(H23:H24) -> 257840

Sheet NARITA (2)
A2: - ATTACHED SHEET -
A4: C/NO. | B4: ART NO. | C4: COLOR | D4: DESCRIPTION OF GOODS | E4: Q'TY | F4: U/PRICE | H4: AMOUNT | I4: 佐川伝票・明細 | J4: 搬入日 | K4: 伝票NO | L4: 搬入内容 | M4: 数量 | N4: 箱数
B6: (H.S. CODE) | D6: ='[2]shipper master'!C36 -> FABRIC & PARTS FOR WEAR | G6: ='[2]shipper master'!C48 -> F.O.B. TOKYO IN YEN
D7: MADE IN JAPAN
D9: STYLE、22SY-74
A10: 6 | B10: pattern paper | E10: 3 | F10: PCS. | G10: 700 | H10: =E10*G10 -> 2100 | I10: 22051578 | J10: 45055
B11: WOVEN NEME | C11: c/#BLACK | E11: 250 | F11: PCS. | G11: 3 | H11: =E11*G11 -> 750
B12: packaging bag | E12: 250 | F12: PCS. | G12: 10 | H12: =E12*G12 -> 2500
B13: men's pants | E13: 1 | F13: PCS. | G13: 1000 | H13: =E13*G13 -> 1000
D16: STYLE、22SY-74
A17: 7 | B17: pattern paper | E17: 3 | F17: PCS. | G17: 700 | H17: =E17*G17 -> 2100
B18: WOVEN NEME | C18: c/#BLUE | E18: 200 | F18: PCS. | G18: 3 | H18: =E18*G18 -> 600
B19: men's pants | C19: c/#BLACK | E19: 1 | F19: PCS. | G19: 1000 | H19: =E19*G19 -> 1000 | I19: 22051874 | J19: 45064
B20: men's jacket | C20: c/#BEIGE | E20: 1 | F20: PCS. | G20: 1000 | H20: =E20*G20 -> 1000
D23: STYLE、22SY-74
B24: B204 | C24: W | D24: ELASTIC WAIST PANTS 30MM | E24: 180 | F24: M. | G24: 80 | H24: =E24*G24 -> 14400
A26: 8 | D26: STYLE、21SY-14 | I26: 22051887 | J26: 45064
B27: 122-337-555 | C27: 140 | D27: CORD | E27: 390 | F27: M. | G27: 70 | H27: =E27*G27 -> 27300
B28: B204 | C28: W | D28: ELASTIC WAIST PANTS 35MM | E28: 190 | F28: M. | G28: 86 | H28: =E28*G28 -> 16340
B29: 1QS*2QM | D29: QUICKLON 25MM
D30: ＃576-6M ＃580-10M | E30: 16 | F30: M. | G30: 400 | H30: =E30*G30 -> 6400
B33: TOTAL : | C33: 3CARTONS | E33: =SUMIF($F$9:$F$32,"M.",$E$9:$E$32) -> 776 | F33: M. | H33: =SUMIF($F$9:$F$32,"M.",$H$9:$H$32) -> 64440
E34: =SUMIF($F$9:$F$32,"PCS.",$E$9:$E$32) -> 709 | F34: PCS. | H34: =SUMIF($F$9:$F$32,"PCS.",$H$9:$H$32) -> 11050
E35: =E33 -> 776 | F35: =E34 -> 709 | H35: =SUM(H33:H34) -> 75490
B36: TOTAL : | G36: TOTAL | H36: =SUM(H9:H32) -> 75490

Sheet LABEL①
A2: LABEL SHEET
A5: C/NO. | B5: ART NO. | C5: COLOR | D5: DESCRIPTION OF GOODS | E5: Q'TY | G5: 原産国
D6: STYLE、22SY-65
A7: 1-3 | B7: SB2030 | C7: C/#5 BLACK | D7: WOVEN FABRIC | E7: 158 | F7: M. | G7: MADE IN JAPAN
B8: WOVEN FABRIC | D8: cotton60% polyester40% | G8: SHUNYA CO., LTD.
D9: WIDTH:128CM (260ｇ/㎡ )
A12: C/NO. | B12: ART NO. | C12: COLOR | D12: DESCRIPTION OF GOODS | E12: Q'TY | G12: 原産国
D13: STYLE、22SY-53
A14: 4 | B14: M-6543ST | C14: c/#018 BEIGE | D14: WOVEN FABRIC | E14: 40 | F14: M. | G14: MADE IN JAPAN
B15: WOVEN FABRIC | D15: NYLON100% | G15: SHUNYA CO., LTD.
D16: WIDTH:115CM (370ｇ/㎡ )
A19: C/NO. | B19: ART NO. | C19: COLOR | D19: DESCRIPTION OF GOODS | E19: Q'TY | G19: 原産国
D20: STYLE、22SY-66
A21: 5 | B21: TAN-ST23150 | C21: C/#0 INDIGO | D21: WOVEN FABRIC | E21: 60 | F21: M. | G21: MADE IN JAPAN
B22: WOVEN FABRIC | D22: cotton70% polyester30% | G22: SHUNYA CO., LTD.
D23: WIDTH:118CM (208ｇ/㎡ )
A26: C/NO. | B26: ART NO. | C26: COLOR | D26: DESCRIPTION OF GOODS | E26: Q'TY | G26: 原産国
D27: STYLE、22SY-74
A28: 6 | B28: pattern paper | E28: 3 | F28: PCS.
B29: WOVEN NEME | C29: c/#BLACK | E29: 250 | F29: PCS. | G29: MADE IN JAPAN
B30: packaging bag | E30: 250 | F30: PCS. | G30: SHUNYA CO., LTD.
B31: men's pants | E31: 1 | F31: PCS.
A34: C/NO. | B34: ART NO. | C34: COLOR | D34: DESCRIPTION OF GOODS | E34: Q'TY | G34: 原産国
D35: STYLE、22SY-74
A36: 7 | B36: pattern paper | E36: 3 | F36: PCS.
B37: WOVEN NEME | C37: c/#BLUE | E37: 200 | F37: PCS. | G37: MADE IN JAPAN
B38: men's pants | C38: c/#BLACK | E38: 1 | F38: PCS. | G38: SHUNYA CO., LTD.
B39: men's jacket | C39: c/#BEIGE | E39: 1 | F39: PCS.
A42: C/NO. | B42: ART NO. | C42: COLOR | D42: DESCRIPTION OF GOODS | E42: Q'TY | G42: 原産国
D43: STYLE、22SY-74
B44: B204 | C44: W | D44: ELASTIC WAIST PANTS 30MM | E44: 180 | F44: M.
A46: 8 | D46: STYLE、21SY-14 | G46: MADE IN JAPAN
B47: 122-337-555 | C47: 140 | D47: CORD | E47: 390 | F47: M. | G47: SHUNYA CO., LTD.
B48: B204 | C48: W | D48: ELASTIC WAIST PANTS 35MM | E48: 190 | F48: M.
B49: 1QS*2QM | D49: QUICKLON 25ＭＭ
D50: ＃576-6M ＃580-10M | E50: 16 | F50: M.
D51: #BK-72 #28-10 #10-22

Sheet サンプル製品カタログ
B2: CORDUROY PANTS(SAMPLE) | C2: C/#BLACK | D2: PANTS SASMPLE | F2: FRONT COTTON 100% LINING COTTON 100% | G2: No.6
B3: KAMEI PANTS(SAMPLE) | C3: C/#BLACK | D3: PANTS SAMPLE | F3: FRONT COTTON 60% POLYESTER40% LINING COTTON 100% | G3: No.7
B4: KAMEI COACH JACKET(SAMPLE） | C4: C/#BEIGE | D4: JACKET SAMPLE | F4: NYLON 100% LINING POLYESTER100%
