Workbook
Name pricetable: #REF!
Name pricetable: #REF!
Name pricetable: #REF!
Name pricetable: #REF!

Sheet shipper master
A1: 1 | B1: S/CODE | C1: SHIPPER NAME
A2: =A1+1 -> 2 | B2: SHIPPER | C2: SHUNYA CO., LTD.
A3: =A2+1 -> 3 | B3: SHIPPER ADDRESS 1 | C3: KENSHIN BLDG., 1F, 1-22-10 DOUGENZAKA,
A4: =A3+1 -> 4 | B4: SHIPPER ADDRESS 2 | C4: SHIBUYA-KU 150-0043
A5: =A4+1 -> 5 | B5: SHIPPER ADDRESS 3 | C5: TEL : +81(0)3-5459-1177
A6: =A5+1 -> 6 | B6: TEL
A7: =A6+1 -> 7 | B7: FAX
A8: =A7+1 -> 8 | B8: ATTN OR VAT NO.
A9: =A8+1 -> 9 | B9: BUYER | C9: VIVAN GARMENTS VIET NAM COMPANY LIMITED
A10: =A9+1 -> 10 | B10: BUYER ADDRESS1 | C10: D17 Street , Sai Gon South Residential Area
A11: =A10+1 -> 11 | B11: BUYER ADDRESS2 | C11: Hamlet 3 , Long Hau Commune , Can Giuoc District,
A12: =A11+1 -> 12 | B12: BUYER ADDRESS3 | C12: Long An Province , VietNam
A13: =A12+1 -> 13 | B13: TEL/FAX | C13: TEL : ( 084 ) 097 22 00 798 ATTN : MR. TUAN
A14: =A13+1 -> 14 | B14: ATTN
A15: =A14+1 -> 15 | B15: CONSIGNEE : | C15: - SAME AS BUYER -
A16: =A15+1 -> 16 | B16: CONSIGNEE ADDRESS1
A17: =A16+1 -> 17 | B17: CONSIGNEE ADDRESS2
A18: =A17+1 -> 18 | B18: CONSIGNEE ADDRESS3
A19: =A18+1 -> 19 | B19: TEL
A20: =A19+1 -> 20 | B20: FAX
A21: =A20+1 -> 21 | B21: ATTN | C21: NO COMMERCIAL
A22: =A21+1 -> 22 | B22: PAYMENT 1
A23: =A22+1 -> 23 | B23: PAYMENT 2
A24: =A23+1 -> 24 | B24: SHIPPER PER | C24: AIRCRAFT
A25: =A24+1 -> 25 | B25: INVOICE DATE | C25: July, 03 2024
A26: =A25+1 -> 26 | B26: INVOICE NO. | C26: SY-5700703-VT-DD-01
A27: =A26+1 -> 27 | B27: CONTRACT NO. | C27: =C26 -> SY-5700703-VT-DD-01
A28: =A27+1 -> 28 | B28: CONTRACT DATE
A29: =A28+1 -> 29 | B29: ORDER DATE
A30: =A29+1 -> 30 | B30: ORDER NO.
A31: =A30+1 -> 31 | B31: L/C DATE
A32: =A31+1 -> 32 | B32: FROM | C32: TOKYO, JAPAN
A33: =A32+1 -> 33 | B33: TO | C33: HOCHIMINH-CITY, VIETNAM
A34: =A33+1 -> 34 | B34: VIA
A35: =A34+1 -> 35 | B35: SHIPPING TERMS | C35: F.O.B. TOKYO IN YEN
A36: =A35+1 -> 36 | B36: TITTLE 1 | C36: FABRIC & PARTS FOR WEAR & SAMPLE CLOTHES
A37: =A36+1 -> 37 | B37: TITTLE 2
A38: =A37+1 -> 38 | B38: ATTACHE | C38: - DETAILS AS PER ATTACHED SHEET -
A39: =A38+1 -> 39 | B39: C/NO.
A40: =A39+1 -> 40 | B40: STYLE NO.
...

Sheet case mark 
A2: ='shipper master'!C49 -> SY-5700703-VT-DD-01 | I2: ='shipper master'!C49 -> SY-5700703-VT-DD-01
A3: ='[1]shipper master'!C50 -> VIVAN GARMENTS VIET NAM | I3: ='[1]shipper master'!C50 -> VIVAN GARMENTS VIET NAM
A4: ='[1]shipper master'!C51 -> COMPANY LIMITED | I4: ='[1]shipper master'!C51 -> COMPANY LIMITED
A5: ='[1]shipper master'!C52 -> HOCHIMINH-CITY, VIETNAM | I5: ='[1]shipper master'!C52 -> HOCHIMINH-CITY, VIETNAM
A6: C/NO. | C6: 1 | I6: C/NO. | K6: 2
A7: ='[1]shipper master'!C54 -> MADE IN JAPAN | I7: ='[1]shipper master'!C54 -> MADE IN JAPAN
A13: ='shipper master'!C49 -> SY-5700703-VT-DD-01 | I13: ='shipper master'!C49 -> SY-5700703-VT-DD-01
A14: ='[1]shipper master'!C50 -> VIVAN GARMENTS VIET NAM | I14: ='[1]shipper master'!C50 -> VIVAN GARMENTS VIET NAM
A15: ='[1]shipper master'!C51 -> COMPANY LIMITED | I15: ='[1]shipper master'!C51 -> COMPANY LIMITED
A16: ='[1]shipper master'!C52 -> HOCHIMINH-CITY, VIETNAM | I16: ='[1]shipper master'!C52 -> HOCHIMINH-CITY, VIETNAM
A17: C/NO. | C17: 3 | I17: C/NO. | K17: 4
A18: ='[1]shipper master'!C54 -> MADE IN JAPAN | I18: ='[1]shipper master'!C54 -> MADE IN JAPAN

Sheet invoice
A1: INVOICE
A2: ='shipper master'!C2 -> SHUNYA CO., LTD.
A3: ='shipper master'!C3 -> KENSHIN BLDG., 1F, 1-22-10 DOUGENZAKA,
A4: ='shipper master'!C4 -> SHIBUYA-KU 150-0043 | K4: ='shipper master'!C6 -> 0
A5: ='shipper master'!C5 -> TEL : +81(0)3-5459-1177 | K5: ='shipper master'!C7 -> 0
A6: IMPORTER | E6: INVOICE NO. | K6: CASE MARK
A7: ='shipper master'!C9 -> VIVAN GARMENTS VIET NAM COMPANY LIMITED | E7: ='shipper master'!C26 -> SY-5700703-VT-DD-01
A8: ='shipper master'!C10 -> D17 Street , Sai Gon South Residential Area | E8: INVOICE DATE | K8: ='shipper master'!C49 -> SY-5700703-VT-DD-01
A9: ='shipper master'!C11 -> Hamlet 3 , Long Hau Commune , Can Giuoc District, | E9: ='shipper master'!C25 -> July, 03 2024 | K9: ='[1]shipper master'!C50 -> VIVAN GARMENTS VIET NAM
A10: ='shipper master'!C12 -> Long An Province , VietNam | E10: CONTRACT NO. | K10: ='[1]shipper master'!C51 -> COMPANY LIMITED
A11: ='shipper master'!C13 -> TEL : ( 084 ) 097 22 00 798 ATTN : MR. TUAN | E11: ='shipper master'!C27 -> SY-5700703-VT-DD-01 | K11: ='[1]shipper master'!C52 -> HOCHIMINH-CITY, VIETNAM
A12: CONSIGNEE | E12: ORDER NO. | K12: C/NO. 1-7
A13: ='shipper master'!C15 -> - SAME AS BUYER - | E13: ='shipper master'!C30 -> 0 | K13: MADE IN JAPAN
A14: ='shipper master'!C16 -> 0 | E14: ORDER DATE
A15: ='shipper master'!C17 -> 0 | E15: ='shipper master'!C29 -> 0
A16: ='shipper master'!C18 -> 0 | E16: L/C NO.
A17: ='shipper master'!C19 -> 0
A18: PAYMENT METHOD
A19: ='shipper master'!C21 -> NO COMMERCIAL
A20: SHIPPED PER | C20: FROM | E20: TO | K20: VIA
A21: ='shipper master'!C24 -> AIRCRAFT | C21: ='shipper master'!C32 -> TOKYO, JAPAN | F21: ='shipper master'!C33 -> HOCHIMINH-CITY, VIETNAM
A22: C/NO. | B22: ART NO. | C22: DESCRIPTION OF GOODS | D22: COLOR | G22: SIZE | J22: Q'TY | K22: U/PRICE | L22: AMOUNT
B24: ='shipper master'!C36 -> FABRIC & PARTS FOR WEAR & SAMPLE CLOTHES | K24: ='shipper master'!C48 -> F.O.B. TOKYO IN YEN
B26: ='shipper master'!C37 -> 0
J27: ='NARITA '!E41 -> 116 | K27: ='NARITA '!F41 -> M. | L27: ='NARITA '!H41 -> 50400
B28: ='shipper master'!C38 -> - DETAILS AS PER ATTACHED SHEET - | J28: ='NARITA '!E42 -> 74 | K28: ='NARITA '!F42 -> PCS. | L28: ='NARITA '!H42 -> 325000
B29: ='shipper master'!C39 -> 0 | J29: ='NARITA '!E43 -> 1 | K29: ='NARITA '!F43 -> SET. | L29: ='NARITA '!H43 -> 100
J30: ='NARITA '!E44 -> 28.8 | K30: ='NARITA '!F44 -> KG. | L30: ='NARITA '!H44 -> 172800
B31: TOTAL : | C31: 116 M. 74 | D31: PCS. | E31: =J29 -> 1 | H31: =H29 -> 0 | I31: SET. | J31: =J30 -> 28.8 | K31: KG. | L31: =SUM(L27:L30) -> 548300
A34: ='shipper master'!C63 -> " THESE GOODS WILL BE RETURN TO JAPAN | H34: " NO COMMER VALUE | J34: " NO COMMERCIAL VALUE
A35: ='shipper master'!C64 -> AFTER MANUFACTURED AT VIET NAM " | H35: VALUE FOR CUSTOMS PURPOSE ONLY " | J35: VALUE FOR CUSTOMS PURPOSE ONLY "
C36: ='shipper master'!C58 -> 0
A37: ='shipper master'!C60 -> COUNTRY OF ORIGIN : JAPAN
A39: TOTAL CARTONS : | C39: 7CARTONS
A40: TOTAL GROSS WEIGHT : | C40: KGS

Sheet NARITA 
A2: - ATTACHED SHEET -
A4: C/NO. | B4: ART NO. | C4: COLOR | D4: DESCRIPTION OF GOODS | E4: Q'TY | F4: U/PRICE | H4: AMOUNT | I4: 佐川伝票・明細 | J4: 搬入日 | K4: 伝票NO | L4: 搬入内容 | M4: 数量 | N4: 箱数
B6: (H.S. CODE) | D6: =[2]invoice!B24 -> FABRIC & PARTS FOR WEAR & SAMPLE CLOTHES | G6: ='[1]shipper master'!C48 -> F.O.B. TOKYO IN YEN
D7: MADE IN JAPAN
A8: 1 | D8: STYLE: cc24aw-03 | I8: 入庫NO.22064979 | N8: 1
B9: T4100 | C9: C/#302 GRAY | D9: WOVEN FABRIC | E9: 100 | F9: M. | G9: 420 | H9: =E9*G9 -> 42000
B10: KNIT FABRIC | D10: NYLON 100%
B11: 後染めチュール生地 | D11: WIDTH:162CM (16ｇ/㎡ )
B12: 長繊維、プリント加工なし
A14: 2-5 | D14: STYLE: 24A-CS02 | I14: 入庫NO,22065136 | L14: 巻反 | N14: 4
B15: #7017 | C15: C/#258 BEIGE | D15: WOVEN FABRIC | E15: 8 | F15: M. | G15: 525 | H15: =E15*G15 -> 4200
B16: WOVEN FABRIC | C16: c/#1-1 BLACK | D16: COTTON 100% | E16: 8 | F16: M. | G16: 525 | H16: =E16*G16 -> 4200
B17: 後染めスレキ生地 朱子織 | D17: WIDTH:102CM (125ｇ/㎡ )
B18: 短繊維、プリント加工なし
D20: STYLE: cc24aw-03 | L20: 箱NO.1
B21: men's used T-shirt | C21: C/#GRAY | E21: 15 | F21: PCS. | G21: 2000 | H21: =E21*G21 -> 30000
B22: COTTON 100%
B23: 古着 プリント有
D26: STYLE: 23sy-AC04/05/06 | L26: 箱NO.2～3
B27: men's crew neck used knit wear | C27: C/#MIX | E27: 24 | F27: PCS. | G27: 5000 | H27: =E27*G27 -> 120000
B28: cashmere 100% | C28: C/#MIX | E28: 35 | F28: PCS. | G28: 5000 | H28: =E28*G28 -> 175000
B29: made in japan
B30: 古着 プリントなし
B32: pattern paper | D32: cc24aw-41 pattern paper | E32: 1 | F32: SET. | G32: 100 | H32: =E32*G32 -> 100
A34: 6-7 | D34: STYLE: 25SS-SV-701/706 | I34: NO.22065156 | N34: 1
B35: used denim cloth | C35: C/#BLUE | E35: 15.1 | F35: KG. | G35: 6000 | H35: =E35*G35 -> 90600
B36: COTTON 100% | C36: C/#BLUE | E36: 13.7 | F36: KG. | G36: 6000 | H36: =E36*G36 -> 82200
B37: 古着 プリントなし
B41: TOTAL : | C41: 7CARTONS | E41: =SUMIF($F$8:$F$39,"M.",$E$8:$E$39) -> 116 | F41: M. | H41: =SUMIF($F$8:$F$39,"M.",$H$8:$H$39) -> 50400
E42: =SUMIF($F$8:$F$39,"PCS.",$E$8:$E$39) -> 74 | F42: PCS. | H42: =SUMIF($F$8:$F$39,"PCS.",$H$8:$H$39) -> 325000
E43: =SUMIF($F$8:$F$39,"SET.",$E$8:$E$39) -> 1 | F43: SET. | H43: =SUMIF($F$8:$F$39,"SET.",$H$8:$H$39) -> 100
E44: =SUMIF($F$8:$F$39,"KG.",$E$8:$E$39) -> 28.8 | F44: KG. | H44: =SUMIF($F$8:$F$39,"KG.",$H$8:$H$39) -> 172800
H45: =SUM(H41:H44) -> 548300

Sheet LABEL
A2: LABEL SHEET -
A4: C/NO. | B4: ART NO. | C4: DESCRIPTION OF GOODS | D4: 原産国
A5: 1 | C5: STYLE: cc24aw-03
B6: T4100 | C6: WOVEN FABRIC | D6: MADE IN JAPAN
B7: KNIT FABRIC | C7: NYLON 100% | D7: SHUNYA CO., LTD.
B8: 後染めチュール生地 | C8: WIDTH:162CM (16ｇ/㎡ )
B9: 長繊維、プリント加工なし
B11: ART NO. | C11: DESCRIPTION OF GOODS | D11: 原産国
A12: 2-5 | C12: STYLE: 24A-CS02
B13: #7017 | C13: WOVEN FABRIC | D13: MADE IN JAPAN
B14: WOVEN FABRIC | C14: COTTON 100% | D14: SHUNYA CO., LTD.
B15: 後染めスレキ生地 朱子織 | C15: WIDTH:102CM (125ｇ/㎡ )
B16: 短繊維、プリント加工なし
C18: STYLE: cc24aw-03 | D18: 原産国
B19: men's used T-shirt
B20: COTTON 100% | D20: MADE IN JAPAN
B21: 古着 プリント有 | D21: SHUNYA CO., LTD.
C24: STYLE: 23sy-AC04/05/06
B25: men's crew neck used knit wear | D25: 原産国
B26: cashmere 100%
B27: made in japan | D27: MADE IN JAPAN
B28: 古着 プリントなし | D28: SHUNYA CO., LTD.
B30: pattern paper | C30: cc24aw-41 pattern paper
A32: C/NO. | B32: ART NO. | C32: DESCRIPTION OF GOODS | D32: 原産国
A33: 6-7 | C33: STYLE: 25SS-SV-701/706
B34: used denim cloth | D34: MADE IN JAPAN
B35: COTTON 100% | D35: SHUNYA CO., LTD.
B36: 古着 プリントなし
