Workbook
Name pricetable: #REF!
Name pricetable: #REF!
Name pricetable: #REF!
Name pricetable: #REF!
Name pricetable: #REF!

Sheet shipper master
A1: 1 | B1: S/CODE | C1: SHIPPER NAME
A2: =A1+1 -> 2 | B2: SHIPPER | C2: SHUNYA CO., LTD.
A3: =A2+1 -> 3 | B3: SHIPPER ADDRESS 1 | C3: KENSHIN BLDG., 1F, 1-22-10 DOUGENZAKA,
A4: =A3+1 -> 4 | B4: SHIPPER ADDRESS 2 | C4: SHIBUYA-KU 150-0043
A5: =A4+1 -> 5 | B5: SHIPPER ADDRESS 3 | C5: TEL : +81(0)3-5459-1177
A6: =A5+1 -> 6 | B6: TEL
A7: =A6+1 -> 7 | B7: FAX
A8: =A7+1 -> 8 | B8: ATTN OR VAT NO.
A9: =A8+1 -> 9 | B9: BUYER | C9: VIVAN GARMENTS VIET NAM COMPANY LIMITED
A10: =A9+1 -> 10 | B10: BUYER ADDRESS1 | C10: D17 Street , Sai Gon South Residential Area
A11: =A10+1 -> 11 | B11: BUYER ADDRESS2 | C11: Hamlet 3 , Long Hau Commune , Can Giuoc District,
A12: =A11+1 -> 12 | B12: BUYER ADDRESS3 | C12: Long An Province , VietNam
A13: =A12+1 -> 13 | B13: TEL/FAX | C13: TEL : ( 084 ) 097 22 00 798 ATTN : MR. TUAN
A14: =A13+1 -> 14 | B14: ATTN
A15: =A14+1 -> 15 | B15: CONSIGNEE : | C15: - SAME AS BUYER -
A16: =A15+1 -> 16 | B16: CONSIGNEE ADDRESS1
A17: =A16+1 -> 17 | B17: CONSIGNEE ADDRESS2
A18: =A17+1 -> 18 | B18: CONSIGNEE ADDRESS3
A19: =A18+1 -> 19 | B19: TEL
A20: =A19+1 -> 20 | B20: FAX
A21: =A20+1 -> 21 | B21: ATTN | C21: NO COMMERCIAL
A22: =A21+1 -> 22 | B22: PAYMENT 1
A23: =A22+1 -> 23 | B23: PAYMENT 2
A24: =A23+1 -> 24 | B24: SHIPPER PER | C24: AIRCRAFT
A25: =A24+1 -> 25 | B25: INVOICE DATE | C25: Oct, 30 2024
A26: =A25+1 -> 26 | B26: INVOICE NO. | C26: SY-5901030-VT-DD-01
A27: =A26+1 -> 27 | B27: CONTRACT NO. | C27: =C26 -> SY-5901030-VT-DD-01
A28: =A27+1 -> 28 | B28: CONTRACT DATE
A29: =A28+1 -> 29 | B29: ORDER DATE
A30: =A29+1 -> 30 | B30: ORDER NO.
A31: =A30+1 -> 31 | B31: L/C DATE
A32: =A31+1 -> 32 | B32: FROM | C32: TOKYO, JAPAN
A33: =A32+1 -> 33 | B33: TO | C33: HOCHIMINH-CITY, VIETNAM
A34: =A33+1 -> 34 | B34: VIA
A35: =A34+1 -> 35 | B35: SHIPPING TERMS | C35: F.O.B. TOKYO IN YEN
A36: =A35+1 -> 36 | B36: TITTLE 1 | C36: FABRIC & PARTS FOR WEAR & SAMPLE CLOTHES
A37: =A36+1 -> 37 | B37: TITTLE 2
A38: =A37+1 -> 38 | B38: ATTACHE | C38: - DETAILS AS PER ATTACHED SHEET -
A39: =A38+1 -> 39 | B39: C/NO.
A40: =A39+1 -> 40 | B40: STYLE NO.
...

Sheet case mark 
A2: ='shipper master'!C26 -> SY-5901030-VT-DD-01 | I2: ='shipper master'!C26 -> SY-5901030-VT-DD-01
A3: ='[2]shipper master'!C50 -> VIVAN GARMENTS VIET NAM | I3: ='[2]shipper master'!C50 -> VIVAN GARMENTS VIET NAM
A4: ='[2]shipper master'!C51 -> COMPANY LIMITED | I4: ='[2]shipper master'!C51 -> COMPANY LIMITED
A5: ='[2]shipper master'!C52 -> HOCHIMINH-CITY, VIETNAM | I5: ='[2]shipper master'!C52 -> HOCHIMINH-CITY, VIETNAM
A6: C/NO. | C6: 1 | I6: C/NO. | K6: 2
A7: ='[2]shipper master'!C54 -> MADE IN JAPAN | I7: ='[2]shipper master'!C54 -> MADE IN JAPAN
A13: ='shipper master'!C26 -> SY-5901030-VT-DD-01 | I13: ='shipper master'!C26 -> SY-5901030-VT-DD-01
A14: ='[2]shipper master'!C50 -> VIVAN GARMENTS VIET NAM | I14: ='[2]shipper master'!C50 -> VIVAN GARMENTS VIET NAM
A15: ='[2]shipper master'!C51 -> COMPANY LIMITED | I15: ='[2]shipper master'!C51 -> COMPANY LIMITED
A16: ='[2]shipper master'!C52 -> HOCHIMINH-CITY, VIETNAM | I16: ='[2]shipper master'!C52 -> HOCHIMINH-CITY, VIETNAM
A17: C/NO. | C17: 3 | I17: C/NO. | K17: 4
A18: ='[2]shipper master'!C54 -> MADE IN JAPAN | I18: ='[2]shipper master'!C54 -> MADE IN JAPAN

Sheet invoice
A1: INVOICE
A2: ='[3]shipper master'!C2 -> SHUNYA CO., LTD.
A3: ='[3]shipper master'!C3 -> KENSHIN BLDG., 1F, 1-22-10 DOUGENZAKA,
A4: ='[3]shipper master'!C4 -> SHIBUYA-KU 150-0043 | K4: ='[3]shipper master'!C6 -> 0
A5: ='[3]shipper master'!C5 -> TEL : +81(0)3-5459-1177 | K5: ='[3]shipper master'!C7 -> 0
A6: IMPORTER | E6: INVOICE NO. | K6: CASE MARK
A7: ='[3]shipper master'!C9 -> VIVAN GARMENTS VIET NAM COMPANY LIMITED | E7: ='[3]shipper master'!C26 -> SY-5800906-VT-DD-01
A8: ='[3]shipper master'!C10 -> D17 Street , Sai Gon South Residential Area | E8: INVOICE DATE | K8: ='shipper master'!C26 -> SY-5901030-VT-DD-01
A9: ='[3]shipper master'!C11 -> Hamlet 3 , Long Hau Commune , Can Giuoc District, | E9: ='[3]shipper master'!C25 -> Sep, 06 2024 | K9: ='[2]shipper master'!C50 -> VIVAN GARMENTS VIET NAM
A10: ='[3]shipper master'!C12 -> Long An Province , VietNam | E10: CONTRACT NO. | K10: ='[2]shipper master'!C51 -> COMPANY LIMITED
A11: ='[3]shipper master'!C13 -> TEL : ( 084 ) 097 22 00 798 ATTN : MR. TUAN | E11: ='[3]shipper master'!C27 -> SY-5800906-VT-DD-01 | K11: ='[2]shipper master'!C52 -> HOCHIMINH-CITY, VIETNAM
A12: CONSIGNEE | E12: ORDER NO. | K12: C/NO. 1-19
A13: ='[3]shipper master'!C15 -> - SAME AS BUYER - | E13: ='[3]shipper master'!C30 -> 0 | K13: MADE IN JAPAN
A14: ='[3]shipper master'!C16 -> 0 | E14: ORDER DATE
A15: ='[3]shipper master'!C17 -> 0 | E15: ='[3]shipper master'!C29 -> 0
A16: ='[3]shipper master'!C18 -> 0 | E16: L/C NO.
A17: ='[3]shipper master'!C19 -> 0
A18: PAYMENT METHOD
A19: ='[3]shipper master'!C21 -> NO COMMERCIAL
A20: SHIPPED PER | C20: FROM | E20: TO | K20: VIA
A21: ='[3]shipper master'!C24 -> AIRCRAFT | C21: ='[3]shipper master'!C32 -> TOKYO, JAPAN | F21: ='[3]shipper master'!C33 -> HOCHIMINH-CITY, VIETNAM
A22: C/NO. | B22: ART NO. | C22: DESCRIPTION OF GOODS | D22: COLOR | G22: SIZE | J22: Q'TY | K22: U/PRICE | L22: AMOUNT
B24: ='[3]shipper master'!C36 -> FABRIC & PARTS FOR WEAR & SAMPLE CLOTHES | K24: ='[3]shipper master'!C48 -> F.O.B. TOKYO IN YEN
B26: ='[3]shipper master'!C37 -> 0
J27: ='NARITA '!E54 -> 821.5 | K27: ='[3]NARITA '!F28 -> M. | L27: ='NARITA '!H54 -> 1196427
B28: ='[3]shipper master'!C38 -> - DETAILS AS PER ATTACHED SHEET - | J28: ='NARITA '!E55 -> 453 | K28: ='[3]NARITA '!F29 -> PCS. | L28: ='NARITA '!H55 -> 18460
J29: ='NARITA '!E56 -> 3 | K29: ='NARITA '!F56 -> SET. | L29: ='NARITA '!H56 -> 300
B30: TOTAL : | C30: ='NARITA '!E54 -> 821.5 | D30: M. | E30: ='NARITA '!E55 -> 453 | H30: =#REF! -> #REF! | I30: PCS. | J30: ='NARITA '!E56 -> 3 | K30: SET. | L30: =SUM(L27:L29) -> 1215187
A33: ='[3]shipper master'!C63 -> " THESE GOODS WILL BE RETURN TO JAPAN | H33: " NO COMMER VALUE | J33: " NO COMMERCIAL VALUE
A34: ='[3]shipper master'!C64 -> AFTER MANUFACTURED AT VIET NAM " | H34: VALUE FOR CUSTOMS PURPOSE ONLY " | J34: VALUE FOR CUSTOMS PURPOSE ONLY "
C35: ='[3]shipper master'!C58 -> 0
A36: ='[3]shipper master'!C60 -> COUNTRY OF ORIGIN : JAPAN
A38: TOTAL CARTONS : | C38: 19CARTONS
A39: TOTAL GROSS WEIGHT : | C39: KGS

Sheet NARITA 
A2: - ATTACHED SHEET -
A4: C/NO. | B4: ART NO. | C4: COLOR | D4: DESCRIPTION OF GOODS | E4: Q'TY | F4: U/PRICE | H4: AMOUNT | I4: 佐川伝票・明細 | J4: 搬入日 | K4: 伝票NO | L4: 搬入内容 | M4: 数量 | N4: 箱数
B6: (H.S. CODE) | D6: =[1]invoice!B24 -> FABRIC & PARTS FOR WEAR & SAMPLE CLOTHES | G6: ='[2]shipper master'!C48 -> F.O.B. TOKYO IN YEN
D7: MADE IN JAPAN
A8: 1-2 | D8: STYLE: f24-so-08 | N8: 2
B9: 027P00Y9100 | C9: C/#56LACK | D9: KNIT FABRIC | E9: 24 | F9: M. | G9: 1200 | H9: =E9*G9 -> 28800
B10: KNIT FABRIC | C10: c/#14 BEIGE | D10: COTTON 90%、POLYURETHANE10% | E10: 13 | F10: M. | G10: 1200 | H10: =E10*G10 -> 15600 | I10: 第一貨物 送り状60839956262 | J10: 10/16着
B11: 丸編み 後染め | D11: WIDTH:84CM (333ｇ/㎡ )
B12: 短繊維、プリント加工なし
A14: 3-5 | D14: STYLE: f24-so-08 | N14: 3
B15: 08500026013 | C15: C/#99 BLACK | D15: KNIT FABRIC | E15: 87.5 | F15: M. | G15: 1150 | H15: =E15*G15 -> 100625
B16: KNIT FABRIC | C16: c/#200BEIGE | D16: POLYESTER100% | E16: 41.2 | F16: M. | G16: 1150 | H16: =E16*G16 -> 47380 | I16: NO.22067818 | J16: 10/8着
B17: ダブルジャージー 後染め | D17: WIDTH:155CM (300ｇ/㎡ )
B18: 短繊維、プリント加工なし
A20: 6-7 | D20: STYLE: 25S-PT01,25S-PT02 | N20: 2
B21: 8500060007 | C21: C/#003 GRAY | D21: WOVEN FABRIC | E21: 34 | F21: M. | G21: 990 | H21: =E21*G21 -> 33660
B22: WOVEN FABRIC | C22: c/#005 NAVY | D22: NYLON100% | E22: 34 | F22: M. | G22: 990 | H22: =E22*G22 -> 33660 | I22: NO.22068131 | J22: 10/16着
B23: 平織 タフタ 後染め | D23: WIDTH:145CM (61ｇ/㎡ ) | I23: NO.22068193
B24: 長繊維、プリント加工なし
A26: 8-11 | D26: STYLE: 25S-SH01 | N26: 4
B27: ICM-100 | C27: C/#25 YELLOW | D27: WOVEN FABRIC | E27: 104 | F27: M. | G27: 1130 | H27: =E27*G27 -> 117520
B28: WOVEN FABRIC | C28: c/#32 BLUE | D28: COTTON100% | E28: 100 | F28: M. | G28: 1130 | H28: =E28*G28 -> 113000 | I28: NO.22068195 | J28: 10/16着
B29: 平織 ブロード素材 後染め | D29: WIDTH:145CM (117ｇ/㎡ )
B30: 短繊維、プリント加工なし
A32: 12-17 | D32: STYLE: 25S-PT01,25S-PT02,25S-JK02 | N32: 6
B33: 32-30678 | C33: C/#BK | D33: WOVEN FABRIC | E33: 143.5 | F33: M. | G33: 2390 | H33: =E33*G33 -> 342965
B34: WOVEN FABRIC | C34: c/#101 GRAY | D34: WOOL100% | E34: 150.3 | F34: M. | G34: 2390 | H34: =E34*G34 -> 359217 | I34: NO.22068219 | J34: 10/17着
B35: 平織 後染め | D35: WIDTH:134CM (232ｇ/㎡ )
B36: 短繊維、プリント加工なし
A38: 18 | D38: STYLE: f24-so-08 | N38: 1
B39: 5RN M DA8LH*DA8LH | C39: 580 | D39: ZIPPER 材質：銅合金 | E39: 35 | F39: PCS. | G39: 205 | H39: =E39*G39 -> 7175
D40: 61cm-12 65cm-15 69cm-8 | I40: NO.22068519 | J40: 10/29着
B41: 5RN M DA8LH*DA8LH | C41: 229 | D41: ZIPPER 材質：銅合金 | E41: 17 | F41: PCS. | G41: 205 | H41: =E41*G41 -> 3485
D42: 61cm-6 65cm-7 69cm-8-4
B44: SE500 | C44: SPC | D44: EYELETO 材質：真鍮 | E44: 200 | F44: PCS. | G44: 15 | H44: =E44*G44 -> 3000
B45: PACKING | D45: W-100 BK-材質：ポリエステル | E45: 200 | F45: PCS. | G45: 4 | H45: =E45*G45 -> 800
A47: 19 | D47: STYLE: f24-so-08 | N47: 1
B48: pattern paper | D48: f24-so-08 pattern paper | E48: 3 | F48: SET. | G48: 100 | H48: =E48*G48 -> 300 | I48: 佐川送り状 181489873305 | J48: 10/29出荷
B49: men's parka SAMPLE CLOTHES | C49: C/#BEIGE | D49: f24-so-08 sample | E49: 1 | F49: PCS. | G49: 3000 | H49: 4000
B50: SIC-3122 | C50: C/#9000 | D50: CORD 材質：ACRYLIC100％ | E50: 90 | F50: M. | G50: 145 | H50: 4000
...

Sheet サンプル製品カタログ
D1: ITEM
B2: NAME | C2: color | E2: lady's or men's | F2: WOVEN or KNIT | G2: picture | H2: Composition | I2: packingNo.
B3: Men's parka SAMPLE CLOTHES | C3: C/#BEIGE | D3: Men's parka SAMPLE CLOTHES | E3: men's | F3: WOVEN FABRIC | H3: FRONT POLYESTER100% | I3: 7

Sheet LABEL
A2: LABEL SHEET -
A4: C/NO. | B4: ART NO. | C4: DESCRIPTION OF GOODS | D4: 原産国
A5: 1-2 | C5: STYLE: f24-so-08
B6: 027P00Y9100 | C6: KNIT FABRIC | D6: MADE IN JAPAN
B7: KNIT FABRIC | C7: COTTON 90%、POLYURETHANE10% | D7: SHUNYA CO., LTD.
B8: 丸編み 後染め | C8: WIDTH:84CM (333ｇ/㎡ )
B9: 短繊維、プリント加工なし
A11: C/NO. | B11: ART NO. | C11: DESCRIPTION OF GOODS | D11: 原産国
A12: 3-5 | C12: STYLE: f24-so-08
B13: 08500026013 | C13: KNIT FABRIC | D13: MADE IN JAPAN
B14: KNIT FABRIC | C14: POLYESTER100% | D14: SHUNYA CO., LTD.
B15: ダブルジャージー 後染め | C15: WIDTH:155CM (300ｇ/㎡ )
B16: 短繊維、プリント加工なし
A18: C/NO. | B18: ART NO. | C18: DESCRIPTION OF GOODS | D18: 原産国
A19: 6-7 | C19: STYLE: 25S-PT01,25S-PT02
B20: 8500060007 | C20: WOVEN FABRIC | D20: MADE IN JAPAN
B21: WOVEN FABRIC | C21: NYLON100% | D21: SHUNYA CO., LTD.
B22: 平織 タフタ 後染め | C22: WIDTH:145CM (61ｇ/㎡ )
B23: 長繊維、プリント加工なし
A25: C/NO. | B25: ART NO. | C25: DESCRIPTION OF GOODS | D25: 原産国
A26: 8-11 | C26: STYLE: 25S-SH01
B27: ICM-100 | C27: WOVEN FABRIC | D27: MADE IN JAPAN
B28: WOVEN FABRIC | C28: COTTON100% | D28: SHUNYA CO., LTD.
B29: 平織 ブロード素材 後染め | C29: WIDTH:145CM (117ｇ/㎡ )
B30: 短繊維、プリント加工なし
A32: C/NO. | B32: ART NO. | C32: DESCRIPTION OF GOODS | D32: 原産国
A33: 12-17 | C33: STYLE: 25S-PT01,25S-PT02,25S-JK02
B34: 32-30678 | C34: WOVEN FABRIC | D34: MADE IN JAPAN
B35: WOVEN FABRIC | C35: WOOL100% | D35: SHUNYA CO., LTD.
B36: 平織 後染め | C36: WIDTH:134CM (232ｇ/㎡ )
B37: 短繊維、プリント加工なし
A39: C/NO. | B39: ART NO. | C39: DESCRIPTION OF GOODS | D39: 原産国
A40: 18 | C40: STYLE: f24-so-08
B41: 5RN M DA8LH*DA8LH | C41: ZIPPER 材質：銅合金 | D41: MADE IN JAPAN
C42: 61cm-12 65cm-15 69cm-8 | D42: SHUNYA CO., LTD.
B43: 5RN M DA8LH*DA8LH | C43: ZIPPER 材質：銅合金
C44: 61cm-6 65cm-7 69cm-8-4
B46: SE500 | C46: EYELETO 材質：真鍮
B47: PACKING | C47: W-100 BK-材質：ポリエステル
A49: C/NO. | B49: ART NO. | C49: DESCRIPTION OF GOODS | D49: 原産国
...
