Workbook
Name pricetable: #REF!
Name pricetable: #REF!
Name pricetable: #REF!
Name pricetable: #REF!
Name pricetable: #REF!

Sheet shipper master
A1: 1 | B1: S/CODE | C1: SHIPPER NAME
A2: =A1+1 -> 2 | B2: SHIPPER | C2: SHUNYA CO., LTD.
A3: =A2+1 -> 3 | B3: SHIPPER ADDRESS 1 | C3: KENSHIN BLDG., 1F, 1-22-10 DOUGENZAKA,
A4: =A3+1 -> 4 | B4: SHIPPER ADDRESS 2 | C4: SHIBUYA-KU 150-0043
A5: =A4+1 -> 5 | B5: SHIPPER ADDRESS 3 | C5: TEL : +81(0)3-5459-1177
A6: =A5+1 -> 6 | B6: TEL
A7: =A6+1 -> 7 | B7: FAX
A8: =A7+1 -> 8 | B8: ATTN OR VAT NO.
A9: =A8+1 -> 9 | B9: BUYER | C9: VIVAN GARMENTS VIET NAM COMPANY LIMITED
A10: =A9+1 -> 10 | B10: BUYER ADDRESS1 | C10: No.10 , D17 Street , Sai Gon South Residential Area
A11: =A10+1 -> 11 | B11: BUYER ADDRESS2 | C11: Hamlet 3 , Long Hau Commune , Can Giuoc District,
A12: =A11+1 -> 12 | B12: BUYER ADDRESS3 | C12: Long An Province , VietNam
A13: =A12+1 -> 13 | B13: TEL/FAX | C13: TEL : ( 084 ) 097 22 00 798 ATTN : MR. TUAN
A14: =A13+1 -> 14 | B14: ATTN
A15: =A14+1 -> 15 | B15: CONSIGNEE : | C15: - SAME AS BUYER -
A16: =A15+1 -> 16 | B16: CONSIGNEE ADDRESS1
A17: =A16+1 -> 17 | B17: CONSIGNEE ADDRESS2
A18: =A17+1 -> 18 | B18: CONSIGNEE ADDRESS3
A19: =A18+1 -> 19 | B19: TEL
A20: =A19+1 -> 20 | B20: FAX
A21: =A20+1 -> 21 | B21: ATTN | C21: NO COMMERCIAL
A22: =A21+1 -> 22 | B22: PAYMENT 1
A23: =A22+1 -> 23 | B23: PAYMENT 2
A24: =A23+1 -> 24 | B24: SHIPPER PER | C24: AIRCRAFT
A25: =A24+1 -> 25 | B25: INVOICE DATE | C25: NOVEMBER,27 2023
A26: =A25+1 -> 26 | B26: INVOICE NO. | C26: SY-5300419-VT-DD-01
A27: =A26+1 -> 27 | B27: CONTRACT NO. | C27: =C26 -> SY-5300419-VT-DD-01
A28: =A27+1 -> 28 | B28: CONTRACT DATE
A29: =A28+1 -> 29 | B29: ORDER DATE
A30: =A29+1 -> 30 | B30: ORDER NO.
A31: =A30+1 -> 31 | B31: L/C DATE
A32: =A31+1 -> 32 | B32: FROM | C32: TOKYO, JAPAN
A33: =A32+1 -> 33 | B33: TO | C33: HOCHIMINH-CITY, VIETNAM
A34: =A33+1 -> 34 | B34: VIA
A35: =A34+1 -> 35 | B35: SHIPPING TERMS | C35: F.O.B. TOKYO IN YEN
A36: =A35+1 -> 36 | B36: TITTLE 1 | C36: FABRIC & PARTS FOR WEAR & SAMPLE CLOTHES
A37: =A36+1 -> 37 | B37: TITTLE 2
A38: =A37+1 -> 38 | B38: ATTACHE | C38: - DETAILS AS PER ATTACHED SHEET -
A39: =A38+1 -> 39 | B39: C/NO.
A40: =A39+1 -> 40 | B40: STYLE NO.
...

Sheet invoice
A1: INVOICE
A2: ='shipper master'!C2 -> SHUNYA CO., LTD.
A3: ='shipper master'!C3 -> KENSHIN BLDG., 1F, 1-22-10 DOUGENZAKA,
A4: ='shipper master'!C4 -> SHIBUYA-KU 150-0043 | K4: ='shipper master'!C6 -> 0
A5: ='shipper master'!C5 -> TEL : +81(0)3-5459-1177 | K5: ='shipper master'!C7 -> 0
A6: IMPORTER | E6: INVOICE NO. | K6: CASE MARK
A7: ='shipper master'!C9 -> VIVAN GARMENTS VIET NAM COMPANY LIMITED | E7: ='shipper master'!C26 -> SY-5300419-VT-DD-01
A8: ='shipper master'!C10 -> No.10 , D17 Street , Sai Gon South Residential Area | E8: INVOICE DATE | K8: ='shipper master'!C49 -> SY-5300419-VT-DD-01
A9: ='shipper master'!C11 -> Hamlet 3 , Long Hau Commune , Can Giuoc District, | E9: ='shipper master'!C25 -> NOVEMBER,27 2023 | K9: ='[1]shipper master'!C50 -> VIVAN GARMENTS VIET NAM
A10: ='shipper master'!C12 -> Long An Province , VietNam | E10: CONTRACT NO. | K10: ='[1]shipper master'!C51 -> COMPANY LIMITED
A11: ='shipper master'!C13 -> TEL : ( 084 ) 097 22 00 798 ATTN : MR. TUAN | E11: ='shipper master'!C27 -> SY-5300419-VT-DD-01 | K11: ='[1]shipper master'!C52 -> HOCHIMINH-CITY, VIETNAM
A12: CONSIGNEE | E12: ORDER NO. | K12: C/NO. 1-60
A13: ='shipper master'!C15 -> - SAME AS BUYER - | E13: ='shipper master'!C30 -> 0 | K13: MADE IN JAPAN
A14: ='shipper master'!C16 -> 0 | E14: ORDER DATE
A15: ='shipper master'!C17 -> 0 | E15: ='shipper master'!C29 -> 0
A16: ='shipper master'!C18 -> 0 | E16: L/C NO.
A17: ='shipper master'!C19 -> 0
A18: PAYMENT METHOD
A19: ='shipper master'!C21 -> NO COMMERCIAL
A20: SHIPPED PER | C20: FROM | E20: TO | K20: VIA
A21: ='shipper master'!C24 -> AIRCRAFT | C21: ='shipper master'!C32 -> TOKYO, JAPAN | F21: ='shipper master'!C33 -> HOCHIMINH-CITY, VIETNAM
A22: C/NO. | B22: ART NO. | C22: DESCRIPTION OF GOODS | D22: COLOR | G22: SIZE | J22: Q'TY | K22: U/PRICE | L22: AMOUNT
B24: ='shipper master'!C36 -> FABRIC & PARTS FOR WEAR & SAMPLE CLOTHES | K24: ='shipper master'!C48 -> F.O.B. TOKYO IN YEN
B26: ='shipper master'!C37 -> 0
J27: ='NARITA '!E106 -> 1267.1 | K27: ='NARITA '!F106 -> M. | L27: ='NARITA '!H106 -> 1351855
B28: ='shipper master'!C38 -> - DETAILS AS PER ATTACHED SHEET - | J28: ='NARITA '!E107 -> 1304 | K28: ='NARITA '!F107 -> PCS. | L28: ='NARITA '!H107 -> 554550
B29: ='shipper master'!C39 -> 0 | J29: ='NARITA '!E108 -> 27 | K29: ='NARITA '!F108 -> SET. | L29: ='NARITA '!H108 -> 2700
B31: TOTAL : | C31: =J27 -> 1267.1 | D31: M. | E31: =J28 -> 1304 | H31: =H29 -> 0 | I31: PCS | J31: =J29 -> 27 | K31: SET. | L31: =SUM(L27:L30) -> 1909105
A34: ='shipper master'!C63 -> " THESE GOODS WILL BE RETURN TO JAPAN | H34: " NO COMMER VALUE | J34: " NO COMMERCIAL VALUE
A35: ='shipper master'!C64 -> AFTER MANUFACTURED AT VIET NAM " | H35: VALUE FOR CUSTOMS PURPOSE ONLY " | J35: VALUE FOR CUSTOMS PURPOSE ONLY "
C36: ='shipper master'!C58 -> 0
A37: ='shipper master'!C60 -> COUNTRY OF ORIGIN : JAPAN
A39: TOTAL CARTONS : | C39: 60CARTONS
A40: TOTAL GROSS WEIGHT : | C40: KGS

Sheet case mark 
A2: ='shipper master'!C49 -> SY-5300419-VT-DD-01 | I2: ='shipper master'!C49 -> SY-5300419-VT-DD-01
A3: ='[1]shipper master'!C50 -> VIVAN GARMENTS VIET NAM | I3: ='[1]shipper master'!C50 -> VIVAN GARMENTS VIET NAM
A4: ='[1]shipper master'!C51 -> COMPANY LIMITED | I4: ='[1]shipper master'!C51 -> COMPANY LIMITED
A5: ='[1]shipper master'!C52 -> HOCHIMINH-CITY, VIETNAM | I5: ='[1]shipper master'!C52 -> HOCHIMINH-CITY, VIETNAM
A6: C/NO. | C6: 1 | I6: C/NO. | K6: 2
A7: ='[1]shipper master'!C54 -> MADE IN JAPAN | I7: ='[1]shipper master'!C54 -> MADE IN JAPAN
A13: ='shipper master'!C49 -> SY-5300419-VT-DD-01 | I13: ='shipper master'!C49 -> SY-5300419-VT-DD-01
A14: ='[1]shipper master'!C50 -> VIVAN GARMENTS VIET NAM | I14: ='[1]shipper master'!C50 -> VIVAN GARMENTS VIET NAM
A15: ='[1]shipper master'!C51 -> COMPANY LIMITED | I15: ='[1]shipper master'!C51 -> COMPANY LIMITED
A16: ='[1]shipper master'!C52 -> HOCHIMINH-CITY, VIETNAM | I16: ='[1]shipper master'!C52 -> HOCHIMINH-CITY, VIETNAM
A17: C/NO. | C17: 3 | I17: C/NO. | K17: 4
A18: ='[1]shipper master'!C54 -> MADE IN JAPAN | I18: ='[1]shipper master'!C54 -> MADE IN JAPAN

Sheet NARITA 
A2: - ATTACHED SHEET -
A4: C/NO. | B4: ART NO. | C4: COLOR | D4: DESCRIPTION OF GOODS | E4: Q'TY | F4: U/PRICE | H4: AMOUNT | I4: 佐川伝票・明細・伝票NO | J4: 搬入日 | K4: 搬入内容 | L4: 数量 | M4: 箱数
B6: (H.S. CODE) | D6: =[2]invoice!B24 -> FABRIC & PARTS FOR WEAR & SAMPLE CLOTHES | G6: ='[1]shipper master'!C48 -> F.O.B. TOKYO IN YEN
D7: MADE IN JAPAN
A8: 1-27 | D8: STYLE: 21SY-60,24A-CS02 | J8: 45390
B9: 007S0052010 | C9: c/#010 BLACK | D9: KNIT FABRIC | E9: 353 | F9: M. | G9: 1030 | H9: =E9*G9 -> 363590 | I9: 入庫NO.22062712
B10: KNIT FABRIC | C10: c/#120 BEIGE | D10: cotton 100% | E10: 23 | F10: M. | G10: 1030 | H10: =E10*G10 -> 23690 | I10: 入庫NO.22062716
B11: パイル編み,後染め | C11: c/#500 BORDEAUX | D11: WIDTH:165CM (450ｇ/㎡ ) | E11: 80.5 | F11: M. | G11: 1030 | H11: =E11*G11 -> 82915
B12: 短繊維、テクスチャード加工無し | C12: c/#103 SMOKEBEIGE | E12: 76 | F12: M. | G12: 1030 | H12: =E12*G12 -> 78280
D14: STYLE: 21SY-60,24A-CS02 | J14: 45390
B15: 007S0052070 | C15: c/#010 BLACK | D15: KNIT FABRIC | E15: 47 | F15: M. | G15: 1120 | H15: =E15*G15 -> 52640
A16: 28-30 | B16: KNIT FABRIC | C16: c/#120 BEIGE | D16: cotton 96% polyurethane 4% | E16: 10 | F16: M. | G16: 1120 | H16: =E16*G16 -> 11200 | I16: 入庫NO.22062714
B17: 後染め フライス編み | C17: c/#500 BORDEAUX | D17: WIDTH:120CM (400ｇ/㎡ ) | E17: 9 | F17: M. | G17: 1120 | H17: =E17*G17 -> 10080 | I17: 入庫NO.22062715
B18: 短繊維、テクスチャード加工無し | C18: c/#103 SMOKEBEIGE | E18: 9 | F18: M. | G18: 1120 | H18: =E18*G18 -> 10080
D20: STYLE: 24A-CS01 | J20: 45390
B21: 027P0003080 | C21: C/#56 BLACK | D21: KNIT FABRIC | E21: 98.3 | F21: M. | G21: 1200 | H21: =E21*G21 -> 117960 | I21: 入庫 No.22062713①
A22: 31-34 | B22: KNIT FABRIC | D22: cotton 100%
B23: パイル編み,後染め | D23: WIDTH:150CM (375ｇ/㎡ )
B24: 短繊維、テクスチャード加工無し
D26: STYLE: 24A-CS01 | J26: 45390
B27: 027P0003080RMG | C27: C/#G | D27: KNIT FABRIC | E27: 95.3 | F27: M. | G27: 1200 | H27: =E27*G27 -> 114360 | I27: 入庫 No.22062713②
A28: 35-38 | B28: KNIT FABRIC | D28: cotton 90% polyester 5% nylon 5%
B29: パイル編み,後染め | D29: WIDTH:150CM (332ｇ/㎡ )
B30: 短繊維、テクスチャード加工無し
D32: STYLE: 24A-PT01/02/03 | J32: 45390
B33: A5100 | C33: C/#521 GRAY | D33: WOVEN FABRIC | E33: 138 | F33: M. | G33: 590 | H33: =E33*G33 -> 81420 | I33: 入庫 No.22062733
A34: 39-40 | B34: WOVEN FABRIC | D34: acetate 100%
B35: 朱子織 後染めサテン生地 | D35: WIDTH:122CM (135ｇ/㎡ )
B36: 長繊維、テクスチャード加工無し
D38: STYLE: 24A-JK01/02 | J38: 45390
B39: 1044309 | C39: C/#00 WHITE | D39: WOVEN FABRIC | E39: 100 | F39: M. | G39: 1200 | H39: =E39*G39 -> 120000 | I39: 入庫 No.22062615
A40: 41-46 | B40: WOVEN FABRIC | C40: C/#09 BLACK | D40: nylon 100% | E40: 200 | F40: M. | G40: 1200 | H40: =E40*G40 -> 240000
B41: 朱子織 後染めサテン生地 | D41: WIDTH:150CM (240ｇ/㎡ )
B42: 長繊維、テクスチャード加工無し
D44: STYLE: bd24-1001/1002 | J44: 45400
B45: 5001-01 | C45: C/#191 WHITE | E45: 52 | F45: PCS. | G45: 457 | H45: =E45*G45 -> 23764 | I45: 入庫No.22063008
A46: 47-48 | B46: men's crew neck T-shirt | C46: C/#165 CHARCOAL | D46: cotton 100% | E46: 48 | F46: PCS. | G46: 457 | H46: =E46*G46 -> 21936
B47: cotton 100%
B48: 短繊維 テクスチャード加工無し
D50: STYLE:AVANI-01 | J50: 45400
...

Sheet サンプル製品カタログ
D1: ITEM
B2: NAME | C2: color | E2: lady's or men's | F2: WOVEN or KNIT | G2: picture | H2: Composition | I2: packingNo.
B3: 24A-JK01 sample | C3: C/#white | D3: men's nylon coat SAMPLE CLOTHES | E3: men's | F3: WOVEN FABRIC | H3: FRONT nylon100% LINING polyester 100% | I3: 58
B4: 24A-JK02 sample | C4: C/#black | D4: men's nylon vest SAMPLE CLOTHES | E4: men's | F4: WOVEN FABRIC | H4: nylon 100%
B5: 24A-CS01 sample | C5: C/#gray | D5: men's zip parker SAMPLE CLOTHES | E5: men's | F5: KNIT FABRIC | H5: COTTON 100%
B6: 21SY-60 sample | C6: C/#yellow | D6: men's parker SAMPLE CLOTHES | E6: men's | F6: KNIT FABRIC | H6: COTTON 100%
B7: 24A-CS02 sample | C7: C/＃beige | D7: men's quilting tops SAMPLE CLOTHES | E7: men's | F7: WOVEN FABRIC | H7: FRONT COTTON 63% NYLON 37% LINING COTTON 100%
B8: 24A-SH01 sample | C8: C/#white | D8: men's pocket shirt SAMPLE CLOTHES | E8: men's | F8: WOVEN FABRIC | H8: COTTON100%
B9: 24A-PT01 sample | C9: C/＃silver | D9: men's satin pants CLOTHES | E9: men's | F9: WOVEN FABRIC | H9: FRONT ACETATE100% LINING POLYESTER 100%
B10: 24A-PT02 sample | C10: C/#silver | D10: men's survival satin pants SAMPLE CLOTHES | E10: men's | F10: WOVEN FABRIC | H10: FRONT ACETATE100% LINING POLYESTER 100%

Sheet LABEL
A2: LABEL SHEET -
A4: C/NO. | B4: ART NO. | C4: DESCRIPTION OF GOODS | D4: 原産国
A5: 1-27 | C5: STYLE: 21SY-60,24A-CS02
B6: 007S0052010 | C6: KNIT FABRIC
B7: KNIT FABRIC | C7: cotton 100% | D7: MADE IN JAPAN
B8: パイル編み,後染め | C8: WIDTH:165CM (450ｇ/㎡ ) | D8: SHUNYA CO., LTD.
B9: 短繊維、テクスチャード加工無し
A11: C/NO. | B11: ART NO. | C11: DESCRIPTION OF GOODS | D11: 原産国
C12: STYLE: 21SY-60,24A-CS02
B13: 007S0052070 | C13: KNIT FABRIC
A14: 28-30 | B14: KNIT FABRIC | C14: cotton 96% polyurethane 4% | D14: MADE IN JAPAN
B15: 後染め フライス編み | C15: WIDTH:120CM (400ｇ/㎡ ) | D15: SHUNYA CO., LTD.
B16: 短繊維、テクスチャード加工無し
A18: C/NO. | B18: ART NO. | C18: DESCRIPTION OF GOODS | D18: 原産国
C19: STYLE: 24A-CS01
B20: 027P0003080 | C20: KNIT FABRIC
A21: 31-34 | B21: KNIT FABRIC | C21: cotton 100% | D21: MADE IN JAPAN
B22: パイル編み,後染め | C22: WIDTH:150CM (375ｇ/㎡ ) | D22: SHUNYA CO., LTD.
B23: 短繊維、テクスチャード加工無し
A25: C/NO. | B25: ART NO. | C25: DESCRIPTION OF GOODS | D25: 原産国
C26: STYLE: 24A-CS01
B27: 027P0003080RMG | C27: KNIT FABRIC
A28: 35-38 | B28: KNIT FABRIC | C28: cotton 90% polyester 5% nylon 5% | D28: MADE IN JAPAN
B29: パイル編み,後染め | C29: WIDTH:150CM (332ｇ/㎡ ) | D29: SHUNYA CO., LTD.
B30: 短繊維、テクスチャード加工無し
A32: C/NO. | B32: ART NO. | C32: DESCRIPTION OF GOODS | D32: 原産国
C33: STYLE: 24A-PT01/02/03
B34: A5100 | C34: WOVEN FABRIC
A35: 39-40 | B35: WOVEN FABRIC | C35: acetate 100% | D35: MADE IN JAPAN
B36: 朱子織 後染めサテン生地 | C36: WIDTH:122CM (135ｇ/㎡ ) | D36: SHUNYA CO., LTD.
B37: 長繊維、テクスチャード加工無し
A39: C/NO. | B39: ART NO. | C39: DESCRIPTION OF GOODS | D39: 原産国
C40: STYLE: 24A-JK01/02
B41: 1044309 | C41: WOVEN FABRIC
A42: 41-46 | B42: WOVEN FABRIC | C42: nylon 100% | D42: MADE IN JAPAN
B43: 朱子織 後染めサテン生地 | C43: WIDTH:150CM (240ｇ/㎡ ) | D43: SHUNYA CO., LTD.
B44: 長繊維、テクスチャード加工無し
A46: C/NO. | B46: ART NO. | C46: DESCRIPTION OF GOODS | D46: 原産国
C47: STYLE: bd24-1001/1002
B48: 5001-01
...
