Workbook
Name pricetable: #REF!
Name pricetable: #REF!
Name pricetable: #REF!
Name pricetable: #REF!
Name pricetable: #REF!

Sheet shipper master
A1: 1 | B1: S/CODE | C1: SHIPPER NAME
A2: =A1+1 -> 2 | B2: SHIPPER | C2: SHUNYA CO., LTD.
A3: =A2+1 -> 3 | B3: SHIPPER ADDRESS 1 | C3: KENSHIN BLDG., 1F, 1-22-10 DOUGENZAKA,
A4: =A3+1 -> 4 | B4: SHIPPER ADDRESS 2 | C4: SHIBUYA-KU 150-0043
A5: =A4+1 -> 5 | B5: SHIPPER ADDRESS 3 | C5: TEL : +81(0)3-5459-1177
A6: =A5+1 -> 6 | B6: TEL
A7: =A6+1 -> 7 | B7: FAX
A8: =A7+1 -> 8 | B8: ATTN OR VAT NO.
A9: =A8+1 -> 9 | B9: BUYER | C9: VIVAN GARMENTS VIET NAM COMPANY LIMITED
A10: =A9+1 -> 10 | B10: BUYER ADDRESS1 | C10: No.10 , D17 Street , Sai Gon South Residential Area
A11: =A10+1 -> 11 | B11: BUYER ADDRESS2 | C11: Hamlet 3 , Long Hau Commune , Can Giuoc District,
A12: =A11+1 -> 12 | B12: BUYER ADDRESS3 | C12: Long An Province , VietNam
A13: =A12+1 -> 13 | B13: TEL/FAX | C13: TEL : ( 084 ) 097 22 00 798 ATTN : MR. TUAN
A14: =A13+1 -> 14 | B14: ATTN
A15: =A14+1 -> 15 | B15: CONSIGNEE : | C15: - SAME AS BUYER -
A16: =A15+1 -> 16 | B16: CONSIGNEE ADDRESS1
A17: =A16+1 -> 17 | B17: CONSIGNEE ADDRESS2
A18: =A17+1 -> 18 | B18: CONSIGNEE ADDRESS3
A19: =A18+1 -> 19 | B19: TEL
A20: =A19+1 -> 20 | B20: FAX
A21: =A20+1 -> 21 | B21: ATTN | C21: NO COMMERCIAL
A22: =A21+1 -> 22 | B22: PAYMENT 1
A23: =A22+1 -> 23 | B23: PAYMENT 2
A24: =A23+1 -> 24 | B24: SHIPPER PER | C24: AIRCRAFT
A25: =A24+1 -> 25 | B25: INVOICE DATE | C25: June, 07 2024
A26: =A25+1 -> 26 | B26: INVOICE NO. | C26: SY-5600605-VT-DD-01
A27: =A26+1 -> 27 | B27: CONTRACT NO. | C27: =C26 -> SY-5600605-VT-DD-01
A28: =A27+1 -> 28 | B28: CONTRACT DATE
A29: =A28+1 -> 29 | B29: ORDER DATE
A30: =A29+1 -> 30 | B30: ORDER NO.
A31: =A30+1 -> 31 | B31: L/C DATE
A32: =A31+1 -> 32 | B32: FROM | C32: TOKYO, JAPAN
A33: =A32+1 -> 33 | B33: TO | C33: HOCHIMINH-CITY, VIETNAM
A34: =A33+1 -> 34 | B34: VIA
A35: =A34+1 -> 35 | B35: SHIPPING TERMS | C35: F.O.B. TOKYO IN YEN
A36: =A35+1 -> 36 | B36: TITTLE 1 | C36: FABRIC & PARTS FOR WEAR & SAMPLE CLOTHES
A37: =A36+1 -> 37 | B37: TITTLE 2
A38: =A37+1 -> 38 | B38: ATTACHE | C38: - DETAILS AS PER ATTACHED SHEET -
A39: =A38+1 -> 39 | B39: C/NO.
A40: =A39+1 -> 40 | B40: STYLE NO.
...

Sheet case mark 
A2: ='shipper master'!C49 -> SY-5600605-VT-DD-01 | I2: ='shipper master'!C49 -> SY-5600605-VT-DD-01
A3: ='[1]shipper master'!C50 -> VIVAN GARMENTS VIET NAM | I3: ='[1]shipper master'!C50 -> VIVAN GARMENTS VIET NAM
A4: ='[1]shipper master'!C51 -> COMPANY LIMITED | I4: ='[1]shipper master'!C51 -> COMPANY LIMITED
A5: ='[1]shipper master'!C52 -> HOCHIMINH-CITY, VIETNAM | I5: ='[1]shipper master'!C52 -> HOCHIMINH-CITY, VIETNAM
A6: C/NO. | C6: 1 | I6: C/NO. | K6: 2
A7: ='[1]shipper master'!C54 -> MADE IN JAPAN | I7: ='[1]shipper master'!C54 -> MADE IN JAPAN
A13: ='shipper master'!C49 -> SY-5600605-VT-DD-01 | I13: ='shipper master'!C49 -> SY-5600605-VT-DD-01
A14: ='[1]shipper master'!C50 -> VIVAN GARMENTS VIET NAM | I14: ='[1]shipper master'!C50 -> VIVAN GARMENTS VIET NAM
A15: ='[1]shipper master'!C51 -> COMPANY LIMITED | I15: ='[1]shipper master'!C51 -> COMPANY LIMITED
A16: ='[1]shipper master'!C52 -> HOCHIMINH-CITY, VIETNAM | I16: ='[1]shipper master'!C52 -> HOCHIMINH-CITY, VIETNAM
A17: C/NO. | C17: 3 | I17: C/NO. | K17: 4
A18: ='[1]shipper master'!C54 -> MADE IN JAPAN | I18: ='[1]shipper master'!C54 -> MADE IN JAPAN

Sheet invoice
A1: INVOICE
A2: ='shipper master'!C2 -> SHUNYA CO., LTD.
A3: ='shipper master'!C3 -> KENSHIN BLDG., 1F, 1-22-10 DOUGENZAKA,
A4: ='shipper master'!C4 -> SHIBUYA-KU 150-0043 | K4: ='shipper master'!C6 -> 0
A5: ='shipper master'!C5 -> TEL : +81(0)3-5459-1177 | K5: ='shipper master'!C7 -> 0
A6: IMPORTER | E6: INVOICE NO. | K6: CASE MARK
A7: ='shipper master'!C9 -> VIVAN GARMENTS VIET NAM COMPANY LIMITED | E7: ='shipper master'!C26 -> SY-5600605-VT-DD-01
A8: ='shipper master'!C10 -> No.10 , D17 Street , Sai Gon South Residential Area | E8: INVOICE DATE | K8: ='shipper master'!C49 -> SY-5600605-VT-DD-01
A9: ='shipper master'!C11 -> Hamlet 3 , Long Hau Commune , Can Giuoc District, | E9: ='shipper master'!C25 -> June, 07 2024 | K9: ='[1]shipper master'!C50 -> VIVAN GARMENTS VIET NAM
A10: ='shipper master'!C12 -> Long An Province , VietNam | E10: CONTRACT NO. | K10: ='[1]shipper master'!C51 -> COMPANY LIMITED
A11: ='shipper master'!C13 -> TEL : ( 084 ) 097 22 00 798 ATTN : MR. TUAN | E11: ='shipper master'!C27 -> SY-5600605-VT-DD-01 | K11: ='[1]shipper master'!C52 -> HOCHIMINH-CITY, VIETNAM
A12: CONSIGNEE | E12: ORDER NO. | K12: C/NO. 1-19
A13: ='shipper master'!C15 -> - SAME AS BUYER - | E13: ='shipper master'!C30 -> 0 | K13: MADE IN JAPAN
A14: ='shipper master'!C16 -> 0 | E14: ORDER DATE
A15: ='shipper master'!C17 -> 0 | E15: ='shipper master'!C29 -> 0
A16: ='shipper master'!C18 -> 0 | E16: L/C NO.
A17: ='shipper master'!C19 -> 0
A18: PAYMENT METHOD
A19: ='shipper master'!C21 -> NO COMMERCIAL
A20: SHIPPED PER | C20: FROM | E20: TO | K20: VIA
A21: ='shipper master'!C24 -> AIRCRAFT | C21: ='shipper master'!C32 -> TOKYO, JAPAN | F21: ='shipper master'!C33 -> HOCHIMINH-CITY, VIETNAM
A22: C/NO. | B22: ART NO. | C22: DESCRIPTION OF GOODS | D22: COLOR | G22: SIZE | J22: Q'TY | K22: U/PRICE | L22: AMOUNT
B24: ='shipper master'!C36 -> FABRIC & PARTS FOR WEAR & SAMPLE CLOTHES | K24: ='shipper master'!C48 -> F.O.B. TOKYO IN YEN
B26: ='shipper master'!C37 -> 0
J27: ='NARITA '!E35 -> 36 | K27: ='NARITA '!F35 -> M. | L27: ='NARITA '!H35 -> 138600
B28: ='shipper master'!C38 -> - DETAILS AS PER ATTACHED SHEET - | J28: ='NARITA (2)'!E71 -> 999 | K28: ='NARITA (2)'!F71 -> M. | L28: ='NARITA (2)'!H71 -> 229320
J29: ='NARITA '!E36 -> 936 | K29: ='NARITA '!F36 -> PCS. | L29: ='NARITA '!H36 -> 992500
J30: ='NARITA (2)'!E72 -> 1695 | K30: ='NARITA (2)'!F72 -> PCS. | L30: ='NARITA (2)'!H72 -> 178318
J31: ='NARITA '!E37 -> 0 | K31: SET. | L31: ='NARITA '!H37 -> 0
J32: ='NARITA (2)'!E73 -> 130 | K32: SET. | L32: ='NARITA (2)'!H73 -> 4600
B33: TOTAL : | C33: =J28+J27 -> 1035 | D33: M. | E33: =J29+J30 -> 2631 | H33: =H29 -> 0 | I33: PCS | J33: =J31+J32 -> 130 | K33: SET. | L33: =SUM(L27:L32) -> 1543338
A36: ='shipper master'!C63 -> " THESE GOODS WILL BE RETURN TO JAPAN | H36: " NO COMMER VALUE | J36: " NO COMMERCIAL VALUE
A37: ='shipper master'!C64 -> AFTER MANUFACTURED AT VIET NAM " | H37: VALUE FOR CUSTOMS PURPOSE ONLY " | J37: VALUE FOR CUSTOMS PURPOSE ONLY "
C38: ='shipper master'!C58 -> 0
A39: ='shipper master'!C60 -> COUNTRY OF ORIGIN : JAPAN
A41: TOTAL CARTONS : | C41: 19CARTONS
A42: TOTAL GROSS WEIGHT : | C42: KGS

Sheet NARITA 
A2: - ATTACHED SHEET -
A4: C/NO. | B4: ART NO. | C4: COLOR | D4: DESCRIPTION OF GOODS | E4: Q'TY | F4: U/PRICE | H4: AMOUNT | I4: 佐川伝票・明細 | J4: 搬入日 | K4: 伝票NO | L4: 搬入内容 | M4: 数量 | N4: 箱数
B6: (H.S. CODE) | D6: =[2]invoice!B24 -> FABRIC & PARTS FOR WEAR & SAMPLE CLOTHES | G6: ='[1]shipper master'!C48 -> F.O.B. TOKYO IN YEN
D7: MADE IN JAPAN
A8: 1 | D8: STYLE: cc24aw-41 | I8: 佐川452575656761 | N8: 1
B9: AC731 | C9: C/#7 KHAKI | D9: KNIT FABRIC | E9: 36 | F9: M. | G9: 3850 | H9: =E9*G9 -> 138600
B10: KNIT FABRIC | D10: ACRYLIC 94.7% NYLON 4.7% POLYURETHANE 0.6%
B11: 後染めリブ生地 丸編み | D11: WIDTH:60CM (310ｇ/㎡ )
B12: 長繊維、プリント加工なし
A14: 2-14 | D14: STYLE: cc24aw-41 | I14: 入庫NO,22064335 | N14: 13
B15: men's used boa jacket | C15: C/#KHAKI | E15: 81 | F15: PCS. | G15: 3000 | H15: =E15*G15 -> 243000
B16: POLYESTER 100%
B17: 古着 プリントなし
D20: STYLE: cc24aw-41
B21: men's used quilt jacket | C21: C/#KHAKI | E21: 112 | F21: PCS. | G21: 3000 | H21: =E21*G21 -> 336000
B22: POLYESTER 100%
B23: 古着 プリントなし
D26: STYLE: cc24aw-30/cc24aw-52
B27: men's used muffler | C27: C/#MIX | E27: 193 | F27: PCS. | G27: 2000 | H27: =E27*G27 -> 386000
B28: ACRYLIC 100%
B29: 古着 プリントなし
B32: 77circa woven tag | D32: woven tag 材質：ポリエステル100% | E32: 550 | F32: PCS. | G32: 50 | H32: =E32*G32 -> 27500
B35: TOTAL : | C35: 14CARTONS | E35: =SUMIF($F$8:$F$33,"M.",$E$8:$E$33) -> 36 | F35: M. | H35: =SUMIF($F$8:$F$33,"M.",$H$8:$H$33) -> 138600
E36: =SUMIF($F$8:$F$33,"PCS.",$E$8:$E$33) -> 936 | F36: PCS. | H36: =SUMIF($F$8:$F$33,"PCS.",$H$8:$H$33) -> 992500
E37: =SUMIF($F$8:$F$33,"SET.",$E$8:$E$33) -> 0 | F37: SET. | H37: =SUMIF($F$8:$F$33,"SET.",$H$8:$H$33) -> 0
H38: =SUM(H35:H37) -> 1131100

Sheet NARITA (2)
A2: - ATTACHED SHEET -
A4: C/NO. | B4: ART NO. | C4: COLOR | D4: DESCRIPTION OF GOODS | E4: Q'TY | F4: U/PRICE | H4: AMOUNT | I4: 佐川伝票・明細 | J4: 搬入日 | K4: 伝票NO | L4: 搬入内容 | M4: 数量 | N4: 箱数
B6: (H.S. CODE) | D6: ='NARITA '!D6 -> FABRIC & PARTS FOR WEAR & SAMPLE CLOTHES | G6: ='[3]shipper master'!C48 -> F.O.B. TOKYO IN YEN
D7: MADE IN JAPAN
A9: 15 | D9: 23SY-67 | I9: 入庫NO.22064192 | M9: 1
B10: 3CF(URA ATAMAAWASE）DA*DA | C10: 315 | D10: ZIPPER 材質：polyester
D11: 29CM-8 32CM-169 | E11: 250 | F11: PCS. | G11: 280 | H11: 70000
A14: 16 | D14: 23SY-67 | I14: 佐川457813901285 | M14: 1
B15: HA-300-2 | C15: 315 | D15: CORD 材質：ACRYLIC100％
D16: BK-210M 46-46M 63-46M | E16: 302 | F16: M. | G16: 50 | H16: =E16*G16 -> 15100
B19: PRESTIGE Hang Tag | D19: Hang tag 材質：紙 | E19: 345 | F19: PCS. | G19: 50 | H19: =E19*G19 -> 17250
A21: 17-19 | D21: cc24aw-03 | I21: 佐川4529-7621-5720 | M21: 3
B22: AZP6517 | C22: N | D22: JUMP RING 材質：真鍮 | E22: 100 | F22: PCS. | G22: 8 | H22: =E22*G22 -> 800
B23: AZP6516 | C23: N | D23: D-RING 材質：真鍮 | E23: 100 | F23: PCS. | G23: 8 | H23: =E23*G23 -> 800
B24: 1200 | D24: TAPE 14ｍｍ 材質：ポリエステル
D25: ＃BK-66ｍ ＃1107-66ｍ | E25: 132 | F25: M. | G25: 30 | H25: =E25*G25 -> 3960
B26: CECILE | D26: BUTTON 材質：プラスチック
D27: ＃BK-69 ＃91-125 | E27: 194 | F27: PCS. | G27: 7 | H27: =E27*G27 -> 1358
B28: SIC147 | D28: TAPE 25mm 材質：ポリエステル
D29: ＃50-5ｍ ＃103-9ｍ | E29: 14 | F29: M. | G29: 450 | H29: =E29*G29 -> 6300
D31: cc24aw-30
B32: 8070 | C32: 1-1 | D32: COTTON 100% PIECE-DYED SLEEK | E32: 44 | F32: M. | G32: 600 | H32: =E32*G32 -> 26400
B33: SUPUNBONDED | C33: W | D33: SUPUNBONDED NONWOVEN FABRIC 材質：不織布 | E33: 45 | F33: M. | G33: 50 | H33: =E33*G33 -> 2250
B34: 5VS OP DA86 | C34: 580 | D34: ZIPPER 40CM 材質：銅合金 | E34: 40 | F34: PCS. | G34: 125 | H34: =E34*G34 -> 5000
D36: CC24AW-28
B37: 1000 | C37: 2 | D37: COTTON 100% PIECE-DYED SLEEK | E37: 4 | F37: M. | G37: 480 | H37: =E37*G37 -> 1920
B38: 3YGKB C GSN8 | C38: 501 | D38: ZIPPER 15.5CM 材質：銅合金 | E38: 30 | F38: PCS. | G38: 65 | H38: =E38*G38 -> 1950
B39: 521K | C39: N | D39: HOOK 材質：真鍮 | E39: 30 | F39: SET. | G39: 80 | H39: =E39*G39 -> 2400
D41: cc24aw-43
B42: 2002S | D42: POLYESTER100% LINING
D43: #BK-25M ＃63-23M #77-7M | E43: 55 | F43: M. | G43: 410 | H43: =E43*G43 -> 22550
B44: UNICORN775 | D44: BUTTON 材質：ポリエステル
D45: #08-208 #45-185 #46-69 | E45: 462 | F45: PCS. | G45: 60 | H45: =E45*G45 -> 27720
D47: CC24AW-08
B48: 620 | D48: CHIPD CORD 材質：アクリル チップ先端：シリコン
D49: 130CM #28-3 #3-4 #46-6 | E49: 13 | F49: PCS. | G49: 600 | H49: =E49*G49 -> 7800
D50: 140CM #28-1 #3-4 #46-2 | E50: 7 | F50: PCS. | G50: 600 | H50: =E50*G50 -> 4200
B51: 5900 | C51: W | D51: PIPING 材質：ポリエステル | E51: 72 | F51: M. | G51: 155 | H51: =E51*G51 -> 11160
B52: 5VS C DA86 | D52: ZIPPER 材質：銅合金
D53: 15CM #519-6 #580-8 #220-12 | E53: 26 | F53: PCS. | G53: 120 | H53: =E53*G53 -> 3120
...

Sheet LABEL
A2: LABEL SHEET -
A4: C/NO. | B4: ART NO. | C4: DESCRIPTION OF GOODS | D4: 原産国
A5: 1 | C5: STYLE: cc24aw-41
B6: AC731 | C6: KNIT FABRIC | D6: MADE IN JAPAN
B7: KNIT FABRIC | C7: ACRYLIC 94.7% NYLON 4.7% POLYURETHANE 0.6% | D7: SHUNYA CO., LTD.
B8: 後染めリブ生地 丸編み | C8: WIDTH:60CM (310ｇ/㎡ )
B9: 長繊維、プリント加工なし
B11: ART NO. | C11: DESCRIPTION OF GOODS | D11: 原産国
A12: 2-14 | C12: STYLE: cc24aw-41
B13: men's used boa jacket | D13: MADE IN JAPAN
B14: POLYESTER 100% | D14: SHUNYA CO., LTD.
B15: 古着 プリントなし
C18: STYLE: cc24aw-41 | D18: 原産国
B19: men's used quilt jacket
B20: POLYESTER 100% | D20: MADE IN JAPAN
B21: 古着 プリントなし | D21: SHUNYA CO., LTD.
C24: STYLE: cc24aw-30/cc24aw-52
B25: men's used muffler | D25: 原産国
B26: ACRYLIC 100%
B27: 古着 プリントなし | D27: MADE IN JAPAN
D28: SHUNYA CO., LTD.
B30: 77circa woven tag | C30: woven tag 材質：ポリエステル100%
A32: C/NO. | B32: ART NO. | C32: DESCRIPTION OF GOODS | D32: 原産国
A33: 15 | C33: 23SY-67
B34: 3CF(URA ATAMAAWASE）DA*DA | C34: ZIPPER 材質：polyester | D34: MADE IN JAPAN
C35: 29CM-8 32CM-169 | D35: SHUNYA CO., LTD.
A38: C/NO. | B38: ART NO. | C38: DESCRIPTION OF GOODS | D38: 原産国
A39: 16 | C39: 23SY-67
B40: HA-300-2 | C40: CORD 材質：ACRYLIC100％ | D40: MADE IN JAPAN
C41: BK-210M 46-46M 63-46M | D41: SHUNYA CO., LTD.
B44: PRESTIGE Hang Tag | C44: Hang tag 材質：紙
A46: C/NO. | B46: ART NO. | C46: DESCRIPTION OF GOODS | D46: 原産国
A47: 17-19 | C47: cc24aw-03
B48: AZP6517 | C48: JUMP RING 材質：真鍮
B49: AZP6516 | C49: D-RING 材質：真鍮
B50: 1200 | C50: TAPE 14ｍｍ 材質：ポリエステル
C51: ＃BK-66ｍ ＃1107-66ｍ
B52: CECILE | C52: BUTTON 材質：プラスチック
C53: ＃BK-69 ＃91-125
B54: SIC147 | C54: TAPE 25mm 材質：ポリエステル
...
