Workbook
Name pricetable: #REF!
Name pricetable: #REF!
Name pricetable: #REF!
Name pricetable: #REF!
Name pricetable: #REF!
Name pricetable: #REF!

Sheet shipper master
A1: 1 | B1: S/CODE | C1: SHIPPER NAME
A2: =A1+1 -> 2 | B2: SHIPPER | C2: SHUNYA CO., LTD.
A3: =A2+1 -> 3 | B3: SHIPPER ADDRESS 1 | C3: KENSHIN BLDG., 1F, 1-22-10 DOUGENZAKA,
A4: =A3+1 -> 4 | B4: SHIPPER ADDRESS 2 | C4: SHIBUYA-KU 150-0043
A5: =A4+1 -> 5 | B5: SHIPPER ADDRESS 3 | C5: TEL : +81(0)3-5459-1177
A6: =A5+1 -> 6 | B6: TEL
A7: =A6+1 -> 7 | B7: FAX
A8: =A7+1 -> 8 | B8: ATTN OR VAT NO.
A9: =A8+1 -> 9 | B9: BUYER | C9: VIVAN GARMENTS VIET NAM COMPANY LIMITED
A10: =A9+1 -> 10 | B10: BUYER ADDRESS1 | C10: No.10 , D17 Street , Sai Gon South Residential Area
A11: =A10+1 -> 11 | B11: BUYER ADDRESS2 | C11: Hamlet 3 , Long Hau Commune , Can Giuoc District,
A12: =A11+1 -> 12 | B12: BUYER ADDRESS3 | C12: Long An Province , VietNam
A13: =A12+1 -> 13 | B13: TEL/FAX | C13: TEL : ( 084 ) 097 22 00 798 ATTN : MR. TUAN
A14: =A13+1 -> 14 | B14: ATTN
A15: =A14+1 -> 15 | B15: CONSIGNEE : | C15: - SAME AS BUYER -
A16: =A15+1 -> 16 | B16: CONSIGNEE ADDRESS1
A17: =A16+1 -> 17 | B17: CONSIGNEE ADDRESS2
A18: =A17+1 -> 18 | B18: CONSIGNEE ADDRESS3
A19: =A18+1 -> 19 | B19: TEL
A20: =A19+1 -> 20 | B20: FAX
A21: =A20+1 -> 21 | B21: ATTN | C21: NO COMMERCIAL
A22: =A21+1 -> 22 | B22: PAYMENT 1
A23: =A22+1 -> 23 | B23: PAYMENT 2
A24: =A23+1 -> 24 | B24: SHIPPER PER | C24: AIRCRAFT
A25: =A24+1 -> 25 | B25: INVOICE DATE | C25: May, 08 2024
A26: =A25+1 -> 26 | B26: INVOICE NO. | C26: SY-5400508-VT-DD-01
A27: =A26+1 -> 27 | B27: CONTRACT NO. | C27: =C26 -> SY-5400508-VT-DD-01
A28: =A27+1 -> 28 | B28: CONTRACT DATE
A29: =A28+1 -> 29 | B29: ORDER DATE
A30: =A29+1 -> 30 | B30: ORDER NO.
A31: =A30+1 -> 31 | B31: L/C DATE
A32: =A31+1 -> 32 | B32: FROM | C32: TOKYO, JAPAN
A33: =A32+1 -> 33 | B33: TO | C33: HOCHIMINH-CITY, VIETNAM
A34: =A33+1 -> 34 | B34: VIA
A35: =A34+1 -> 35 | B35: SHIPPING TERMS | C35: F.O.B. TOKYO IN YEN
A36: =A35+1 -> 36 | B36: TITTLE 1 | C36: FABRIC & PARTS FOR WEAR & SAMPLE CLOTHES
A37: =A36+1 -> 37 | B37: TITTLE 2
A38: =A37+1 -> 38 | B38: ATTACHE | C38: - DETAILS AS PER ATTACHED SHEET -
A39: =A38+1 -> 39 | B39: C/NO.
A40: =A39+1 -> 40 | B40: STYLE NO.
...

Sheet case mark 
A2: ='shipper master'!C49 -> SY-5400508-VT-DD-01 | I2: ='shipper master'!C49 -> SY-5400508-VT-DD-01
A3: ='[1]shipper master'!C50 -> VIVAN GARMENTS VIET NAM | I3: ='[1]shipper master'!C50 -> VIVAN GARMENTS VIET NAM
A4: ='[1]shipper master'!C51 -> COMPANY LIMITED | I4: ='[1]shipper master'!C51 -> COMPANY LIMITED
A5: ='[1]shipper master'!C52 -> HOCHIMINH-CITY, VIETNAM | I5: ='[1]shipper master'!C52 -> HOCHIMINH-CITY, VIETNAM
A6: C/NO. | C6: 1 | I6: C/NO. | K6: 2
A7: ='[1]shipper master'!C54 -> MADE IN JAPAN | I7: ='[1]shipper master'!C54 -> MADE IN JAPAN
A13: ='shipper master'!C49 -> SY-5400508-VT-DD-01 | I13: ='shipper master'!C49 -> SY-5400508-VT-DD-01
A14: ='[1]shipper master'!C50 -> VIVAN GARMENTS VIET NAM | I14: ='[1]shipper master'!C50 -> VIVAN GARMENTS VIET NAM
A15: ='[1]shipper master'!C51 -> COMPANY LIMITED | I15: ='[1]shipper master'!C51 -> COMPANY LIMITED
A16: ='[1]shipper master'!C52 -> HOCHIMINH-CITY, VIETNAM | I16: ='[1]shipper master'!C52 -> HOCHIMINH-CITY, VIETNAM
A17: C/NO. | C17: 3 | I17: C/NO. | K17: 4
A18: ='[1]shipper master'!C54 -> MADE IN JAPAN | I18: ='[1]shipper master'!C54 -> MADE IN JAPAN

Sheet invoice
A1: INVOICE
A2: ='shipper master'!C2 -> SHUNYA CO., LTD.
A3: ='shipper master'!C3 -> KENSHIN BLDG., 1F, 1-22-10 DOUGENZAKA,
A4: ='shipper master'!C4 -> SHIBUYA-KU 150-0043 | K4: ='shipper master'!C6 -> 0
A5: ='shipper master'!C5 -> TEL : +81(0)3-5459-1177 | K5: ='shipper master'!C7 -> 0
A6: IMPORTER | E6: INVOICE NO. | K6: CASE MARK
A7: ='shipper master'!C9 -> VIVAN GARMENTS VIET NAM COMPANY LIMITED | E7: ='shipper master'!C26 -> SY-5400508-VT-DD-01
A8: ='shipper master'!C10 -> No.10 , D17 Street , Sai Gon South Residential Area | E8: INVOICE DATE | K8: ='shipper master'!C49 -> SY-5400508-VT-DD-01
A9: ='shipper master'!C11 -> Hamlet 3 , Long Hau Commune , Can Giuoc District, | E9: ='shipper master'!C25 -> May, 08 2024 | K9: ='[1]shipper master'!C50 -> VIVAN GARMENTS VIET NAM
A10: ='shipper master'!C12 -> Long An Province , VietNam | E10: CONTRACT NO. | K10: ='[1]shipper master'!C51 -> COMPANY LIMITED
A11: ='shipper master'!C13 -> TEL : ( 084 ) 097 22 00 798 ATTN : MR. TUAN | E11: ='shipper master'!C27 -> SY-5400508-VT-DD-01 | K11: ='[1]shipper master'!C52 -> HOCHIMINH-CITY, VIETNAM
A12: CONSIGNEE | E12: ORDER NO. | K12: C/NO. 1-9
A13: ='shipper master'!C15 -> - SAME AS BUYER - | E13: ='shipper master'!C30 -> 0 | K13: MADE IN JAPAN
A14: ='shipper master'!C16 -> 0 | E14: ORDER DATE
A15: ='shipper master'!C17 -> 0 | E15: ='shipper master'!C29 -> 0
A16: ='shipper master'!C18 -> 0 | E16: L/C NO.
A17: ='shipper master'!C19 -> 0
A18: PAYMENT METHOD
A19: ='shipper master'!C21 -> NO COMMERCIAL
A20: SHIPPED PER | C20: FROM | E20: TO | K20: VIA
A21: ='shipper master'!C24 -> AIRCRAFT | C21: ='shipper master'!C32 -> TOKYO, JAPAN | F21: ='shipper master'!C33 -> HOCHIMINH-CITY, VIETNAM
A22: C/NO. | B22: ART NO. | C22: DESCRIPTION OF GOODS | D22: COLOR | G22: SIZE | J22: Q'TY | K22: U/PRICE | L22: AMOUNT
B24: ='shipper master'!C36 -> FABRIC & PARTS FOR WEAR & SAMPLE CLOTHES | K24: ='shipper master'!C48 -> F.O.B. TOKYO IN YEN
B26: ='shipper master'!C37 -> 0
J27: ='NARITA '!E39 -> 244.5 | K27: ='NARITA '!F39 -> M. | L27: ='NARITA '!H39 -> 244420
B28: ='shipper master'!C38 -> - DETAILS AS PER ATTACHED SHEET - | J28: ='NARITA (2)'!E26 -> 1462 | K28: ='NARITA (2)'!F26 -> M. | L28: ='NARITA (2)'!H26 -> 87880
J29: ='NARITA '!E40 -> 1001 | K29: ='NARITA '!F40 -> PCS. | L29: ='NARITA '!H40 -> 47000
J30: ='NARITA (2)'!E27 -> 1950 | K30: ='NARITA (2)'!F27 -> PCS. | L30: ='NARITA (2)'!H27 -> 84500
J31: ='NARITA '!E41 -> 0 | K31: SET. | L31: ='NARITA '!H41 -> 0
J32: ='NARITA (2)'!E28 -> 370 | K32: SET. | L32: ='NARITA (2)'!H28 -> 38600
B33: TOTAL : | C33: =J28+J27 -> 1706.5 | D33: M. | E33: =J29+J30 -> 2951 | H33: =H29 -> 0 | I33: PCS | J33: =J31+J32 -> 370 | K33: SET. | L33: =SUM(L27:L32) -> 502400
A36: ='shipper master'!C63 -> " THESE GOODS WILL BE RETURN TO JAPAN | H36: " NO COMMER VALUE | J36: " NO COMMERCIAL VALUE
A37: ='shipper master'!C64 -> AFTER MANUFACTURED AT VIET NAM " | H37: VALUE FOR CUSTOMS PURPOSE ONLY " | J37: VALUE FOR CUSTOMS PURPOSE ONLY "
C38: ='shipper master'!C58 -> 0
A39: ='shipper master'!C60 -> COUNTRY OF ORIGIN : JAPAN
A41: TOTAL CARTONS : | C41: 9CARTONS
A42: TOTAL GROSS WEIGHT : | C42: KGS

Sheet NARITA 
A2: - ATTACHED SHEET -
A4: C/NO. | B4: ART NO. | C4: COLOR | D4: DESCRIPTION OF GOODS | E4: Q'TY | F4: U/PRICE | H4: AMOUNT | I4: 佐川伝票・明細 | J4: 搬入日 | K4: 伝票NO | L4: 搬入内容 | M4: 数量 | N4: 箱数
B6: (H.S. CODE) | D6: =[2]invoice!B24 -> FABRIC & PARTS FOR WEAR & SAMPLE CLOTHES | G6: ='[1]shipper master'!C48 -> F.O.B. TOKYO IN YEN
D7: MADE IN JAPAN
A8: 1-2 | D8: STYLE: 24A-PT01/02/03 | N8: 2
B9: A5100 | C9: C/#BK | D9: WOVEN FABRIC | E9: 138 | F9: M. | G9: 590 | H9: =E9*G9 -> 81420
B10: WOVEN FABRIC | D10: acetate 100% | I10: 入庫NO.22063388
B11: 朱子織 後染めサテン生地 | D11: WIDTH:122CM (135ｇ/㎡ )
B12: 長繊維、テクスチャード加工無し
D14: STYLE: AVANI-02 | I14: 入庫NO.22063386 | L14: 箱NO.2－4 | N14: 4
A15: 3-6 | B15: men's used jeans | C15: C/#BLUE | E15: 50 | F15: M. | G15: 1500 | H15: =E15*G15 -> 75000
B16: cotton100% | C16: c/#BLACK | E16: 33 | F16: M. | G16: 1500 | H16: =E16*G16 -> 49500
B17: made in japan
B18: 短繊維 テクスチャード加工無し
D20: STYLE、AVANI-01 | L20: 箱NO.1
B21: NFD-30 | C21: C/#F-4 BEIGE | D21: WOVEN FABRIC | E21: 5 | F21: M. | G21: 1000 | H21: =E21*G21 -> 5000
B22: NYLON100% | C22: c/#F-15 GRAY | D22: NYLON 100% | E22: 3.5 | F22: M. | G22: 1000 | H22: =E22*G22 -> 3500
B23: 後染め綾織 タフタ生地 | D23: WIDTH:145M (174ｇ/㎡ )
B24: 長繊維、テクスチャード加工無し
D26: STYLE、24A-SH01
B27: ST1005 shell button PINCTA DA MARGARITIFERA | C27: c/#takase | D27: shell PINCTA DA MARGARITIFERA 11.5mm | E27: 500 | F27: PCS. | G27: 45 | H27: =E27*G27 -> 22500
B28: SB1005 shell button PINCTA DA MARGARITIFERA | C28: c/#kokucho | D28: shell PINCTA DA MARGARITIFERA 11.5mm | E28: 500 | F28: PCS. | G28: 45 | H28: =E28*G28 -> 22500
B30: lady's satin pants CLOTHES | D30: 24A-PT03 sample | E30: 1 | F30: PCS. | G30: 2000 | H30: =E30*G30 -> 2000
A32: 7 | D32: STYLE: 24A-SH01 | N32: 1
B33: 11267 | C33: C/#51 WHITE | D33: WOVEN FABRIC | E33: 5 | F33: M. | G33: 2000 | H33: =E33*G33 -> 10000
B34: WOVEN FABRIC | C34: C/#19 KHAKI | D34: COTTON 100% | E34: 5 | F34: M. | G34: 2000 | H34: =E34*G34 -> 10000 | I34: 伝票457815962424
B35: 平織 後染めブロード生地 | C35: C/#20 BLACK | D35: WIDTH:145CM (115ｇ/㎡ ) | E35: 5 | F35: M. | G35: 2000 | H35: =E35*G35 -> 10000
B36: 短繊維、プリント加工あり
B39: TOTAL : | C39: 7CARTONS | E39: =SUMIF($F$8:$F$36,"M.",$E$8:$E$36) -> 244.5 | F39: M. | H39: =SUMIF($F$8:$F$36,"M.",$H$8:$H$36) -> 244420
E40: =SUMIF($F$8:$F$36,"PCS.",$E$8:$E$36) -> 1001 | F40: PCS. | H40: =SUMIF($F$8:$F$36,"PCS.",$H$8:$H$36) -> 47000
H42: =SUM(H39:H41) -> 291420

Sheet NARITA (2)
A2: - ATTACHED SHEET -
A4: C/NO. | B4: ART NO. | C4: COLOR | D4: DESCRIPTION OF GOODS | E4: Q'TY | F4: U/PRICE | H4: AMOUNT | I4: 佐川伝票・明細 | J4: 搬入日 | K4: 伝票NO | L4: 搬入内容 | M4: 数量 | N4: 箱数
B6: (H.S. CODE) | D6: ='NARITA '!D6 -> FABRIC & PARTS FOR WEAR & SAMPLE CLOTHES | G6: ='[3]shipper master'!C48 -> F.O.B. TOKYO IN YEN
D7: MADE IN JAPAN
A9: 8 | D9: STYLE: 23sy-67 | M9: 1
B10: AST1018 | C10: 09 BLACK | D10: CORD STOPPER 材質：ポリカーポネイト/真鍮 | E10: 1250 | F10: PCS. | G10: 40 | H10: =E10*G10 -> 50000
B11: SIC3141 | C11: BK | D11: ELASTICK CORD 材質：polyester100% | E11: 1050 | F11: M. | G11: 35 | H11: 36750 | I11: 入庫NO.22063385
B12: SIC199 | C12: BK | D12: TAPE 材質：polyester 100% | E12: 90 | F12: M. | G12: 50 | H12: 4500
B13: 2CC | C13: 315 | D13: ZIPPER 22CM 材質：polyester UP | E13: 500 | F13: PCS. | G13: 60 | H13: =E13*G13 -> 30000
B14: 3CF(URA ATAMAAWASE）DA*DA | C14: 315 | D14: ZIPPER 材質：polyester 29CM-8 32CM-169 | E14: 150 | F14: M. | G14: 40 | H14: =E14*G14 -> 6000
A16: 9 | D16: 23SY-63 | M16: 1
B17: 500 | C17: SPC | D17: EYELET | E17: 185 | F17: SET. | G17: 10 | H17: =E17*G17 -> 1850
B18: 500 | C18: BOX | D18: EYELET | E18: 185 | F18: SET. | G18: 10 | H18: 36750 | I18: 入庫NO.22063220
B19: PACKING | C19: D/G | E19: 200 | F19: PCS. | G19: 3 | H19: 4500
B20: FB011 | C20: 100 | D20: TAPE 12MM | E20: 40 | F20: M. | G20: 135 | H20: =E20*G20 -> 5400
B21: FB011 | C21: 50 | D21: TAPE 12MM | E21: 40 | F21: M. | G21: 135 | H21: =E21*G21 -> 5400
B22: 1000 | D22: COTTON 100% PIECE-DYED SLEEK W/102CM #125-31M #802-1-31M | E22: 62 | F22: M. | G22: 470 | H22: =E22*G22 -> 29140
B24: 131-500 | C24: 001 | D24: TAPE 4ＭＭ | E24: 30 | F24: M. | G24: 23 | H24: 690
B26: TOTAL : | C26: 2CARTONS | E26: =SUMIF($F$9:$F$24,"M.",$E$9:$E$24) -> 1462 | F26: M. | H26: =SUMIF($F$9:$F$24,"M.",$H$9:$H$24) -> 87880
E27: =SUMIF($F$9:$F$24,"PCS.",$E$9:$E$24) -> 1950 | F27: PCS. | H27: =SUMIF($F$9:$F$24,"PCS.",$H$9:$H$24) -> 84500
E28: =SUMIF($F$9:$F$24,"SET.",$E$9:$E$24) -> 370 | F28: SET. | H28: =SUMIF($F$9:$F$24,"SET.",$H$9:$H$24) -> 38600
B29: TOTAL : | G29: TOTAL | H29: =SUM(H9:H24) -> 210980

Sheet サンプル製品カタログ
D1: ITEM
B2: NAME | C2: color | E2: lady's or men's | F2: WOVEN or KNIT | G2: picture | H2: Composition | I2: packingNo.
B3: lady's satin pants CLOTHES | C3: C/#GRAY | D3: lady's satin pants CLOTHES | E3: lady's | F3: WOVEN FABRIC | H3: FRONT COTTON 100% | I3: 3

Sheet LABEL
A2: LABEL SHEET -
A4: C/NO. | B4: ART NO. | C4: DESCRIPTION OF GOODS | D4: 原産国
A5: 1-2 | C5: STYLE: 24A-PT01/02/03
B6: A5100 | C6: WOVEN FABRIC | D6: MADE IN JAPAN
B7: WOVEN FABRIC | C7: acetate 100% | D7: SHUNYA CO., LTD.
B8: 朱子織 後染めサテン生地 | C8: WIDTH:122CM (135ｇ/㎡ )
B9: 長繊維、テクスチャード加工無し
A12: C/NO. | B12: ART NO. | C12: DESCRIPTION OF GOODS | D12: 原産国
A13: 3 | C13: STYLE、AVANI-01
B14: NFD-30 | C14: WOVEN FABRIC
B15: NYLON100% | C15: NYLON 100%
B16: 後染め綾織 タフタ生地 | C16: WIDTH:145M (174ｇ/㎡ ) | D16: MADE IN JAPAN
B17: 長繊維、テクスチャード加工無し | D17: SHUNYA CO., LTD.
C19: STYLE、24A-SH01
B20: ST1005 shell button PINCTA DA MARGARITIFERA | C20: shell PINCTA DA MARGARITIFERA 11.5mm
B21: SB1005 shell button PINCTA DA MARGARITIFERA | C21: shell PINCTA DA MARGARITIFERA 11.5mm
B23: lady's satin pants CLOTHES | C23: 24A-PT03 sample
A25: 3 | B25: ART NO. | C25: DESCRIPTION OF GOODS | D25: 原産国
A26: 4-6 | C26: STYLE: AVANI-02
B27: men's used jeans | D27: MADE IN JAPAN
B28: cotton100% | D28: SHUNYA CO., LTD.
B29: made in japan
B30: 短繊維 テクスチャード加工無し
A32: C/NO. | B32: ART NO. | C32: DESCRIPTION OF GOODS | D32: 原産国
A33: 7 | C33: STYLE: 24A-SH01
B34: 11267 | C34: WOVEN FABRIC | D34: MADE IN JAPAN
B35: WOVEN FABRIC | C35: COTTON 100% | D35: SHUNYA CO., LTD.
B36: 平織 後染めブロード生地 | C36: WIDTH:145CM (115ｇ/㎡ )
B37: 短繊維、プリント加工あり
A39: C/NO. | B39: ART NO. | C39: DESCRIPTION OF GOODS | D39: 原産国
A40: 8 | C40: STYLE: 23sy-67
B41: AST1018 | C41: CORD STOPPER 材質：ポリカーポネイト/真鍮 | D41: MADE IN JAPAN
B42: SIC3141 | C42: ELASTICK CORD 材質：polyester100% | D42: SHUNYA CO., LTD.
B43: SIC199 | C43: TAPE 材質：polyester 100%
B44: 2CC | C44: ZIPPER 22CM 材質：polyester UP
B45: 3CF(URA ATAMAAWASE）DA*DA | C45: ZIPPER 材質：polyester 29CM-8 32CM-169
A48: C/NO. | B48: ART NO. | C48: DESCRIPTION OF GOODS | D48: 原産国
A49: 9 | C49: 23SY-63
B50: 500 | C50: EYELET | D50: MADE IN JAPAN
B51: 500 | C51: EYELET | D51: SHUNYA CO., LTD.
...
