Workbook
Name pricetable: #REF!
Name pricetable: #REF!
Name pricetable: #REF!
Name pricetable: #REF!
Name pricetable: #REF!
Name pricetable: #REF!

Sheet shipper master
A1: 1 | B1: S/CODE | C1: SHIPPER NAME
A2: =A1+1 -> 2 | B2: SHIPPER | C2: SHUNYA CO., LTD.
A3: =A2+1 -> 3 | B3: SHIPPER ADDRESS 1 | C3: KENSHIN BLDG., 1F, 1-22-10 DOUGENZAKA,
A4: =A3+1 -> 4 | B4: SHIPPER ADDRESS 2 | C4: SHIBUYA-KU 150-0043
A5: =A4+1 -> 5 | B5: SHIPPER ADDRESS 3 | C5: TEL : +81(0)3-5459-1177
A6: =A5+1 -> 6 | B6: TEL
A7: =A6+1 -> 7 | B7: FAX
A8: =A7+1 -> 8 | B8: ATTN OR VAT NO.
A9: =A8+1 -> 9 | B9: BUYER | C9: VIVAN GARMENTS VIET NAM COMPANY LIMITED
A10: =A9+1 -> 10 | B10: BUYER ADDRESS1 | C10: D17 Street , Sai Gon South Residential Area
A11: =A10+1 -> 11 | B11: BUYER ADDRESS2 | C11: Hamlet 3 , Long Hau Commune , Can Giuoc District,
A12: =A11+1 -> 12 | B12: BUYER ADDRESS3 | C12: Long An Province , VietNam
A13: =A12+1 -> 13 | B13: TEL/FAX | C13: TEL : ( 084 ) 097 22 00 798 ATTN : MR. TUAN
A14: =A13+1 -> 14 | B14: ATTN
A15: =A14+1 -> 15 | B15: CONSIGNEE : | C15: - SAME AS BUYER -
A16: =A15+1 -> 16 | B16: CONSIGNEE ADDRESS1
A17: =A16+1 -> 17 | B17: CONSIGNEE ADDRESS2
A18: =A17+1 -> 18 | B18: CONSIGNEE ADDRESS3
A19: =A18+1 -> 19 | B19: TEL
A20: =A19+1 -> 20 | B20: FAX
A21: =A20+1 -> 21 | B21: ATTN | C21: NO COMMERCIAL
A22: =A21+1 -> 22 | B22: PAYMENT 1
A23: =A22+1 -> 23 | B23: PAYMENT 2
A24: =A23+1 -> 24 | B24: SHIPPER PER | C24: AIRCRAFT
A25: =A24+1 -> 25 | B25: INVOICE DATE | C25: Nov, 21 2024
A26: =A25+1 -> 26 | B26: INVOICE NO. | C26: SY-6001121-VT-DD-01
A27: =A26+1 -> 27 | B27: CONTRACT NO. | C27: =C26 -> SY-6001121-VT-DD-01
A28: =A27+1 -> 28 | B28: CONTRACT DATE
A29: =A28+1 -> 29 | B29: ORDER DATE
A30: =A29+1 -> 30 | B30: ORDER NO.
A31: =A30+1 -> 31 | B31: L/C DATE
A32: =A31+1 -> 32 | B32: FROM | C32: TOKYO, JAPAN
A33: =A32+1 -> 33 | B33: TO | C33: HOCHIMINH-CITY, VIETNAM
A34: =A33+1 -> 34 | B34: VIA
A35: =A34+1 -> 35 | B35: SHIPPING TERMS | C35: F.O.B. TOKYO IN YEN
A36: =A35+1 -> 36 | B36: TITTLE 1 | C36: FABRIC & PARTS FOR WEAR & SAMPLE CLOTHES
A37: =A36+1 -> 37 | B37: TITTLE 2
A38: =A37+1 -> 38 | B38: ATTACHE | C38: - DETAILS AS PER ATTACHED SHEET -
A39: =A38+1 -> 39 | B39: C/NO.
A40: =A39+1 -> 40 | B40: STYLE NO.
...

Sheet case mark 
A2: ='shipper master'!C26 -> SY-6001121-VT-DD-01 | I2: ='shipper master'!C26 -> SY-6001121-VT-DD-01
A3: ='[1]shipper master'!C50 -> VIVAN GARMENTS VIET NAM | I3: ='[1]shipper master'!C50 -> VIVAN GARMENTS VIET NAM
A4: ='[1]shipper master'!C51 -> COMPANY LIMITED | I4: ='[1]shipper master'!C51 -> COMPANY LIMITED
A5: ='[1]shipper master'!C52 -> HOCHIMINH-CITY, VIETNAM | I5: ='[1]shipper master'!C52 -> HOCHIMINH-CITY, VIETNAM
A6: C/NO. | C6: 1 | I6: C/NO. | K6: 2
A7: ='[1]shipper master'!C54 -> MADE IN JAPAN | I7: ='[1]shipper master'!C54 -> MADE IN JAPAN
A13: ='shipper master'!C26 -> SY-6001121-VT-DD-01 | I13: ='shipper master'!C26 -> SY-6001121-VT-DD-01
A14: ='[1]shipper master'!C50 -> VIVAN GARMENTS VIET NAM | I14: ='[1]shipper master'!C50 -> VIVAN GARMENTS VIET NAM
A15: ='[1]shipper master'!C51 -> COMPANY LIMITED | I15: ='[1]shipper master'!C51 -> COMPANY LIMITED
A16: ='[1]shipper master'!C52 -> HOCHIMINH-CITY, VIETNAM | I16: ='[1]shipper master'!C52 -> HOCHIMINH-CITY, VIETNAM
A17: C/NO. | C17: 3 | I17: C/NO. | K17: 4
A18: ='[1]shipper master'!C54 -> MADE IN JAPAN | I18: ='[1]shipper master'!C54 -> MADE IN JAPAN

Sheet invoice
A1: INVOICE
A2: ='[2]shipper master'!C2 -> SHUNYA CO., LTD.
A3: ='[2]shipper master'!C3 -> KENSHIN BLDG., 1F, 1-22-10 DOUGENZAKA,
A4: ='[2]shipper master'!C4 -> SHIBUYA-KU 150-0043 | K4: ='[2]shipper master'!C6 -> 0
A5: ='[2]shipper master'!C5 -> TEL : +81(0)3-5459-1177 | K5: ='[2]shipper master'!C7 -> 0
A6: IMPORTER | E6: INVOICE NO. | K6: CASE MARK
A7: ='[2]shipper master'!C9 -> VIVAN GARMENTS VIET NAM COMPANY LIMITED | E7: ='[2]shipper master'!C26 -> SY-5800906-VT-DD-01
A8: ='[2]shipper master'!C10 -> D17 Street , Sai Gon South Residential Area | E8: INVOICE DATE | K8: ='shipper master'!C26 -> SY-6001121-VT-DD-01
A9: ='[2]shipper master'!C11 -> Hamlet 3 , Long Hau Commune , Can Giuoc District, | E9: ='[2]shipper master'!C25 -> Sep, 06 2024 | K9: ='[1]shipper master'!C50 -> VIVAN GARMENTS VIET NAM
A10: ='[2]shipper master'!C12 -> Long An Province , VietNam | E10: CONTRACT NO. | K10: ='[1]shipper master'!C51 -> COMPANY LIMITED
A11: ='[2]shipper master'!C13 -> TEL : ( 084 ) 097 22 00 798 ATTN : MR. TUAN | E11: ='[2]shipper master'!C27 -> SY-5800906-VT-DD-01 | K11: ='[1]shipper master'!C52 -> HOCHIMINH-CITY, VIETNAM
A12: CONSIGNEE | E12: ORDER NO. | K12: C/NO. 1-20
A13: ='[2]shipper master'!C15 -> - SAME AS BUYER - | E13: ='[2]shipper master'!C30 -> 0 | K13: MADE IN JAPAN
A14: ='[2]shipper master'!C16 -> 0 | E14: ORDER DATE
A15: ='[2]shipper master'!C17 -> 0 | E15: ='[2]shipper master'!C29 -> 0
A16: ='[2]shipper master'!C18 -> 0 | E16: L/C NO.
A17: ='[2]shipper master'!C19 -> 0
A18: PAYMENT METHOD
A19: ='[2]shipper master'!C21 -> NO COMMERCIAL
A20: SHIPPED PER | C20: FROM | E20: TO | K20: VIA
A21: ='[2]shipper master'!C24 -> AIRCRAFT | C21: ='[2]shipper master'!C32 -> TOKYO, JAPAN | F21: ='[2]shipper master'!C33 -> HOCHIMINH-CITY, VIETNAM
A22: C/NO. | B22: ART NO. | C22: DESCRIPTION OF GOODS | D22: COLOR | G22: SIZE | J22: Q'TY | K22: U/PRICE | L22: AMOUNT
B24: ='[2]shipper master'!C36 -> FABRIC & PARTS FOR WEAR & SAMPLE CLOTHES | K24: ='[2]shipper master'!C48 -> F.O.B. TOKYO IN YEN
B26: ='[2]shipper master'!C37 -> 0
J27: ='NARITA '!E69+'NARITA (2)'!E77 -> 3771 | K27: ='[2]NARITA '!F28 -> M. | L27: ='NARITA '!H69+'NARITA (2)'!H77 -> 639776
B28: ='[2]shipper master'!C38 -> - DETAILS AS PER ATTACHED SHEET - | J28: ='NARITA '!E70+'NARITA (2)'!E78 -> 2085 | K28: ='[2]NARITA '!F29 -> PCS. | L28: ='NARITA '!H70+'NARITA (2)'!H78 -> 187608
J29: ='NARITA '!E71+'NARITA (2)'!E79 -> 790 | K29: ='NARITA '!F71 -> SET. | L29: ='NARITA '!H71+'NARITA (2)'!H79 -> 27070
B30: TOTAL : | C30: =J27 -> 3771 | D30: M. | E30: =J28 -> 2085 | H30: =#REF! -> #REF! | I30: PCS. | J30: =J29 -> 790 | K30: SET. | L30: =SUM(L27:L29) -> 854454
A33: ='[2]shipper master'!C63 -> " THESE GOODS WILL BE RETURN TO JAPAN | H33: " NO COMMER VALUE | J33: " NO COMMERCIAL VALUE
A34: ='[2]shipper master'!C64 -> AFTER MANUFACTURED AT VIET NAM " | H34: VALUE FOR CUSTOMS PURPOSE ONLY " | J34: VALUE FOR CUSTOMS PURPOSE ONLY "
C35: ='[2]shipper master'!C58 -> 0
A36: ='[2]shipper master'!C60 -> COUNTRY OF ORIGIN : JAPAN
A38: TOTAL CARTONS : | C38: 20CARTONS
A39: TOTAL GROSS WEIGHT : | C39: KGS

Sheet NARITA 
A2: - ATTACHED SHEET -
A4: C/NO. | B4: ART NO. | C4: COLOR | D4: DESCRIPTION OF GOODS | E4: Q'TY | F4: U/PRICE | H4: AMOUNT | I4: 佐川伝票・明細 | J4: 搬入日 | K4: 伝票NO | L4: 搬入内容 | M4: 数量 | N4: 箱数
B6: (H.S. CODE) | D6: =[3]invoice!B24 -> FABRIC & PARTS FOR WEAR & SAMPLE CLOTHES | G6: ='[1]shipper master'!C48 -> F.O.B. TOKYO IN YEN
D7: MADE IN JAPAN
A8: 1-2 | D8: STYLE: 25S-JK01(24SY-19) | N8: 2
B9: 012S0008298 | C9: C/#099 BLACK | D9: WOVEN FABRIC | E9: 51 | F9: M. | G9: 1040 | H9: =E9*G9 -> 53040
B10: WOVEN FABRIC | C10: c/#204 BEIGE | D10: COTTON 72%、POLYURETHANE28% | E10: 50 | F10: M. | G10: 1040 | H10: =E10*G10 -> 52000 | I10: NO.22068766 | J10: 11/7着
B11: 綾織 ツイル 後染め | D11: WIDTH:140CM (186ｇ/㎡ )
B12: 短繊維、プリント加工なし
A14: 3-4 | D14: STYLE: cc25ss-25, | N14: 2
B15: BL1300 | C15: C/#BK | D15: KNIT FABRIC | E15: 36.5 | F15: M. | G15: 1480 | H15: =E15*G15 -> 54020
B16: KNIT FABRIC | C16: c/#1 | D16: COTTON100% | E16: 38 | F16: M. | G16: 1480 | H16: =E16*G16 -> 56240 | I16: NO.22068731 | J16: 11/7着
B17: 綿メッシュ 丸編み | D17: WIDTH:85WCM (190ｇ/㎡ )
B18: 短繊維、プリント加工なし
A20: 5-6 | D20: STYLE: cc25ss-26/cc25ss-33 | N20: 2
B21: 81-81051 | C21: C/#4 BROWN | D21: WOVEN FABRIC | E21: 22 | F21: M. | G21: 1090 | H21: =E21*G21 -> 23980
B22: WOVEN FABRIC | C22: c/#BK | D22: POLYESTER100% | E22: 10 | F22: M. | G22: 1090 | H22: =E22*G22 -> 10900 | I22: NO.22068730 | J22: 11/7着
B23: 朱子織 サテン 後染め | D23: WIDTH:138CM (128ｇ/㎡ )
B24: 長繊維、プリント加工なし
A26: 7-8 | D26: STYLE: cc25ss-07 | N26: 2
B27: PIN79 | C27: C/#99 BLACK | D27: KNIT FABRIC | E27: 10 | F27: M. | G27: 1310 | H27: =E27*G27 -> 13100
B28: KNIT FABRIC | C28: c/#93 GRAY | D28: POLYESTER100% | E28: 9 | F28: M. | G28: 1310 | H28: =E28*G28 -> 11790 | I28: NO.22068761 | J28: 11/7着
B29: スムース 後染め | D29: WIDTH:140CM (108ｇ/㎡ )
B30: 長繊維、プリント加工なし
A32: 9 | D32: STYLE: 25S-PT03 | N32: 1
B33: BALLOON COTTON 5 | C33: c/#1 WHITE | D33: COTTON YARM | E33: 1 | F33: KG. | G33: 4500 | H33: =E33*G33 -> 4500
D34: COTTON 50% ACRYLIC 50% | I34: NO.22069147 | J34: 11/19着
B36: men's shirt SAMPLE CLOTHES | D36: 25S-SH01 sample | E36: 1 | F36: PCS. | G36: 5000 | H36: =E36*G36 -> 5000
B37: men's wool pants SAMPLE CLOTHES | D37: 25S-PT01 sample | E37: 1 | F37: PCS. | G37: 5000 | H37: =E37*G37 -> 5000
B39: WOVEN NAME | D39: PRESTIGE name | E39: 400 | F39: PCS. | G39: 10 | H39: =E39*G39 -> 4000
A41: 10 | D41: STYLE: 25S-PT03 | N41: 1
B42: lace motif sample | D42: 25S-PT03 sample | E42: 2 | F42: PCS. | G42: 5000 | H42: =E42*G42 -> 10000 | I42: NO.22069257 | J42: 11/21着
A45: 11-14 | D45: STYLE: cc25ss-04/cc25ss-05/cc25ss-06/cc25ss-07 | N45: 4
B46: KKF 2742 | C46: C/#11 WHITE | D46: KNIT FABRIC | E46: 50.5 | F46: M. | G46: 1010 | H46: =E46*G46 -> 51005
B47: KNIT FABRIC | C47: C/#46 GRAY | D47: POLYESTER100% | E47: 55 | F47: M. | G47: 1010 | H47: =E47*G47 -> 55550 | I47: 佐川561400824972 | J47: 11/22着
B48: クサリ 後染め | C48: C/#20 BLACK | D48: WIDTH:140CM (160ｇ/㎡ ) | E48: 51 | F48: M. | G48: 1010 | H48: =E48*G48 -> 51510 | I48: 佐川561400824961
B49: 長繊維、プリント加工なし | I49: 第一貨物60950825154
A51: 15 | D51: STYLE: cc25ss-44 | I51: 佐川457813907246 | N51: 1
B52: used synthetic leather jacket | C52: C/#MIX | E52: 13 | F52: PCS. | G52: 5000 | H52: =E52*G52 -> 65000
B53: 合皮 | J53: 11/22着
...

Sheet NARITA (2)
A2: - ATTACHED SHEET -
A4: C/NO. | B4: ART NO. | C4: COLOR | D4: DESCRIPTION OF GOODS | E4: Q'TY | F4: U/PRICE | H4: AMOUNT | I4: 佐川伝票・明細 | J4: 搬入日 | K4: 伝票NO | L4: 搬入内容 | M4: 数量 | N4: 箱数
B6: (H.S. CODE) | D6: ='[4]NARITA '!D6 -> FABRIC & PARTS FOR WEAR & SAMPLE CLOTHES | G6: ='[5]shipper master'!C48 -> F.O.B. TOKYO IN YEN
D7: MADE IN JAPAN
A9: 16-19 | D9: 25S-JK01(24SY-19) | I9: 入庫NO.22068948 | M9: 4
B10: 2002S | D10: POLYESTER LINING POLYESTER100%
D11: #63-23m #BK-23m | E11: 46 | F11: M. | G11: 410 | H11: =E11*G11 -> 18860
B12: 1000 | D12: COTTON 100% PIECE-DYED SLEEK
D13: #128-5m #1-2-5m | E13: 10 | F13: M. | G13: 550 | H13: =E13*G13 -> 5500
B14: KBC9024 | D14: BUCKLE 材質：真鍮
C15: PN | D15: 50MM | E15: 22 | G15: 335 | H15: =E15*G15 -> 7370
C16: PN | D16: 25MM | E16: 44 | F16: PCS. | G16: 165 | H16: =E16*G16 -> 7260
B17: 300 | C17: SPF | D17: EYELET 材質：真鍮 | E17: 250 | F17: SET. | G17: 11 | H17: =E17*G17 -> 2750
D18: PLASTIC BUTTONS
B19: COROZO300 | C19: 405 | D19: 20MM-55 15MM-66 | E19: 121 | F19: PCS. | G19: 16 | H19: =E19*G19 -> 1936
C20: NERO | D20: 20MM-55 15MM-66 | E20: 121 | F20: PCS. | G20: 16 | H20: =E20*G20 -> 1936
B21: OP53 | D21: 11.5MM #40-55 #09-55 | E21: 110 | F21: PCS. | G21: 7 | H21: =E21*G21 -> 770
B22: 5TBH | C22: P-SSL | D22: HOOK 材質：真鍮 | E22: 22 | F22: SET. | G22: 110 | H22: =E22*G22 -> 2420
D24: 25S-PT01/PT02
B25: 500 | D25: COTTON 100% PIECE-DYED SLEEK
D26: #10-68M #24-68M | E26: 136 | F26: M. | G26: 390 | H26: =E26*G26 -> 53040
B27: 3MA C DA | D27: METAL ZIPPER
D28: 13CM #133-88 #580-88 | E28: 176 | F28: PCS. | G28: 80 | H28: =E28*G28 -> 14080
B29: UNCORN775 | D29: PLASTIC BUTTONS
D30: 15MM #42-89 #09-89 | E30: 178 | F30: PCS. | G30: 22 | H30: =E30*G30 -> 3916
B31: B204 | C31: W | D31: ELASTIC WAIST 30MM | E31: 180 | F31: M. | G31: 80 | H31: =E31*G31 -> 14400
B32: PL-S17 | D32: SNAP BUTTONS
D33: #1937-200 #2034-200 | E33: 400 | F33: SET. | G33: 10 | H33: =E33*G33 -> 4000
B34: SIC133 | D34: POLYESTER TAPE 20MM POLYESTER100%
D35: #48-30M #BK-30M | E35: 60 | F35: M. | G35: 110 | H35: =E35*G35 -> 6600
B36: M50 | D36: POLYESTER CORD POLYESTER100%
D37: #76NT-400M #47NT-400M | E37: 800 | F37: M. | G37: 35 | H37: =E37*G37 -> 28000
B38: STAR600 | D38: COTTON TAPE 6MM COTTON100%
D39: #687-800M #BK-800M | E39: 1600 | F39: M. | G39: 30 | H39: =E39*G39 -> 48000
B40: 131-505 | C40: 001 | D40: POLYESTER TAPE 4mm POLYESTER100% | E40: 90 | F40: M. | G40: 25 | H40: =E40*G40 -> 2250
A43: 20 | D43: cc25ss-45 | I43: 入庫NO.22069179 | M43: 1
B44: 2002S | C44: 157 | D44: POLYESTER LINING POLYESTER100% | E44: 17 | F44: M. | G44: 410 | H44: =E44*G44 -> 6970
B46: SB12 | C46: 84NT/BK | D46: THREAD | E46: 3 | F46: SET. | G46: 1800 | H46: =E46*G46 -> 5400
B47: CM5 | C47: 09 | D47: BUTTONS 11.5M,M | E47: 157 | F47: PCS. | G47: 8 | H47: =E47*G47 -> 1256
D49: cc25ss-60
...

Sheet サンプル製品カタログ
D1: ITEM
B2: NAME | C2: color | E2: lady's or men's | F2: WOVEN or KNIT | G2: picture | H2: Composition | I2: packingNo.
B3: men's shirt SAMPLE CLOTHES | C3: C/#YELLOW | D3: men's shirt SAMPLE CLOTHES | E3: men's | F3: WOVEN FABRIC | H3: COTTON100% | I3: 9
B4: men's wool pants SAMPLE CLOTHES | C4: C/#BLACK | D4: men's wool pants SAMPLE CLOTHES | E4: men's | F4: WOVEN FABRIC | H4: FRONT WOOL100% | I4: 9
B5: lace motif sample | C5: C/#WHITE | D5: lace motif sample | E5: men's | F5: KNIT FABRIC | H5: COTTON100% | I5: 10
B6: lace motif sample | C6: C/#WHITE | D6: lace motif sample | E6: men's | F6: KNIT FABRIC | H6: COTTON100% | I6: 10

Sheet LABEL
A2: LABEL SHEET -
A4: C/NO. | B4: ART NO. | C4: DESCRIPTION OF GOODS | D4: 原産国
A5: 1-2 | C5: STYLE: 25S-JK01(24SY-19)
B6: 012S0008298 | C6: WOVEN FABRIC | D6: MADE IN JAPAN
B7: WOVEN FABRIC | C7: COTTON 72%、POLYURETHANE28% | D7: SHUNYA CO., LTD.
B8: 綾織 ツイル 後染め | C8: WIDTH:140CM (186ｇ/㎡ )
B9: 短繊維、プリント加工なし
A11: C/NO. | B11: ART NO. | C11: DESCRIPTION OF GOODS | D11: 原産国
A12: 3-4 | C12: STYLE: cc25ss-25,
B13: BL1300 | C13: KNIT FABRIC | D13: MADE IN JAPAN
B14: KNIT FABRIC | C14: COTTON100% | D14: SHUNYA CO., LTD.
B15: 綿メッシュ 丸編み | C15: WIDTH:85WCM (190ｇ/㎡ )
B16: 短繊維、プリント加工なし
A18: C/NO. | B18: ART NO. | C18: DESCRIPTION OF GOODS | D18: 原産国
A19: 5-6 | C19: STYLE: cc25ss-26/cc25ss-33
B20: 81-81051 | C20: WOVEN FABRIC | D20: MADE IN JAPAN
B21: WOVEN FABRIC | C21: POLYESTER100% | D21: SHUNYA CO., LTD.
B22: 朱子織 サテン 後染め | C22: WIDTH:138CM (128ｇ/㎡ )
B23: 長繊維、プリント加工なし
A25: C/NO. | B25: ART NO. | C25: DESCRIPTION OF GOODS | D25: 原産国
A26: 7-8 | C26: STYLE: cc25ss-07
B27: PIN79 | C27: KNIT FABRIC | D27: MADE IN JAPAN
B28: KNIT FABRIC | C28: POLYESTER100% | D28: SHUNYA CO., LTD.
B29: スムース 後染め | C29: WIDTH:140CM (108ｇ/㎡ )
B30: 長繊維、プリント加工なし
A32: C/NO. | B32: ART NO. | C32: DESCRIPTION OF GOODS | D32: 原産国
A33: 9 | C33: STYLE: 25S-PT03
B34: BALLOON COTTON 5 | C34: COTTON YARM
C35: COTTON 50% ACRYLIC 50%
B37: men's shirt SAMPLE CLOTHES | C37: 25S-SH01 sample | D37: MADE IN JAPAN
B38: men's wool pants SAMPLE CLOTHES | C38: 25S-PT01 sample | D38: SHUNYA CO., LTD.
B40: WOVEN NAME | C40: PRESTIGE name
A42: C/NO. | B42: ART NO. | C42: DESCRIPTION OF GOODS | D42: 原産国
A43: 10 | C43: STYLE: 25S-PT03
B44: lace motif sample | C44: 25S-PT03 sample | D44: MADE IN JAPAN
D45: SHUNYA CO., LTD.
A47: C/NO. | B47: ART NO. | C47: DESCRIPTION OF GOODS | D47: 原産国
A48: 11-14 | C48: STYLE: cc25ss-04/cc25ss-05/cc25ss-06/cc25ss-07
B49: KKF 2742 | C49: KNIT FABRIC | D49: MADE IN JAPAN
B50: KNIT FABRIC | C50: POLYESTER100% | D50: SHUNYA CO., LTD.
...
