Workbook
Name pricetable: #REF!
Name pricetable: #REF!
Name pricetable: #REF!
Name pricetable: #REF!
Name pricetable: #REF!

Sheet shipper master
A1: 1 | B1: S/CODE | C1: SHIPPER NAME
A2: =A1+1 -> 2 | B2: SHIPPER | C2: SHUNYA CO., LTD.
A3: =A2+1 -> 3 | B3: SHIPPER ADDRESS 1 | C3: KENSHIN BLDG., 1F, 1-22-10 DOUGENZAKA,
A4: =A3+1 -> 4 | B4: SHIPPER ADDRESS 2 | C4: SHIBUYA-KU 150-0043
A5: =A4+1 -> 5 | B5: SHIPPER ADDRESS 3 | C5: TEL : +81(0)3-5459-1177
A6: =A5+1 -> 6 | B6: TEL
A7: =A6+1 -> 7 | B7: FAX
A8: =A7+1 -> 8 | B8: ATTN OR VAT NO.
A9: =A8+1 -> 9 | B9: BUYER | C9: VIVAN GARMENTS VIET NAM COMPANY LIMITED
A10: =A9+1 -> 10 | B10: BUYER ADDRESS1 | C10: D17 Street , Sai Gon South Residential Area
A11: =A10+1 -> 11 | B11: BUYER ADDRESS2 | C11: Hamlet 3 , Long Hau Commune , Can Giuoc District,
A12: =A11+1 -> 12 | B12: BUYER ADDRESS3 | C12: Long An Province , VietNam
A13: =A12+1 -> 13 | B13: TEL/FAX | C13: TEL : ( 084 ) 097 22 00 798 ATTN : MR. TUAN
A14: =A13+1 -> 14 | B14: ATTN
A15: =A14+1 -> 15 | B15: CONSIGNEE : | C15: - SAME AS BUYER -
A16: =A15+1 -> 16 | B16: CONSIGNEE ADDRESS1
A17: =A16+1 -> 17 | B17: CONSIGNEE ADDRESS2
A18: =A17+1 -> 18 | B18: CONSIGNEE ADDRESS3
A19: =A18+1 -> 19 | B19: TEL
A20: =A19+1 -> 20 | B20: FAX
A21: =A20+1 -> 21 | B21: ATTN | C21: NO COMMERCIAL
A22: =A21+1 -> 22 | B22: PAYMENT 1
A23: =A22+1 -> 23 | B23: PAYMENT 2
A24: =A23+1 -> 24 | B24: SHIPPER PER | C24: AIRCRAFT
A25: =A24+1 -> 25 | B25: INVOICE DATE | C25: Apr, 09 2025
A26: =A25+1 -> 26 | B26: INVOICE NO. | C26: SY-6400409-VT-DD-01
A27: =A26+1 -> 27 | B27: CONTRACT NO. | C27: =C26 -> SY-6400409-VT-DD-01
A28: =A27+1 -> 28 | B28: CONTRACT DATE
A29: =A28+1 -> 29 | B29: ORDER DATE
A30: =A29+1 -> 30 | B30: ORDER NO.
A31: =A30+1 -> 31 | B31: L/C DATE
A32: =A31+1 -> 32 | B32: FROM | C32: TOKYO, JAPAN
A33: =A32+1 -> 33 | B33: TO | C33: HOCHIMINH-CITY, VIETNAM
A34: =A33+1 -> 34 | B34: VIA
A35: =A34+1 -> 35 | B35: SHIPPING TERMS | C35: F.O.B. TOKYO IN YEN
A36: =A35+1 -> 36 | B36: TITTLE 1 | C36: FABRIC & PARTS FOR WEAR & SAMPLE CLOTHES
A37: =A36+1 -> 37 | B37: TITTLE 2
A38: =A37+1 -> 38 | B38: ATTACHE | C38: - DETAILS AS PER ATTACHED SHEET -
A39: =A38+1 -> 39 | B39: C/NO.
A40: =A39+1 -> 40 | B40: STYLE NO.
...

Sheet case mark 
A2: ='shipper master'!C26 -> SY-6400409-VT-DD-01 | I2: ='shipper master'!C26 -> SY-6400409-VT-DD-01
A3: ='[1]shipper master'!C50 -> VIVAN GARMENTS VIET NAM | I3: ='[1]shipper master'!C50 -> VIVAN GARMENTS VIET NAM
A4: ='[1]shipper master'!C51 -> COMPANY LIMITED | I4: ='[1]shipper master'!C51 -> COMPANY LIMITED
A5: ='[1]shipper master'!C52 -> HOCHIMINH-CITY, VIETNAM | I5: ='[1]shipper master'!C52 -> HOCHIMINH-CITY, VIETNAM
A6: C/NO. | C6: 1 | I6: C/NO. | K6: 2
A7: ='[1]shipper master'!C54 -> MADE IN JAPAN | I7: ='[1]shipper master'!C54 -> MADE IN JAPAN
A13: ='shipper master'!C26 -> SY-6400409-VT-DD-01 | I13: ='shipper master'!C26 -> SY-6400409-VT-DD-01
A14: ='[1]shipper master'!C50 -> VIVAN GARMENTS VIET NAM | I14: ='[1]shipper master'!C50 -> VIVAN GARMENTS VIET NAM
A15: ='[1]shipper master'!C51 -> COMPANY LIMITED | I15: ='[1]shipper master'!C51 -> COMPANY LIMITED
A16: ='[1]shipper master'!C52 -> HOCHIMINH-CITY, VIETNAM | I16: ='[1]shipper master'!C52 -> HOCHIMINH-CITY, VIETNAM
A17: C/NO. | C17: 3 | I17: C/NO. | K17: 4
A18: ='[1]shipper master'!C54 -> MADE IN JAPAN | I18: ='[1]shipper master'!C54 -> MADE IN JAPAN

Sheet invoice
A1: INVOICE
A2: ='[2]shipper master'!C2 -> SHUNYA CO., LTD.
A3: ='[2]shipper master'!C3 -> KENSHIN BLDG., 1F, 1-22-10 DOUGENZAKA,
A4: ='[2]shipper master'!C4 -> SHIBUYA-KU 150-0043 | L4: ='[2]shipper master'!C6 -> 0
A5: ='[2]shipper master'!C5 -> TEL : +81(0)3-5459-1177 | L5: ='[2]shipper master'!C7 -> 0
A6: IMPORTER | F6: INVOICE NO. | L6: CASE MARK
A7: ='[2]shipper master'!C9 -> VIVAN GARMENTS VIET NAM COMPANY LIMITED | F7: ='shipper master'!C26 -> SY-6400409-VT-DD-01
A8: ='[2]shipper master'!C10 -> D17 Street , Sai Gon South Residential Area | F8: INVOICE DATE | L8: ='shipper master'!C26 -> SY-6400409-VT-DD-01
A9: ='[2]shipper master'!C11 -> Hamlet 3 , Long Hau Commune , Can Giuoc District, | F9: ='shipper master'!C25 -> Apr, 09 2025 | L9: ='[1]shipper master'!C50 -> VIVAN GARMENTS VIET NAM
A10: ='[2]shipper master'!C12 -> Long An Province , VietNam | F10: CONTRACT NO. | L10: ='[1]shipper master'!C51 -> COMPANY LIMITED
A11: ='[2]shipper master'!C13 -> TEL : ( 084 ) 097 22 00 798 ATTN : MR. TUAN | F11: ='shipper master'!C26 -> SY-6400409-VT-DD-01 | L11: ='[1]shipper master'!C52 -> HOCHIMINH-CITY, VIETNAM
A12: CONSIGNEE | F12: ORDER NO. | L12: C/NO. 1-21
A13: ='[2]shipper master'!C15 -> - SAME AS BUYER - | F13: ='[2]shipper master'!C30 -> 0 | L13: MADE IN JAPAN
A14: ='[2]shipper master'!C16 -> 0 | F14: ORDER DATE
A15: ='[2]shipper master'!C17 -> 0 | F15: ='[2]shipper master'!C29 -> 0
A16: ='[2]shipper master'!C18 -> 0 | F16: L/C NO.
A17: ='[2]shipper master'!C19 -> 0
A18: PAYMENT METHOD
A19: ='[2]shipper master'!C21 -> NO COMMERCIAL
A20: SHIPPED PER | D20: FROM | F20: TO | L20: VIA
A21: ='[2]shipper master'!C24 -> AIRCRAFT | D21: ='[2]shipper master'!C32 -> TOKYO, JAPAN | G21: ='[2]shipper master'!C33 -> HOCHIMINH-CITY, VIETNAM
A22: C/NO. | B22: ART NO. | D22: DESCRIPTION OF GOODS | E22: COLOR | H22: SIZE | K22: Q'TY | L22: U/PRICE | M22: AMOUNT
B24: ='[2]shipper master'!C36 -> FABRIC & PARTS FOR WEAR & SAMPLE CLOTHES | L24: ='[2]shipper master'!C48 -> F.O.B. TOKYO IN YEN
B26: ='[2]shipper master'!C37 -> 0 | K26: ='NARITA '!E65 -> 638.8 | L26: M. | M26: ='NARITA '!H65 -> 969723
K27: ='NARITA '!E66 -> 486 | L27: PCS. | M27: ='NARITA '!H66 -> 19400
B28: ='[2]shipper master'!C38 -> - DETAILS AS PER ATTACHED SHEET - | K28: ='NARITA '!E67 -> 16 | L28: SET. | M28: ='NARITA '!H67 -> 1600
B30: TOTAL : | D30: =K26 -> 638.8 | E30: M. | F30: =K27 -> 486 | I30: PCS. | J30: PCS. | K30: =K28 -> 16 | L30: SET. | M30: =SUM(M26:M29) -> 990723
A33: ='[2]shipper master'!C63 -> " THESE GOODS WILL BE RETURN TO JAPAN | I33: " NO COMMER VALUE | K33: " NO COMMERCIAL VALUE
A34: ='[2]shipper master'!C64 -> AFTER MANUFACTURED AT VIET NAM " | I34: VALUE FOR CUSTOMS PURPOSE ONLY " | K34: VALUE FOR CUSTOMS PURPOSE ONLY "
D35: ='[2]shipper master'!C58 -> 0
A36: ='[2]shipper master'!C60 -> COUNTRY OF ORIGIN : JAPAN
A38: TOTAL CARTONS : | D38: 21CARTONS
A39: TOTAL GROSS WEIGHT : | D39: KGS

Sheet NARITA 
A2: - ATTACHED SHEET -
A4: C/NO. | B4: ART NO. | C4: COLOR | D4: DESCRIPTION OF GOODS | E4: Q'TY | F4: U/PRICE | H4: AMOUNT | I4: 佐川伝票・明細 | J4: 搬入日 | K4: 伝票NO | L4: 搬入内容 | M4: 数量 | N4: 箱数
B6: (H.S. CODE) | D6: =[3]invoice!B24 -> FABRIC & PARTS FOR WEAR & SAMPLE CLOTHES | G6: ='[1]shipper master'!C48 -> F.O.B. TOKYO IN YEN
D7: MADE IN JAPAN
A8: 1 | D8: STYLE:25A-SH01(24SY-55) | N8: 1
B9: 3041 | C9: c/#01 WHITE | D9: WOVEN FABRIC | E9: 59.5 | F9: M. | G9: 770 | H9: =E9*G9 -> 45815
B10: WOVEN FABRIC | C10: c/#05 STRIPE | D10: COTTON100% | E10: 128 | F10: M. | G10: 770 | H10: =E10*G10 -> 98560 | I10: 入庫NO.22072383 | J10: 3/28
B11: 平織 オックス 先染め | D11: WIDTH:112CM (218ｇ/㎡ )
B12: 短繊維、プリント加工なし
A14: 2-3 | D14: STYLE:25A-PT03(24SY-52),25A-SK01(24SY-61) | N14: 2
B15: 7070 | C15: c/#213 BLUE | D15: WOVEN FABRIC | E15: 57 | F15: M. | G15: 1570 | H15: =E15*G15 -> 89490
B16: WOVEN FABRIC | D16: COTTON100% | I16: 入庫NO.22072380 | J16: 3/28
B17: 綾織 デニム 先染め | D17: WIDTH:150CM (440ｇ/㎡ ) | I17: 入庫NO.22072381
B18: 短繊維、プリント加工なし
A20: 4-5 | D20: STYLE:25A-CO01(24SY-59) | N20: 2
B21: 32-30628 | C21: c/#21 BROWN | D21: WOVEN FABRIC | E21: 52.1 | F21: M. | G21: 3260 | H21: =E21*G21 -> 169846 | I21: 入庫NO.22072382 | J21: 3/28
B22: WOVEN FABRIC | C22: c/#11 BLACK | D22: WOOL65%、POLYESTER35% | E22: 52.2 | F22: M. | G22: 3260 | H22: =E22*G22 -> 170172 | I22: 入庫NO.22072684 | J22: 4/9
B23: 綾織 ツイル 先染め | D23: WIDTH:151CM (480ｇ/㎡ )
B24: 短繊維、プリント加工なし
A26: 6-17 | D26: STYLE:21SY-60 | I26: 入庫NO.22072481 | J26: 4/4 | N26: 12
B27: 007S0052010 | C27: c/#010 BLACK | D27: KNIT FABRIC | E27: 130 | F27: M. | G27: 1400 | H27: =E27*G27 -> 182000
B28: KNIT FABRIC | D28: COTTON100%
B29: 裏毛パイル編 丸編み | D29: WIDTH:165CM (450g/㎡ )
B30: 短繊維、プリント加工なし
D32: STYLE:21SY-60
B33: 007S0052015 | C33: c/#00G TOPGRAY | D33: KNIT FABRIC | E33: 120 | F33: M. | G33: 1400 | H33: =E33*G33 -> 168000
B34: KNIT FABRIC | D34: COTTON100%
B35: 裏毛パイル編 丸編み | D35: WIDTH:165CM (450g/㎡ )
B36: 短繊維、プリント加工なし
A38: 18-19 | D38: STYLE: 21SY-60 | N38: 2
B39: 007S0052070 | C39: c/#010 BLACK | D39: KNIT FABRIC | E39: 14 | F39: M. | G39: 1140 | H39: =E39*G39 -> 15960
B40: KNIT FABRIC | C40: c/#00G TOPGRAY | D40: COTTON96% POLYURETHANE4% | E40: 14 | F40: M. | G40: 1140 | H40: =E40*G40 -> 15960 | I40: 入庫NO.22072516 | J40: 4/4
B41: リブ編み 丸編み テレコ | D41: WIDTH:120CM (400ｇ/㎡ )
B42: 短繊維、プリント加工なし
A44: 20 | D44: STYLE: 25A-SK01(24SY-61) | N44: 1
B45: 016S0040116 | C45: c/#600 BROWN | D45: WOVEN FABRIC | E45: 6 | F45: M. | G45: 1160 | H45: =E45*G45 -> 6960
B46: WOVEN FABRIC | C46: c/#750 BLACK | D46: POLYESTER100% | E46: 6 | F46: M. | G46: 1160 | H46: =E46*G46 -> 6960 | I46: 佐川450005309180 | J46: 4/9
B47: 綾織 ツイル 後染め | D47: WIDTH:140CM (210ｇ/㎡ )
B48: 短繊維、プリント加工なし
B50: PRESTIGE WOVEN quality tag | D50: PRESTIGE WOVEN quality tag | E50: 480 | F50: PCS. | G50: 5 | H50: =E50*G50 -> 2400
...

Sheet サンプル製品カタログ
D1: ITEM
B2: NAME | C2: color | E2: lady's or men's | F2: WOVEN or KNIT | G2: picture | H2: Composition | I2: packingNo.
B3: men'coat SAMPLE CLOTHES | C3: C/#BROWN | D3: 25A-CO01 SAMPLE | E3: men's | F3: WOVEN FABRIC | H3: WOOL65%、POLYESTER35% | I3: 21
B4: men's pants SAMPLE CLOTHES | C4: C/#BROWN | D4: 25A-PT01 SAMPLE | E4: men's | F4: WOVEN FABRIC | H4: WOOL100% | I4: 21
B5: men's pants SAMPLE CLOTHES | C5: C/#BLACK | D5: 25A-PT02 SAMPLE | E5: men's | F5: WOVEN FABRIC | H5: WOOL100% | I5: 21
B6: men's pants SAMPLE CLOTHES | C6: C/#BLACK | D6: 25A-PT04 SAMPLE | E6: men's | F6: WOVEN FABRIC | H6: POLYESTER100% | I6: 21
B7: men's shirt SAMPLE CLOTHES | C7: C/#STRIPE | D7: 25A-SH01 SAMPLE | E7: men's | F7: WOVEN FABRIC | H7: COTTON100% | I7: 21
B8: lady's skirt SAMPLE CLOTHES | C8: c/#BLUE | D8: 25A-SK01 SAMPLE | E8: lady's | F8: WOVEN FABRIC | H8: COTTON100% 別布：POLYESTER100％ | I8: 21

Sheet LABEL
A2: LABEL SHEET -
A4: C/NO. | B4: ART NO. | C4: DESCRIPTION OF GOODS | D4: 原産国
A5: 1 | C5: STYLE:25A-SH01(24SY-55)
B6: 3041 | C6: WOVEN FABRIC
B7: WOVEN FABRIC | C7: COTTON100% | D7: MADE IN JAPAN
B8: 平織 オックス 先染め | C8: WIDTH:112CM (218ｇ/㎡ ) | D8: SHUNYA CO., LTD.
B9: 短繊維、プリント加工なし
A11: C/NO. | B11: ART NO. | C11: DESCRIPTION OF GOODS | D11: 原産国
A12: 2-3 | C12: STYLE:25A-PT03(24SY-52),25A-SK01(24SY-61)
B13: 7070 | C13: WOVEN FABRIC
B14: WOVEN FABRIC | C14: COTTON100%
B15: 綾織 デニム 先染め | C15: WIDTH:150CM (440ｇ/㎡ ) | D15: MADE IN JAPAN
B16: 短繊維、プリント加工なし | D16: SHUNYA CO., LTD.
A18: C/NO. | B18: ART NO. | C18: DESCRIPTION OF GOODS | D18: 原産国
A19: 4-5 | C19: STYLE:25A-CO01(24SY-59)
B20: 32-30628 | C20: WOVEN FABRIC
B21: WOVEN FABRIC | C21: WOOL65%、POLYESTER35% | D21: MADE IN JAPAN
B22: 綾織 ツイル 先染め | C22: WIDTH:151CM (480ｇ/㎡ ) | D22: SHUNYA CO., LTD.
B23: 短繊維、プリント加工なし
A25: C/NO. | B25: ART NO. | C25: DESCRIPTION OF GOODS | D25: 原産国
A26: 6-17 | C26: STYLE:21SY-60
B27: 007S0052010 | C27: KNIT FABRIC
B28: KNIT FABRIC | C28: COTTON100% | D28: MADE IN JAPAN
B29: 裏毛パイル編 丸編み | C29: WIDTH:165CM (450g/㎡ ) | D29: SHUNYA CO., LTD.
B30: 短繊維、プリント加工なし
A32: C/NO. | B32: ART NO. | C32: DESCRIPTION OF GOODS | D32: 原産国
A33: 18-19 | C33: STYLE: 21SY-60
B34: 007S0052070 | C34: KNIT FABRIC
B35: KNIT FABRIC | C35: COTTON96% POLYURETHANE4% | D35: MADE IN JAPAN
B36: リブ編み 丸編み テレコ | C36: WIDTH:120CM (400ｇ/㎡ ) | D36: SHUNYA CO., LTD.
B37: 短繊維、プリント加工なし
A39: C/NO. | B39: ART NO. | C39: DESCRIPTION OF GOODS | D39: 原産国
A40: 20 | C40: STYLE: 25A-SK01(24SY-61)
B41: 016S0040116 | C41: WOVEN FABRIC
B42: WOVEN FABRIC | C42: POLYESTER100% | D42: MADE IN JAPAN
B43: 綾織 ツイル 後染め | C43: WIDTH:140CM (210ｇ/㎡ ) | D43: SHUNYA CO., LTD.
B44: 短繊維、プリント加工なし
B46: PRESTIGE WOVEN quality tag | C46: PRESTIGE WOVEN quality tag
A48: C/NO. | B48: ART NO. | C48: DESCRIPTION OF GOODS | D48: 原産国
A49: 21 | B49: pattern paper | C49: 21SY-60 pattern paper
...
