Workbook
Name pricetable: #REF!
Name pricetable: #REF!
Name pricetable: #REF!
Name pricetable: #REF!
Name pricetable: #REF!
Name pricetable: #REF!

Sheet shipper master
A1: 1 | B1: S/CODE | C1: SHIPPER NAME
A2: =A1+1 -> 2 | B2: SHIPPER | C2: SHUNYA CO., LTD.
A3: =A2+1 -> 3 | B3: SHIPPER ADDRESS 1 | C3: KENSHIN BLDG., 1F, 1-22-10 DOUGENZAKA,
A4: =A3+1 -> 4 | B4: SHIPPER ADDRESS 2 | C4: SHIBUYA-KU 150-0043
A5: =A4+1 -> 5 | B5: SHIPPER ADDRESS 3 | C5: TEL : +81(0)3-5459-1177
A6: =A5+1 -> 6 | B6: TEL
A7: =A6+1 -> 7 | B7: FAX
A8: =A7+1 -> 8 | B8: ATTN OR VAT NO.
A9: =A8+1 -> 9 | B9: BUYER | C9: VIVAN GARMENTS VIET NAM COMPANY LIMITED
A10: =A9+1 -> 10 | B10: BUYER ADDRESS1 | C10: D17 Street , Sai Gon South Residential Area
A11: =A10+1 -> 11 | B11: BUYER ADDRESS2 | C11: Hamlet 3 , Long Hau Commune , Can Giuoc District,
A12: =A11+1 -> 12 | B12: BUYER ADDRESS3 | C12: Long An Province , VietNam
A13: =A12+1 -> 13 | B13: TEL/FAX | C13: TEL : ( 084 ) 097 22 00 798 ATTN : MR. TUAN
A14: =A13+1 -> 14 | B14: ATTN
A15: =A14+1 -> 15 | B15: CONSIGNEE : | C15: - SAME AS BUYER -
A16: =A15+1 -> 16 | B16: CONSIGNEE ADDRESS1
A17: =A16+1 -> 17 | B17: CONSIGNEE ADDRESS2
A18: =A17+1 -> 18 | B18: CONSIGNEE ADDRESS3
A19: =A18+1 -> 19 | B19: TEL
A20: =A19+1 -> 20 | B20: FAX
A21: =A20+1 -> 21 | B21: ATTN | C21: NO COMMERCIAL
A22: =A21+1 -> 22 | B22: PAYMENT 1
A23: =A22+1 -> 23 | B23: PAYMENT 2
A24: =A23+1 -> 24 | B24: SHIPPER PER | C24: AIRCRAFT
A25: =A24+1 -> 25 | B25: INVOICE DATE | C25: Feb, 09 2025
A26: =A25+1 -> 26 | B26: INVOICE NO. | C26: SY-6300208-VT-DD-01
A27: =A26+1 -> 27 | B27: CONTRACT NO. | C27: =C26 -> SY-6300208-VT-DD-01
A28: =A27+1 -> 28 | B28: CONTRACT DATE
A29: =A28+1 -> 29 | B29: ORDER DATE
A30: =A29+1 -> 30 | B30: ORDER NO.
A31: =A30+1 -> 31 | B31: L/C DATE
A32: =A31+1 -> 32 | B32: FROM | C32: TOKYO, JAPAN
A33: =A32+1 -> 33 | B33: TO | C33: HOCHIMINH-CITY, VIETNAM
A34: =A33+1 -> 34 | B34: VIA
A35: =A34+1 -> 35 | B35: SHIPPING TERMS | C35: F.O.B. TOKYO IN YEN
A36: =A35+1 -> 36 | B36: TITTLE 1 | C36: FABRIC & PARTS FOR WEAR & SAMPLE CLOTHES
A37: =A36+1 -> 37 | B37: TITTLE 2
A38: =A37+1 -> 38 | B38: ATTACHE | C38: - DETAILS AS PER ATTACHED SHEET -
A39: =A38+1 -> 39 | B39: C/NO.
A40: =A39+1 -> 40 | B40: STYLE NO.
...

Sheet case mark 
A2: ='shipper master'!C26 -> SY-6300208-VT-DD-01 | I2: ='shipper master'!C26 -> SY-6300208-VT-DD-01
A3: ='[1]shipper master'!C50 -> VIVAN GARMENTS VIET NAM | I3: ='[1]shipper master'!C50 -> VIVAN GARMENTS VIET NAM
A4: ='[1]shipper master'!C51 -> COMPANY LIMITED | I4: ='[1]shipper master'!C51 -> COMPANY LIMITED
A5: ='[1]shipper master'!C52 -> HOCHIMINH-CITY, VIETNAM | I5: ='[1]shipper master'!C52 -> HOCHIMINH-CITY, VIETNAM
A6: C/NO. | C6: 1 | I6: C/NO. | K6: 2
A7: ='[1]shipper master'!C54 -> MADE IN JAPAN | I7: ='[1]shipper master'!C54 -> MADE IN JAPAN
A13: ='shipper master'!C26 -> SY-6300208-VT-DD-01 | I13: ='shipper master'!C26 -> SY-6300208-VT-DD-01
A14: ='[1]shipper master'!C50 -> VIVAN GARMENTS VIET NAM | I14: ='[1]shipper master'!C50 -> VIVAN GARMENTS VIET NAM
A15: ='[1]shipper master'!C51 -> COMPANY LIMITED | I15: ='[1]shipper master'!C51 -> COMPANY LIMITED
A16: ='[1]shipper master'!C52 -> HOCHIMINH-CITY, VIETNAM | I16: ='[1]shipper master'!C52 -> HOCHIMINH-CITY, VIETNAM
A17: C/NO. | C17: 3 | I17: C/NO. | K17: 4
A18: ='[1]shipper master'!C54 -> MADE IN JAPAN | I18: ='[1]shipper master'!C54 -> MADE IN JAPAN

Sheet invoice
A1: INVOICE
A2: ='[2]shipper master'!C2 -> SHUNYA CO., LTD.
A3: ='[2]shipper master'!C3 -> KENSHIN BLDG., 1F, 1-22-10 DOUGENZAKA,
A4: ='[2]shipper master'!C4 -> SHIBUYA-KU 150-0043 | L4: ='[2]shipper master'!C6 -> 0
A5: ='[2]shipper master'!C5 -> TEL : +81(0)3-5459-1177 | L5: ='[2]shipper master'!C7 -> 0
A6: IMPORTER | F6: INVOICE NO. | L6: CASE MARK
A7: ='[2]shipper master'!C9 -> VIVAN GARMENTS VIET NAM COMPANY LIMITED | F7: ='shipper master'!C26 -> SY-6300208-VT-DD-01
A8: ='[2]shipper master'!C10 -> D17 Street , Sai Gon South Residential Area | F8: INVOICE DATE | L8: ='shipper master'!C26 -> SY-6300208-VT-DD-01
A9: ='[2]shipper master'!C11 -> Hamlet 3 , Long Hau Commune , Can Giuoc District, | F9: ='shipper master'!C25 -> Feb, 09 2025 | L9: ='[1]shipper master'!C50 -> VIVAN GARMENTS VIET NAM
A10: ='[2]shipper master'!C12 -> Long An Province , VietNam | F10: CONTRACT NO. | L10: ='[1]shipper master'!C51 -> COMPANY LIMITED
A11: ='[2]shipper master'!C13 -> TEL : ( 084 ) 097 22 00 798 ATTN : MR. TUAN | F11: ='shipper master'!C26 -> SY-6300208-VT-DD-01 | L11: ='[1]shipper master'!C52 -> HOCHIMINH-CITY, VIETNAM
A12: CONSIGNEE | F12: ORDER NO. | L12: C/NO. 1-18
A13: ='[2]shipper master'!C15 -> - SAME AS BUYER - | F13: ='[2]shipper master'!C30 -> 0 | L13: MADE IN JAPAN
A14: ='[2]shipper master'!C16 -> 0 | F14: ORDER DATE
A15: ='[2]shipper master'!C17 -> 0 | F15: ='[2]shipper master'!C29 -> 0
A16: ='[2]shipper master'!C18 -> 0 | F16: L/C NO.
A17: ='[2]shipper master'!C19 -> 0
A18: PAYMENT METHOD
A19: ='[2]shipper master'!C21 -> NO COMMERCIAL
A20: SHIPPED PER | D20: FROM | F20: TO | L20: VIA
A21: ='[2]shipper master'!C24 -> AIRCRAFT | D21: ='[2]shipper master'!C32 -> TOKYO, JAPAN | G21: ='[2]shipper master'!C33 -> HOCHIMINH-CITY, VIETNAM
A22: C/NO. | B22: ART NO. | D22: DESCRIPTION OF GOODS | E22: COLOR | H22: SIZE | K22: Q'TY | L22: U/PRICE | M22: AMOUNT
B24: ='[2]shipper master'!C36 -> FABRIC & PARTS FOR WEAR & SAMPLE CLOTHES | L24: ='[2]shipper master'!C48 -> F.O.B. TOKYO IN YEN
B26: ='[2]shipper master'!C37 -> 0 | K26: ='NARITA '!E51+'NARITA (2)'!E35 -> 438.4 | L26: M. | M26: ='NARITA '!H51+'NARITA (2)'!H35 -> 468459
K27: ='NARITA '!E52+'NARITA (2)'!E36 -> 519 | L27: PCS. | M27: ='NARITA '!H52+'NARITA (2)'!H36 -> 30150
B28: ='[2]shipper master'!C38 -> - DETAILS AS PER ATTACHED SHEET - | K28: ='NARITA '!E53+'NARITA (2)'!E37 -> 218 | L28: SET. | M28: ='NARITA '!H53+'NARITA (2)'!H37 -> 5000
B30: TOTAL : | D30: =K26 -> 438.4 | E30: M. | F30: =K27 -> 519 | I30: PCS. | J30: PCS. | K30: =K28 -> 218 | L30: SET. | M30: =SUM(M26:M29) -> 503609
A33: ='[2]shipper master'!C63 -> " THESE GOODS WILL BE RETURN TO JAPAN | I33: " NO COMMER VALUE | K33: " NO COMMERCIAL VALUE
A34: ='[2]shipper master'!C64 -> AFTER MANUFACTURED AT VIET NAM " | I34: VALUE FOR CUSTOMS PURPOSE ONLY " | K34: VALUE FOR CUSTOMS PURPOSE ONLY "
D35: ='[2]shipper master'!C58 -> 0
A36: ='[2]shipper master'!C60 -> COUNTRY OF ORIGIN : JAPAN
A38: TOTAL CARTONS : | D38: 18CARTONS
A39: TOTAL GROSS WEIGHT : | D39: KGS

Sheet NARITA 
A2: - ATTACHED SHEET -
A4: C/NO. | B4: ART NO. | C4: COLOR | D4: DESCRIPTION OF GOODS | E4: Q'TY | F4: U/PRICE | H4: AMOUNT | I4: 佐川伝票・明細 | J4: 搬入日 | K4: 伝票NO | L4: 搬入内容 | M4: 数量 | N4: 箱数
B6: (H.S. CODE) | D6: =[3]invoice!B24 -> FABRIC & PARTS FOR WEAR & SAMPLE CLOTHES | G6: ='[1]shipper master'!C48 -> F.O.B. TOKYO IN YEN
D7: MADE IN JAPAN
A8: 1-3 | D8: STYLE:s25-so-08 | N8: 3
B9: 08500020052 | C9: c/#099 BLACK | D9: WOVEN FABRIC | E9: 12 | F9: M. | G9: 1460 | H9: =E9*G9 -> 17520
B10: WOVEN FABRIC | C10: c/#760 BLUE | D10: NYLON85%、POLYURETHANE15% | E10: 12 | F10: M. | G10: 1460 | H10: =E10*G10 -> 17520 | I10: 入庫NO.22070913 | J10: 1/22
B11: 綾織 ツイル 後染め | C11: c/#610 GRAY | D11: WIDTH:140CM (156ｇ/㎡ ) | E11: 12 | F11: M. | G11: 1460 | H11: =E11*G11 -> 17520
B12: 短繊維、プリント加工なし
A14: 4-12 | D14: STYLE:s25-so-06,s25-so-07 | I14: 入庫NO.22070928 | N14: 9
B15: 14-9910 | C15: c/#3 PINK | D15: KNIT FABRIC | E15: 11 | F15: M. | G15: 1230 | H15: =E15*G15 -> 13530
B16: KNIT FABRIC | C16: c/#10 OLIVE | D16: POLYESTER100% | E16: 18 | F16: M. | G16: 1230 | H16: =E16*G16 -> 22140
B17: 両面ハニカム 丸編み 後染め | C17: c/#6 YELLOW | D17: WIDTH:130CM (190ｇ/㎡ ) | E17: 11 | F17: M. | G17: 1230 | H17: =E17*G17 -> 13530
B18: 短繊維、プリント加工なし | C18: c/#7 GREEN | E18: 39.9 | F18: M. | G18: 1230 | H18: =E18*G18 -> 49077 | J18: 1/23
C19: c/#BK | E19: 41.2 | F19: M. | G19: 1230 | H19: =E19*G19 -> 50676
D21: STYLE:s25-so-00
B22: 1060341 | C22: c/#09 BLACK | D22: WOVEN FABRIC | E22: 63.2 | F22: M. | G22: 1570 | H22: =E22*G22 -> 99224
B23: WOVEN FABRIC | C23: c/#16 ORANGE | D23: NYLON90%、POLYURETHANE10% | E23: 63.1 | F23: M. | G23: 1570 | H23: =E23*G23 -> 99067
B24: 平織 後染め | D24: WIDTH:130CM (87ｇ/㎡ )
B25: 短繊維、プリント加工なし
A27: 13-15 | D27: STYLE:s25-so-05 | N27: 3
B28: 1060201 | C28: c/#00 WHITE | D28: KNIT FABRIC | E28: 11 | F28: M. | G28: 1230 | H28: =E28*G28 -> 13530
B29: KNIT FABRIC | C29: c/#09 BLACK | D29: POLYESTER100% | E29: 11 | F29: M. | G29: 1230 | H29: =E29*G29 -> 13530 | I29: 入庫NO.22071144 | J29: 2/5
B30: クールドッツ 後染め | C30: c/#24 GRAY | D30: WIDTH:155CM (108g/㎡ ) | E30: 11 | F30: M. | G30: 1230 | H30: =E30*G30 -> 13530
B31: 短繊維、プリント加工なし
A33: 16 | D33: STYLE: cc25ss-26 | N33: 1
B34: BL1300 | C34: C/#BK | D34: KNIT FABRIC | E34: 3 | F34: M. | G34: 1480 | H34: =E34*G34 -> 4440
B35: KNIT FABRIC | D35: COTTON100% | I35: 入庫NO.22071510 | J35: 2/18
B36: 綿メッシュ 丸編み | D36: WIDTH:85WCM (190ｇ/㎡ )
B37: 短繊維、プリント加工なし
A39: 17 | B39: pattern paper | D39: s25-so-00 pattern paper | E39: 3 | F39: SET. | G39: 100 | H39: =E39*G39 -> 300 | N39: 1
B40: pattern paper | D40: s25-so-05 pattern paper | E40: 3 | F40: SET. | G40: 100 | H40: =E40*G40 -> 300
B41: pattern paper | D41: s25-so-06 pattern paper | E41: 4 | F41: SET. | G41: 100 | H41: =E41*G41 -> 400
B42: pattern paper | D42: s25-so-07 pattern paper | E42: 4 | F42: SET. | G42: 100 | H42: =E42*G42 -> 400 | I42: 入庫NO.22071540
B43: pattern paper | D43: s25-so-08 pattern paper | E43: 4 | F43: SET. | G43: 100 | H43: =E43*G43 -> 400 | J43: 2/19
B45: men's jacket SAMPLE CLOTHES | D45: s25-so-00 SAMPLE | E45: 1 | F45: PCS. | G45: 4000 | H45: =E45*G45 -> 4000
B46: men's T-shirt SAMPLE CLOTHES | D46: s25-so-05 SAMPLE | E46: 1 | F46: PCS. | G46: 2500 | H46: =E46*G46 -> 2500
B47: men's T-shirt SAMPLE CLOTHES | D47: s25-so-06 SAMPLE | E47: 1 | F47: PCS. | G47: 2500 | H47: 3000
B48: men's tank top SAMPLE CLOTHES | D48: s25-so-07 SAMPLE | E48: 1 | F48: PCS. | G48: 2000 | H48: 4000
B49: men's short pants SAMPLE CLOTHES | D49: s25-so-08 SAMPLE | E49: 1 | F49: PCS. | G49: 3000 | H49: 3000
...

Sheet NARITA (2)
A2: - ATTACHED SHEET -
A4: C/NO. | B4: ART NO. | C4: COLOR | D4: DESCRIPTION OF GOODS | E4: Q'TY | F4: U/PRICE | H4: AMOUNT | I4: 佐川伝票・明細 | J4: 搬入日 | K4: 伝票NO | L4: 搬入内容 | M4: 数量 | N4: 箱数
B6: (H.S. CODE) | D6: ='[4]NARITA '!D6 -> FABRIC & PARTS FOR WEAR & SAMPLE CLOTHES | G6: ='[5]shipper master'!C48 -> F.O.B. TOKYO IN YEN
D7: MADE IN JAPAN
A9: 18 | D9: S25-SO-06 | I9: 入庫NO.22071482 | M9: 1
B10: T415 | D10: KNIT FABRIC POLYESTER100% メッシュ 後染め 短繊維
D11: BK-2m 15-2m 13-2m | E11: 6 | F11: M. | G11: 530 | H11: 3180
B12: 3C DA4FQ1 | D12: ZIPPER 材質：ポリエステル
D13: 22cm ＃342-15 ＃830-15 ＃580-15 | E13: 45 | F13: PCS. | G13: 70 | H13: 3150
D15: S25-SO-00
B16: PX EJ24 M | C16: SPC | D16: DOT BUTTONS 材質：真鍮 | E16: 100 | F16: SET. | G16: 22 | H16: 2200
B17: PACKING | C17: D/G | E17: 100 | F17: PCS. | G17: 4 | H17: 400
D19: S25-SO-05
B20: W7480 | C20: BK | D20: KNIT FABRIC POLYESTER100% メッシュ 後染め 短繊維 | E20: 1 | F20: M. | G20: 385 | H20: 385
B21: 3CF C DFW | C21: 580 | D21: ZIPPER 12CM 材質：ポリエステル | E21: 30 | F21: PCS. | G21: 100 | H21: 3000
B22: SIC199 | C22: BK | D22: TAPE 10MM 材質：ポリエステル100％ | E22: 30 | F22: M. | G22: 50 | H22: 1500
B23: PL-S17 | C23: C/BK | D23: DOT BUTTONS 材質：真鍮 | E23: 100 | F23: SET. | G23: 10 | H23: 1000
B24: PACKING | C24: D/G | D24: パッキン 材質：ポリエステル | E24: 100 | F24: PCS. | G24: 4 | H24: 400
D26: S25-SO-00
B27: W7480 | C27: BK | D27: KNIT FABRIC POLYESTER100% メッシュ 後染め 短繊維 | E27: 8 | F27: M. | G27: 385 | H27: 3080
B28: SE300 | C28: HBK | D28: EYELET 材質：真鍮 | E28: 100 | F28: PCS. | G28: 25 | H28: 2500
B29: PACKING | C29: BK | D29: パッキン 材質：ポリエステル | E29: 100 | F29: PCS. | G29: 3 | H29: 300
B30: SIC199 | C30: BK | D30: TAPE 20MM 材質：ポリエステル100％ | E30: 4 | F30: M. | G30: 150 | H30: 600
B31: 3CF C DFW | C31: 580 | D31: ZIPPER 12CM 材質：ポリエステル | E31: 39 | F31: PCS. | G31: 100 | H31: 3900
B32: SIC105 | C32: BK | D32: TAPE 9MM ニットテープ 材質：ポリエステル | E32: 34 | F32: M. | G32: 120 | H32: 4080
B33: B21 | C33: BK | D33: ELASTIC WAIST 30mm 材質：ナイロン | E33: 36 | F33: M. | G33: 300 | H33: 10800
B35: TOTAL : | C35: 1CARTONS | E35: =SUMIF($F$9:$F$34,"M.",$E$9:$E$34) -> 119 | F35: M. | H35: =SUMIF($F$9:$F$34,"M.",$H$9:$H$34) -> 23625
E36: =SUMIF($F$9:$F$34,"PCS.",$E$9:$E$34) -> 514 | F36: PCS. | H36: =SUMIF($F$9:$F$34,"PCS.",$H$9:$H$34) -> 13650
E37: =SUMIF($F$9:$F$34,"SET.",$E$9:$E$34) -> 200 | F37: SET. | H37: =SUMIF($F$9:$F$34,"SET.",$H$9:$H$34) -> 3200
B38: TOTAL : | G38: TOTAL | H38: =SUM(H9:H34) -> 40475

Sheet サンプル製品カタログ
D1: ITEM
B2: NAME | C2: color | E2: lady's or men's | F2: WOVEN or KNIT | G2: picture | H2: Composition | I2: packingNo.
B3: men's jacket SAMPLE CLOTHES | C3: C/#BLACK | D3: s25-so-00 SAMPLE | E3: men's | F3: WOVEN FABRIC | H3: NYLON90%、POLYURETHANE10% | I3: 17
B4: men's T-shirt SAMPLE CLOTHES | C4: C/#BLACK | D4: s25-so-05 SAMPLE | E4: men's | F4: KNIT FABRIC | H4: POLYESTER100% | I4: 17
B5: men's T-shirt SAMPLE CLOTHES | C5: C/#BLACK | D5: s25-so-06 SAMPLE | E5: men's | F5: KNIT FABRIC | H5: POLYESTER100% | I5: 17
B6: men's tank top SAMPLE CLOTHES | C6: C/#BLACK | D6: s25-so-07 SAMPLE | E6: men's | F6: KNIT FABRIC | H6: POLYESTER100% | I6: 17
B7: men's short pants SAMPLE CLOTHES | C7: C/#BLACK | D7: s25-so-08 SAMPLE | E7: men's | F7: WOVEN FABRIC | H7: NYLON85%、POLYURETHANE15% | I7: 17

Sheet LABEL
A2: LABEL SHEET -
A4: C/NO. | B4: ART NO. | C4: DESCRIPTION OF GOODS | D4: 原産国
A5: 1-3 | C5: STYLE:s25-so-08
B6: 08500020052 | C6: WOVEN FABRIC
B7: WOVEN FABRIC | C7: NYLON85%、POLYURETHANE15% | D7: MADE IN JAPAN
B8: 綾織 ツイル 後染め | C8: WIDTH:140CM (156ｇ/㎡ ) | D8: SHUNYA CO., LTD.
B9: 短繊維、プリント加工なし
A11: C/NO. | B11: ART NO. | C11: DESCRIPTION OF GOODS | D11: 原産国
A12: 4-12 | C12: STYLE:s25-so-06,s25-so-07
B13: 14-9910 | C13: KNIT FABRIC
B14: KNIT FABRIC | C14: POLYESTER100%
B15: 両面ハニカム 丸編み 後染め | C15: WIDTH:130CM (190ｇ/㎡ )
B16: 短繊維、プリント加工なし
D18: MADE IN JAPAN
C19: STYLE:s25-so-00 | D19: SHUNYA CO., LTD.
B20: 1060341 | C20: WOVEN FABRIC
B21: WOVEN FABRIC | C21: NYLON90%、POLYURETHANE10%
B22: 平織 後染め | C22: WIDTH:130CM (87ｇ/㎡ )
B23: 短繊維、プリント加工なし
A25: C/NO. | B25: ART NO. | C25: DESCRIPTION OF GOODS | D25: 原産国
A26: 13-15 | C26: STYLE:s25-so-05
B27: 1060201 | C27: KNIT FABRIC
B28: KNIT FABRIC | C28: POLYESTER100%
B29: クールドッツ 後染め | C29: WIDTH:155CM (108g/㎡ ) | D29: MADE IN JAPAN
B30: 短繊維、プリント加工なし | D30: SHUNYA CO., LTD.
A32: C/NO. | B32: ART NO. | C32: DESCRIPTION OF GOODS | D32: 原産国
A33: 16 | C33: STYLE: cc25ss-26
B34: BL1300 | C34: KNIT FABRIC
B35: KNIT FABRIC | C35: COTTON100% | D35: MADE IN JAPAN
B36: 綿メッシュ 丸編み | C36: WIDTH:85WCM (190ｇ/㎡ ) | D36: SHUNYA CO., LTD.
B37: 短繊維、プリント加工なし
A39: C/NO. | B39: ART NO. | C39: DESCRIPTION OF GOODS | D39: 原産国
A40: 17 | B40: pattern paper | C40: s25-so-00 pattern paper
B41: pattern paper | C41: s25-so-05 pattern paper
B42: pattern paper | C42: s25-so-06 pattern paper
B43: pattern paper | C43: s25-so-07 pattern paper
B44: pattern paper | C44: s25-so-08 pattern paper | D44: MADE IN JAPAN
D45: SHUNYA CO., LTD.
B46: men's jacket SAMPLE CLOTHES | C46: s25-so-00 SAMPLE
B47: men's T-shirt SAMPLE CLOTHES | C47: s25-so-05 SAMPLE
...
