Workbook
Name pricetable: #REF!
Name pricetable: #REF!
Name pricetable: #REF!
Name pricetable: #REF!

Sheet shipper master
A1: 1 | B1: S/CODE | C1: SHIPPER NAME
A2: =A1+1 -> 2 | B2: SHIPPER | C2: SHUNYA CO., LTD.
A3: =A2+1 -> 3 | B3: SHIPPER ADDRESS 1 | C3: KENSHIN BLDG., 1F, 1-22-10 DOUGENZAKA,
A4: =A3+1 -> 4 | B4: SHIPPER ADDRESS 2 | C4: SHIBUYA-KU 150-0043
A5: =A4+1 -> 5 | B5: SHIPPER ADDRESS 3 | C5: TEL : +81(0)3-5459-1177
A6: =A5+1 -> 6 | B6: TEL
A7: =A6+1 -> 7 | B7: FAX
A8: =A7+1 -> 8 | B8: ATTN OR VAT NO.
A9: =A8+1 -> 9 | B9: BUYER | C9: VIVAN GARMENTS VIET NAM COMPANY LIMITED
A10: =A9+1 -> 10 | B10: BUYER ADDRESS1 | C10: D17 Street , Sai Gon South Residential Area
A11: =A10+1 -> 11 | B11: BUYER ADDRESS2 | C11: Hamlet 3 , Long Hau Commune , Can Giuoc District,
A12: =A11+1 -> 12 | B12: BUYER ADDRESS3 | C12: Long An Province , VietNam
A13: =A12+1 -> 13 | B13: TEL/FAX | C13: TEL : ( 084 ) 097 22 00 798 ATTN : MR. TUAN
A14: =A13+1 -> 14 | B14: ATTN
A15: =A14+1 -> 15 | B15: CONSIGNEE : | C15: - SAME AS BUYER -
A16: =A15+1 -> 16 | B16: CONSIGNEE ADDRESS1
A17: =A16+1 -> 17 | B17: CONSIGNEE ADDRESS2
A18: =A17+1 -> 18 | B18: CONSIGNEE ADDRESS3
A19: =A18+1 -> 19 | B19: TEL
A20: =A19+1 -> 20 | B20: FAX
A21: =A20+1 -> 21 | B21: ATTN | C21: NO COMMERCIAL
A22: =A21+1 -> 22 | B22: PAYMENT 1
A23: =A22+1 -> 23 | B23: PAYMENT 2
A24: =A23+1 -> 24 | B24: SHIPPER PER | C24: AIRCRAFT
A25: =A24+1 -> 25 | B25: INVOICE DATE | C25: Jan, 09 2026
A26: =A25+1 -> 26 | B26: INVOICE NO. | C26: SY-7900109VT-DD-01
A27: =A26+1 -> 27 | B27: CONTRACT NO. | C27: =C26 -> SY-7900109VT-DD-01
A28: =A27+1 -> 28 | B28: CONTRACT DATE
A29: =A28+1 -> 29 | B29: ORDER DATE
A30: =A29+1 -> 30 | B30: ORDER NO.
A31: =A30+1 -> 31 | B31: L/C DATE
A32: =A31+1 -> 32 | B32: FROM | C32: TOKYO, JAPAN
A33: =A32+1 -> 33 | B33: TO | C33: HOCHIMINH-CITY, VIETNAM
A34: =A33+1 -> 34 | B34: VIA
A35: =A34+1 -> 35 | B35: SHIPPING TERMS | C35: F.O.B. TOKYO IN YEN
A36: =A35+1 -> 36 | B36: TITTLE 1 | C36: FABRIC & PARTS FOR WEAR & SAMPLE CLOTHES
A37: =A36+1 -> 37 | B37: TITTLE 2
A38: =A37+1 -> 38 | B38: ATTACHE | C38: - DETAILS AS PER ATTACHED SHEET -
A39: =A38+1 -> 39 | B39: C/NO.
A40: =A39+1 -> 40 | B40: STYLE NO.
...

Sheet case mark 
A2: ='shipper master'!C26 -> SY-7900109VT-DD-01 | I2: ='shipper master'!C26 -> SY-7900109VT-DD-01
A3: ='[1]shipper master'!C50 -> VIVAN GARMENTS VIET NAM | I3: ='[1]shipper master'!C50 -> VIVAN GARMENTS VIET NAM
A4: ='[1]shipper master'!C51 -> COMPANY LIMITED | I4: ='[1]shipper master'!C51 -> COMPANY LIMITED
A5: ='[1]shipper master'!C52 -> HOCHIMINH-CITY, VIETNAM | I5: ='[1]shipper master'!C52 -> HOCHIMINH-CITY, VIETNAM
A6: C/NO. | C6: 1 | I6: C/NO. | K6: 2
A7: ='[1]shipper master'!C54 -> MADE IN JAPAN | I7: ='[1]shipper master'!C54 -> MADE IN JAPAN
A13: ='shipper master'!C26 -> SY-7900109VT-DD-01 | I13: ='shipper master'!C26 -> SY-7900109VT-DD-01
A14: ='[1]shipper master'!C50 -> VIVAN GARMENTS VIET NAM | I14: ='[1]shipper master'!C50 -> VIVAN GARMENTS VIET NAM
A15: ='[1]shipper master'!C51 -> COMPANY LIMITED | I15: ='[1]shipper master'!C51 -> COMPANY LIMITED
A16: ='[1]shipper master'!C52 -> HOCHIMINH-CITY, VIETNAM | I16: ='[1]shipper master'!C52 -> HOCHIMINH-CITY, VIETNAM
A17: C/NO. | C17: 3 | I17: C/NO. | K17: 4
A18: ='[1]shipper master'!C54 -> MADE IN JAPAN | I18: ='[1]shipper master'!C54 -> MADE IN JAPAN

Sheet invoice
A1: INVOICE
A2: ='[2]shipper master'!C2 -> SHUNYA CO., LTD.
A3: ='[2]shipper master'!C3 -> KENSHIN BLDG., 1F, 1-22-10 DOUGENZAKA,
A4: ='[2]shipper master'!C4 -> SHIBUYA-KU 150-0043 | N4: ='[2]shipper master'!C6 -> 0
A5: ='[2]shipper master'!C5 -> TEL : +81(0)3-5459-1177 | N5: ='[2]shipper master'!C7 -> 0
A6: IMPORTER | F6: INVOICE NO. | N6: CASE MARK
A7: ='[2]shipper master'!C9 -> VIVAN GARMENTS VIET NAM COMPANY LIMITED | F7: ='shipper master'!C26 -> SY-7900109VT-DD-01
A8: ='[2]shipper master'!C10 -> D17 Street , Sai Gon South Residential Area | F8: INVOICE DATE | N8: ='shipper master'!C26 -> SY-7900109VT-DD-01
A9: ='[2]shipper master'!C11 -> Hamlet 3 , Long Hau Commune , Can Giuoc District, | F9: ='shipper master'!C25 -> Jan, 09 2026 | N9: ='[1]shipper master'!C50 -> VIVAN GARMENTS VIET NAM
A10: ='[2]shipper master'!C12 -> Long An Province , VietNam | F10: CONTRACT NO. | N10: ='[1]shipper master'!C51 -> COMPANY LIMITED
A11: ='[2]shipper master'!C13 -> TEL : ( 084 ) 097 22 00 798 ATTN : MR. TUAN | F11: ='shipper master'!C26 -> SY-7900109VT-DD-01 | N11: ='[1]shipper master'!C52 -> HOCHIMINH-CITY, VIETNAM
A12: CONSIGNEE | F12: ORDER NO. | N12: C/NO. 1-8
A13: ='[2]shipper master'!C15 -> - SAME AS BUYER - | F13: ='[2]shipper master'!C30 -> 0 | N13: MADE IN JAPAN
A14: ='[2]shipper master'!C16 -> 0 | F14: ORDER DATE
A15: ='[2]shipper master'!C17 -> 0 | F15: ='[2]shipper master'!C29 -> 0
A16: ='[2]shipper master'!C18 -> 0 | F16: L/C NO.
A17: ='[2]shipper master'!C19 -> 0
A18: PAYMENT METHOD
A19: ='[2]shipper master'!C21 -> NO COMMERCIAL
A20: SHIPPED PER | D20: FROM | F20: TO | N20: VIA
A21: ='[2]shipper master'!C24 -> AIRCRAFT | D21: ='[2]shipper master'!C32 -> TOKYO, JAPAN | G21: ='[2]shipper master'!C33 -> HOCHIMINH-CITY, VIETNAM
A22: C/NO. | B22: ART NO. | D22: DESCRIPTION OF GOODS | E22: COLOR | H22: SIZE | M22: Q'TY | N22: U/PRICE | O22: AMOUNT
B24: ='[2]shipper master'!C36 -> FABRIC & PARTS FOR WEAR & SAMPLE CLOTHES | N24: ='[2]shipper master'!C48 -> F.O.B. TOKYO IN YEN
B26: ='[2]shipper master'!C37 -> 0 | M26: ='NARITA '!E38 -> 228.4 | N26: M. | O26: ='NARITA '!H38 -> 250253
M27: ='NARITA '!E39 -> 1700 | N27: PCS. | O27: ='NARITA '!H39 -> 85000
M28: ='NARITA '!E40 -> 0 | O28: ='NARITA '!H40 -> 0
B29: ='[2]shipper master'!C38 -> - DETAILS AS PER ATTACHED SHEET -
B31: TOTAL : | E31: ='NARITA '!E38 -> 228.4 | J31: M. | K31: =K29 -> 0 | L31: ='NARITA '!E39 -> 1700 | M31: PCS. | O31: =SUM(O26:O27) -> 335253
A34: ='[2]shipper master'!C63 -> " THESE GOODS WILL BE RETURN TO JAPAN | I34: " NO COMMER VALUE | M34: " NO COMMERCIAL VALUE
A35: ='[2]shipper master'!C64 -> AFTER MANUFACTURED AT VIET NAM " | I35: VALUE FOR CUSTOMS PURPOSE ONLY " | M35: VALUE FOR CUSTOMS PURPOSE ONLY "
D36: ='[2]shipper master'!C58 -> 0
A37: ='[2]shipper master'!C60 -> COUNTRY OF ORIGIN : JAPAN
A39: TOTAL CARTONS : | D39: 8CARTONS
A40: TOTAL GROSS WEIGHT : | D40: KGS

Sheet NARITA 
A2: - ATTACHED SHEET -
A4: C/NO. | B4: ART NO. | C4: COLOR | D4: DESCRIPTION OF GOODS | E4: Q'TY | F4: U/PRICE | H4: AMOUNT | I4: 佐川伝票・明細 | J4: 搬入日 | K4: 伝票NO | L4: 搬入内容 | M4: 数量 | N4: 箱数
B6: (H.S. CODE) | D6: =[3]invoice!B24 -> FABRIC & PARTS FOR WEAR & SAMPLE CLOTHES | G6: ='[1]shipper master'!C48 -> F.O.B. TOKYO IN YEN
D7: MADE IN JAPAN
A8: 1-4 | D8: STYLE:26S-SH03(25SY-36),26S-SH04(25SY-35),26S-PT05(25SY-39) | N8: 4
B9: 32-44105 | C9: c/#BK | D9: WOVEN FABRIC | E9: 155 | F9: M. | G9: 1370 | H9: =E9*G9 -> 212350
B10: WOVEN FABRIC | D10: VISCOSE100% | I10: 入庫NO.22078279 | J10: 12/25
B11: 朱子織 後染め サテン | D11: WIDTH:135CM (200ｇ/㎡ ) | I11: 入庫NO.22078280
B12: 長繊維、プリント加工なし
A14: 5 | D14: STYLE:26S-JK01(25SY-22) | N14: 1
B15: 51010 | C15: c/#102 RED | D15: WOVEN FABRIC | E15: 29.7 | F15: M. | G15: 395 | H15: =E15*G15 -> 11731.5 | J15: 1/5
B16: WOVEN FABRIC | C16: c/#513 BEIGE | D16: COTTON100% | E16: 29.7 | F16: M. | G16: 395 | H16: =E16*G16 -> 11731.5 | I16: 入庫NO.22078307
B17: 平織 先染め タータンチェック | D17: WIDTH:111CM (100ｇ/㎡ )
B18: 短繊維、プリント加工あり
A20: 6 | D20: STYLE:26S-SH01(25SY-28),26S-SH02(25SY-19),26S-SH03(25SY-36),26S-SH04(25SY-35) | N20: 1
B21: ST-1005 | C21: c/#WHITE | D21: shell button 11.5mm | E21: 1700 | F21: PCS. | G21: 50 | H21: =E21*G21 -> 85000
B22: shell button | I22: 入庫NO.22078348 | J22: 1/8
B23: 学術名： Tectus maximus
B24: 高瀬
A26: 7 | D26: STYLE:26S-CS01(25SY-29) | N26: 1
B27: 027G0081930 | C27: c/#G GRAY | D27: KNIT FABRIC | E27: 3 | F27: M. | G27: 1020 | H27: =E27*G27 -> 3060
B28: KNIT FABRIC | C28: c/#008 BLACK | D28: COTTON100% | E28: 3 | F28: M. | G28: 1020 | H28: =E28*G28 -> 3060 | I28: 第一貨物/61446559403 | J28: 1/8
B29: 丸編みパイル編 裏毛 先染め | D29: WIDTH:180CM (227ｇ/㎡ )
B30: 短繊維、プリント加工なし
A32: 8 | D32: STYLE:26S-CS01(25SY-29) | N32: 1
B33: 027G0081924 | C33: c/#G GRAY | D33: KNIT FABRIC | E33: 8 | F33: M. | G33: 1040 | H33: =E33*G33 -> 8320
B34: KNIT FABRIC | D34: COTTON 95% POLYURETHANE5% | I34: 佐川：4408-9526-5871 | J34: 1/9
B35: 丸編みリブ編 先染め | D35: WIDTH:90CM (234ｇ/㎡ )
B36: 短繊維、プリント加工なし
E38: =SUMIF($F$8:$F$37,"M.",$E$8:$E$37) -> 228.4 | F38: M. | H38: =SUMIF($F$8:$F$37,"M.",$H$8:$H$37) -> 250253
E39: =SUMIF($F$8:$F$37,"PCS.",$E$8:$E$37) -> 1700 | F39: PCS. | H39: =SUMIF($F$8:$F$37,"PCS.",$H$8:$H$37) -> 85000
B41: TOTAL : | C41: 8CARTONS | G41: TOTAL | H41: =SUM(H8:H37) -> 335253

Sheet LABEL
A2: LABEL SHEET -
A4: C/NO. | B4: ART NO. | C4: DESCRIPTION OF GOODS | D4: 原産国
A5: 1-4 | C5: STYLE:26S-SH03(25SY-36),26S-SH04(25SY-35),26S-PT05(25SY-39)
B6: 32-44105 | C6: WOVEN FABRIC | D6: MADE IN JAPAN
B7: WOVEN FABRIC | C7: VISCOSE100% | D7: SHUNYA CO., LTD.
B8: 朱子織 後染め サテン | C8: WIDTH:135CM (200ｇ/㎡ )
B9: 長繊維、プリント加工なし
A11: C/NO. | B11: ART NO. | C11: DESCRIPTION OF GOODS | D11: 原産国
A12: 5 | C12: STYLE:26S-JK01(25SY-22)
B13: 51010 | C13: WOVEN FABRIC | D13: MADE IN JAPAN
B14: WOVEN FABRIC | C14: COTTON100% | D14: SHUNYA CO., LTD.
B15: 平織 先染め タータンチェック | C15: WIDTH:111CM (100ｇ/㎡ )
B16: 短繊維、プリント加工あり
A18: C/NO. | B18: ART NO. | C18: DESCRIPTION OF GOODS | D18: 原産国
A19: 6 | C19: STYLE:26S-SH01(25SY-28),26S-SH02(25SY-19),26S-SH03(25SY-36),26S-SH04(25SY-35)
B20: ST-1005 | C20: shell button 11.5mm | D20: MADE IN JAPAN
B21: shell button | D21: SHUNYA CO., LTD.
B22: 学術名： Tectus maximus
B23: 高瀬
A25: C/NO. | B25: ART NO. | C25: DESCRIPTION OF GOODS | D25: 原産国
A26: 7 | C26: STYLE:26S-CS01(25SY-29)
B27: 027G0081930 | C27: KNIT FABRIC | D27: MADE IN JAPAN
B28: KNIT FABRIC | C28: COTTON100% | D28: SHUNYA CO., LTD.
B29: 丸編みパイル編 裏毛 先染め | C29: WIDTH:180CM (227ｇ/㎡ )
B30: 短繊維、プリント加工なし
A32: C/NO. | B32: ART NO. | C32: DESCRIPTION OF GOODS | D32: 原産国
A33: 8 | C33: STYLE:26S-CS01(25SY-29)
B34: 027G0081924 | C34: KNIT FABRIC | D34: MADE IN JAPAN
B35: KNIT FABRIC | C35: COTTON 95% POLYURETHANE5% | D35: SHUNYA CO., LTD.
B36: 丸編みリブ編 先染め | C36: WIDTH:90CM (234ｇ/㎡ )
B37: 短繊維、プリント加工なし
