Workbook
Name pricetable: #REF!
Name pricetable: #REF!
Name pricetable: #REF!
Name pricetable: #REF!
Name pricetable: #REF!

Sheet shipper master
A1: 1 | B1: S/CODE | C1: SHIPPER NAME
A2: =A1+1 -> 2 | B2: SHIPPER | C2: SHUNYA CO., LTD.
A3: =A2+1 -> 3 | B3: SHIPPER ADDRESS 1 | C3: KENSHIN BLDG., 1F, 1-22-10 DOUGENZAKA,
A4: =A3+1 -> 4 | B4: SHIPPER ADDRESS 2 | C4: SHIBUYA-KU 150-0043
A5: =A4+1 -> 5 | B5: SHIPPER ADDRESS 3 | C5: TEL : +81(0)3-5459-1177
A6: =A5+1 -> 6 | B6: TEL
A7: =A6+1 -> 7 | B7: FAX
A8: =A7+1 -> 8 | B8: ATTN OR VAT NO.
A9: =A8+1 -> 9 | B9: BUYER | C9: VIVAN GARMENTS VIET NAM COMPANY LIMITED
A10: =A9+1 -> 10 | B10: BUYER ADDRESS1 | C10: D17 Street , Sai Gon South Residential Area
A11: =A10+1 -> 11 | B11: BUYER ADDRESS2 | C11: Hamlet 3 , Long Hau Commune , Can Giuoc District,
A12: =A11+1 -> 12 | B12: BUYER ADDRESS3 | C12: Long An Province , VietNam
A13: =A12+1 -> 13 | B13: TEL/FAX | C13: TEL : ( 084 ) 097 22 00 798 ATTN : MR. TUAN
A14: =A13+1 -> 14 | B14: ATTN
A15: =A14+1 -> 15 | B15: CONSIGNEE : | C15: - SAME AS BUYER -
A16: =A15+1 -> 16 | B16: CONSIGNEE ADDRESS1
A17: =A16+1 -> 17 | B17: CONSIGNEE ADDRESS2
A18: =A17+1 -> 18 | B18: CONSIGNEE ADDRESS3
A19: =A18+1 -> 19 | B19: TEL
A20: =A19+1 -> 20 | B20: FAX
A21: =A20+1 -> 21 | B21: ATTN | C21: NO COMMERCIAL
A22: =A21+1 -> 22 | B22: PAYMENT 1
A23: =A22+1 -> 23 | B23: PAYMENT 2
A24: =A23+1 -> 24 | B24: SHIPPER PER | C24: AIRCRAFT
A25: =A24+1 -> 25 | B25: INVOICE DATE | C25: Dec, 22 2025
A26: =A25+1 -> 26 | B26: INVOICE NO. | C26: SY-7801222-VT-DD-01
A27: =A26+1 -> 27 | B27: CONTRACT NO. | C27: =C26 -> SY-7801222-VT-DD-01
A28: =A27+1 -> 28 | B28: CONTRACT DATE
A29: =A28+1 -> 29 | B29: ORDER DATE
A30: =A29+1 -> 30 | B30: ORDER NO.
A31: =A30+1 -> 31 | B31: L/C DATE
A32: =A31+1 -> 32 | B32: FROM | C32: TOKYO, JAPAN
A33: =A32+1 -> 33 | B33: TO | C33: HOCHIMINH-CITY, VIETNAM
A34: =A33+1 -> 34 | B34: VIA
A35: =A34+1 -> 35 | B35: SHIPPING TERMS | C35: F.O.B. TOKYO IN YEN
A36: =A35+1 -> 36 | B36: TITTLE 1 | C36: FABRIC & PARTS FOR WEAR & SAMPLE CLOTHES
A37: =A36+1 -> 37 | B37: TITTLE 2
A38: =A37+1 -> 38 | B38: ATTACHE | C38: - DETAILS AS PER ATTACHED SHEET -
A39: =A38+1 -> 39 | B39: C/NO.
A40: =A39+1 -> 40 | B40: STYLE NO.
...

Sheet case mark 
A2: ='shipper master'!C26 -> SY-7801222-VT-DD-01 | I2: ='shipper master'!C26 -> SY-7801222-VT-DD-01
A3: ='[1]shipper master'!C50 -> VIVAN GARMENTS VIET NAM | I3: ='[1]shipper master'!C50 -> VIVAN GARMENTS VIET NAM
A4: ='[1]shipper master'!C51 -> COMPANY LIMITED | I4: ='[1]shipper master'!C51 -> COMPANY LIMITED
A5: ='[1]shipper master'!C52 -> HOCHIMINH-CITY, VIETNAM | I5: ='[1]shipper master'!C52 -> HOCHIMINH-CITY, VIETNAM
A6: C/NO. | C6: 1 | I6: C/NO. | K6: 2
A7: ='[1]shipper master'!C54 -> MADE IN JAPAN | I7: ='[1]shipper master'!C54 -> MADE IN JAPAN
A13: ='shipper master'!C26 -> SY-7801222-VT-DD-01 | I13: ='shipper master'!C26 -> SY-7801222-VT-DD-01
A14: ='[1]shipper master'!C50 -> VIVAN GARMENTS VIET NAM | I14: ='[1]shipper master'!C50 -> VIVAN GARMENTS VIET NAM
A15: ='[1]shipper master'!C51 -> COMPANY LIMITED | I15: ='[1]shipper master'!C51 -> COMPANY LIMITED
A16: ='[1]shipper master'!C52 -> HOCHIMINH-CITY, VIETNAM | I16: ='[1]shipper master'!C52 -> HOCHIMINH-CITY, VIETNAM
A17: C/NO. | C17: 3 | I17: C/NO. | K17: 4
A18: ='[1]shipper master'!C54 -> MADE IN JAPAN | I18: ='[1]shipper master'!C54 -> MADE IN JAPAN

Sheet invoice
A1: INVOICE
A2: ='[2]shipper master'!C2 -> SHUNYA CO., LTD.
A3: ='[2]shipper master'!C3 -> KENSHIN BLDG., 1F, 1-22-10 DOUGENZAKA,
A4: ='[2]shipper master'!C4 -> SHIBUYA-KU 150-0043 | N4: ='[2]shipper master'!C6 -> 0
A5: ='[2]shipper master'!C5 -> TEL : +81(0)3-5459-1177 | N5: ='[2]shipper master'!C7 -> 0
A6: IMPORTER | F6: INVOICE NO. | N6: CASE MARK
A7: ='[2]shipper master'!C9 -> VIVAN GARMENTS VIET NAM COMPANY LIMITED | F7: ='shipper master'!C26 -> SY-7801222-VT-DD-01
A8: ='[2]shipper master'!C10 -> D17 Street , Sai Gon South Residential Area | F8: INVOICE DATE | N8: ='shipper master'!C26 -> SY-7801222-VT-DD-01
A9: ='[2]shipper master'!C11 -> Hamlet 3 , Long Hau Commune , Can Giuoc District, | F9: ='shipper master'!C25 -> Dec, 22 2025 | N9: ='[1]shipper master'!C50 -> VIVAN GARMENTS VIET NAM
A10: ='[2]shipper master'!C12 -> Long An Province , VietNam | F10: CONTRACT NO. | N10: ='[1]shipper master'!C51 -> COMPANY LIMITED
A11: ='[2]shipper master'!C13 -> TEL : ( 084 ) 097 22 00 798 ATTN : MR. TUAN | F11: ='shipper master'!C26 -> SY-7801222-VT-DD-01 | N11: ='[1]shipper master'!C52 -> HOCHIMINH-CITY, VIETNAM
A12: CONSIGNEE | F12: ORDER NO. | N12: C/NO. 1-21
A13: ='[2]shipper master'!C15 -> - SAME AS BUYER - | F13: ='[2]shipper master'!C30 -> 0 | N13: MADE IN JAPAN
A14: ='[2]shipper master'!C16 -> 0 | F14: ORDER DATE | N14: MADE IN USA
A15: ='[2]shipper master'!C17 -> 0 | F15: ='[2]shipper master'!C29 -> 0 | N15: MADE IN CHINA
A16: ='[2]shipper master'!C18 -> 0 | F16: L/C NO.
A17: ='[2]shipper master'!C19 -> 0
A18: PAYMENT METHOD
A19: ='[2]shipper master'!C21 -> NO COMMERCIAL
A20: SHIPPED PER | D20: FROM | F20: TO | N20: VIA
A21: ='[2]shipper master'!C24 -> AIRCRAFT | D21: ='[2]shipper master'!C32 -> TOKYO, JAPAN | G21: ='[2]shipper master'!C33 -> HOCHIMINH-CITY, VIETNAM
A22: C/NO. | B22: ART NO. | D22: DESCRIPTION OF GOODS | E22: COLOR | H22: SIZE | M22: Q'TY | N22: U/PRICE | O22: AMOUNT
B24: ='[2]shipper master'!C36 -> FABRIC & PARTS FOR WEAR & SAMPLE CLOTHES | N24: ='[2]shipper master'!C48 -> F.O.B. TOKYO IN YEN
B26: ='[2]shipper master'!C37 -> 0 | M26: ='NARITA '!E71+'NARITA (2)'!E113 -> 687 | N26: M. | O26: ='NARITA '!H71+'NARITA (2)'!H113 -> 579080
M27: ='NARITA '!E72+'NARITA (2)'!E114 -> 3189 | N27: PCS. | O27: ='NARITA '!H72+'NARITA (2)'!H114 -> 567140
M28: ='NARITA '!E73 -> 10 | N28: KG. | O28: ='NARITA '!H73 -> 10000
M29: ='NARITA (2)'!E115 -> 500 | N29: SET. | O29: ='NARITA (2)'!H115 -> 9500
M30: ='NARITA (2)'!E116 -> 25 | N30: ROLL. | O30: ='NARITA (2)'!H116 -> 55200
B31: ='[2]shipper master'!C38 -> - DETAILS AS PER ATTACHED SHEET -
A33: TOTAL : | B33: =M26 -> 687 | C33: M. | D33: =M27 -> 3189 | E33: PCS. | F33: =M28 -> 10 | I33: PCS. | J33: KG. | K33: =M29 -> 500 | L33: =N29 -> SET. | M33: =M30 -> 25 | N33: ROLL. | O33: =SUM(O26:O32) -> 1220920
A36: ='[2]shipper master'!C63 -> " THESE GOODS WILL BE RETURN TO JAPAN | I36: " NO COMMER VALUE | M36: " NO COMMERCIAL VALUE
A37: ='[2]shipper master'!C64 -> AFTER MANUFACTURED AT VIET NAM " | I37: VALUE FOR CUSTOMS PURPOSE ONLY " | M37: VALUE FOR CUSTOMS PURPOSE ONLY "
D38: ='[2]shipper master'!C58 -> 0
A39: ='[2]shipper master'!C60 -> COUNTRY OF ORIGIN : JAPAN
A41: TOTAL CARTONS : | D41: 21CARTONS
A42: TOTAL GROSS WEIGHT : | D42: KGS

Sheet NARITA 
A2: - ATTACHED SHEET -
A4: C/NO. | B4: ART NO. | C4: COLOR | D4: DESCRIPTION OF GOODS | E4: Q'TY | F4: U/PRICE | H4: AMOUNT | I4: 佐川伝票・明細 | J4: 搬入日 | K4: 伝票NO | L4: 搬入内容 | M4: 数量 | N4: 箱数
B6: (H.S. CODE) | D6: =[3]invoice!B24 -> FABRIC & PARTS FOR WEAR & SAMPLE CLOTHES | G6: ='[1]shipper master'!C48 -> F.O.B. TOKYO IN YEN
D7: MADE IN JAPAN
A8: 1-2 | D8: STYLE:26S-PT02(25SY-16) | N8: 2
B9: YG1072 | C9: c/#25 GRAY | D9: KNIT FABRIC | E9: 10 | F9: M. | G9: 1370 | H9: =E9*G9 -> 13700
B10: KNIT FABRIC | C10: c/#5 BLACK | D10: COTTON100% | E10: 19 | F10: M. | G10: 1370 | H10: =E10*G10 -> 26030 | I10: 入庫NO.22077213 | J10: 11/6
B11: 丸編み パイル編 裏毛 後染め | D11: WIDTH:160CM (570ｇ/㎡ )
B12: 短繊維、プリント加工なし
A14: 3-6 | D14: STYLE:26S-SH01(25SY-28),26S-SH02(25SY-19) | N14: 4
B15: 012S0086110 | C15: c/#100 WHITE | D15: WOVEN FABRIC | E15: 174 | F15: M. | G15: 1110 | H15: =E15*G15 -> 193140 | J15: 11/18
B16: WOVEN FABRIC | C16: c/#099 BLACK | D16: COTTON100% | E16: 54 | F16: M. | G16: 1110 | H16: =E16*G16 -> 59940 | I16: 入庫NO.2207491
B17: 平織 先染め タイプライター | D17: WIDTH:145CM (145ｇ/㎡ )
B18: 短繊維、プリント加工なし
A20: 7-8 | D20: STYLE:26S-CS01(25SY-29) | N20: 2
B21: 027G0081935 | C21: c/#G01 GRAY | D21: KNIT FABRIC | E21: 41 | F21: M. | G21: 1020 | H21: =E21*G21 -> 41820
B22: KNIT FABRIC | D22: COTTON100% | I22: 入庫NO.22077572 | J22: 11/21
B23: 丸編みパイル編 裏毛 先染め | D23: WIDTH:180CM (227ｇ/㎡ )
B24: 短繊維、プリント加工なし
A26: 9 | D26: STYLE:cc26ss-22 | N26: 1
B27: 43887 | C27: c/#52 WHITE | D27: KNIT FABRIC | E27: 74 | F27: M. | G27: 880 | H27: =E27*G27 -> 65120
B28: KNIT FABRIC | D28: NYLON100% | I28: 入庫NO.22077600 | J28: 12/1
B29: チュール 後染め | D29: WIDTH:130CM (30ｇ/㎡ )
B30: 長繊維、プリント加工なし
A32: 10-11 | D32: STYLE:cc26ss-52,cc26ss-48,cc26ss-54 | J32: 12/1 | N32: 2
B33: used denim pants | C33: c/#BLUE | D33: WOVEN FABRIC | E33: 74 | F33: PCS. | G33: 1000 | H33: =E33*G33 -> 74000
B34: COTTON 100% | C34: c/#BLACK | E34: 23 | F34: PCS. | G34: 1000 | H34: =E34*G34 -> 23000
B35: 古着
B36: made in USA
D38: STYLE:cc26ss-22 | I38: 入庫NO.2207735
B39: used lace cloth | C39: c/#WHITE | D39: KNIT FABRIC | E39: 10 | F39: KG. | G39: 1000 | H39: =E39*G39 -> 10000
B40: COTTON 100%
B41: 古着
B42: made in JAPAN
A44: 12-14 | D44: STYLE: bd26-001/bd26-004 | N44: 3
B45: 5001-01 | C45: C/#191 WHITE | D45: KNIT FABRIC | E45: 93 | F45: PCS. | G45: 462 | H45: =E45*G45 -> 42966
B46: men's crew neck T-shirt | C46: C/#087 NAVY | D46: COTTON 100% | E46: 59 | F46: PCS. | G46: 462 | H46: =E46*G46 -> 27258 | I46: 入庫NO.22078120 | J46: 12/18
B47: KNIT FABRIC | C47: C/#165 BLACK | D47: made in CHINA | E47: 68 | F47: PCS. | G47: 462 | H47: =E47*G47 -> 31416
B48: 短繊維 天竺 テクスチャード加工無し | C48: c/#369 YELLOW | E48: 1 | F48: PCS. | G48: 462 | H48: =E48*G48 -> 462
A50: 15-17 | D50: STYLE: 26S-CS01,26S-JK01,26S-JK02,26S-JK03,26S-PT02,26S-PT03,26S-PT04,26S-PT05,26S-SH01,26S-SH02,26S-SH03,26S-SH04,26S-TE03 | N50: 3
...

Sheet NARITA (2)
A2: - ATTACHED SHEET -
A4: C/NO. | B4: ART NO. | C4: COLOR | D4: DESCRIPTION OF GOODS | E4: Q'TY | F4: U/PRICE | H4: AMOUNT | I4: 佐川伝票・明細 | J4: 搬入日 | K4: 伝票NO | L4: 搬入内容 | M4: 数量 | N4: 箱数
B6: (H.S. CODE) | D6: ='[4]NARITA '!D6 -> FABRIC & PARTS FOR WEAR & SAMPLE CLOTHES | G6: ='[5]shipper master'!C48 -> F.O.B. TOKYO IN YEN
D7: MADE IN JAPAN
A9: 19-21 | D9: STYLE：26S-PT01(25SY-17) | I9: 佐川 4529-7621-8295 | N9: 3
B10: 5RA C DA8 | D10: metal ZIPPER
D11: 19CM #560-12 #580-12 | E11: 24 | F11: PCS. | G11: 55 | H11: 1320
D12: 20CM #560-13 #580-13 | E12: 26 | F12: PCS. | G12: 57 | H12: 1482
B13: 3YGRDS C GSN8 | D13: metal ZIPPER | F13: PCS.
D14: 100CM #560-4 #580-4 | E14: 8 | F14: PCS. | G14: 315 | H14: 2520
D15: 102CM #560-8 #580-8 | E15: 16 | F15: PCS. | G15: 320 | H15: 5120
D16: 104CM #560-8 #580-8 | E16: 16 | F16: PCS. | G16: 325 | H16: 5200
D17: 106CM #560-5 #580-5 | E17: 10 | F17: PCS. | G17: 330 | H17: 3300
B18: 15BURR E 2779-2910 | C18: NSL | D18: BURR 素材：真鍮 | E18: 300 | F18: SET. | G18: 15 | H18: 4500
D19: STYLE：26S-PT02(25SY-16)
B20: 3YGRDS C GSN8 | D20: metal ZIPPER
D21: 19CM #560-5 #580-10 | E21: 15 | F21: PCS. | G21: 86 | H21: 1290
D22: 20CM #560-5 #580-10 | E22: 15 | F22: PCS. | G22: 88 | H22: 1320
B23: Ｂ204 | C23: Ｗ | D23: WAIST ELASTIC (30M) 素材：ポリエステル 芯：ポリウレタン | E23: 1 | F23: ROLL. | G23: 2700 | H23: 2700
D25: STYLE：26S-PT03(25SY-21)
B26: 5RA OP DA8 | D26: metal ZIPPER
D27: 74CM #580-4 #572-4 #061-2 | E27: 10 | F27: PCS. | G27: 146 | H27: 1460
D28: 77CM #580-12 #572-8 #061-2 | E28: 22 | F28: PCS. | G28: 150 | H28: 3300
D29: 80CM #580-18 #572-8 #061-2 | E29: 28 | F29: PCS. | G29: 153 | H29: 4284
B31: 5RA OP DA8 | D31: metal ZIPPER
D32: 66.5CM #580-4 #572-4 #061-2 | E32: 10 | F32: PCS. | G32: 138 | H32: 1380
D33: 68CM #580-12 #572-8 #061-2 | E33: 22 | F33: PCS. | G33: 139 | H33: 3058
D34: 69.5CM #580-18 #572-8 #061-2 | E34: 28 | F34: PCS. | G34: 140 | H34: 3920
B35: B204 | C35: Ｗ | D35: WAIST ELASTIC (30M) 素材：ポリエステル 芯：ポリウレタン | E35: 1 | F35: ROLL. | G35: 2700 | H35: 2700
B36: A400 | D36: (SV)CHIPD CORD 200CM 素材：アクリル 先端チップ素材：真鍮
D37: #31-34 #10-20 #6-6 | E37: 60 | F37: PCS. | G37: 295 | H37: 17700
B38: SIC3140 2.5MM | D38: ELASTIC CORD (50M) 素材：ポリエステル100% | J38: 12/22
D39: #50-1 #70-1 | E39: 2 | F39: ROLL. | G39: 2300 | H39: 4600
D40: #132 | E40: 4 | F40: M. | G40: 90 | H40: 360
B41: AST1018 | C41: 09 | D41: STOPPER 素材：ナイロン/ステンレス | E41: 60 | F41: PCS. | G41: 50 | H41: 3000
D42: STYLE：26S-PT05(25SY-39)
B43: 1000 | D43: COTTON 100% PIECE-DYED SLEEK 平織
D44: #3-19 #1-2-26 #5-8 | E44: 53 | F44: M. | G44: 550 | H44: 29150
B45: 3MA C DA | D45: metal ZIPPER 16CM
D46: #551-25 #580-35 #087-10 | E46: 70 | F46: PCS. | G46: 80 | H46: 5600
...

Sheet LABEL
A2: LABEL SHEET -
A4: C/NO. | B4: ART NO. | C4: DESCRIPTION OF GOODS | D4: 原産国
A5: 1-2 | C5: STYLE:26S-PT02(25SY-16)
B6: YG1072 | C6: KNIT FABRIC | D6: MADE IN JAPAN
B7: KNIT FABRIC | C7: COTTON100% | D7: SHUNYA CO., LTD.
B8: 丸編み パイル編 裏毛 後染め | C8: WIDTH:160CM (570ｇ/㎡ )
B9: 短繊維、プリント加工なし
A11: C/NO. | B11: ART NO. | C11: DESCRIPTION OF GOODS | D11: 原産国
A12: 3-6 | C12: STYLE:26S-SH01(25SY-28),26S-SH02(25SY-19)
B13: 012S0086110 | C13: WOVEN FABRIC | D13: MADE IN JAPAN
B14: WOVEN FABRIC | C14: COTTON100% | D14: SHUNYA CO., LTD.
B15: 平織 先染め タイプライター | C15: WIDTH:145CM (145ｇ/㎡ )
B16: 短繊維、プリント加工なし
A18: C/NO. | B18: ART NO. | C18: DESCRIPTION OF GOODS | D18: 原産国
A19: 7-8 | C19: STYLE:26S-CS01(25SY-29)
B20: 027G0081935 | C20: KNIT FABRIC | D20: MADE IN JAPAN
B21: KNIT FABRIC | C21: COTTON100% | D21: SHUNYA CO., LTD.
B22: 丸編みパイル編 裏毛 先染め | C22: WIDTH:180CM (227ｇ/㎡ )
B23: 短繊維、プリント加工なし
A25: C/NO. | B25: ART NO. | C25: DESCRIPTION OF GOODS | D25: 原産国
A26: 9 | C26: STYLE:cc26ss-22
B27: 43887 | C27: KNIT FABRIC | D27: MADE IN JAPAN
B28: KNIT FABRIC | C28: NYLON100% | D28: SHUNYA CO., LTD.
B29: チュール 後染め | C29: WIDTH:130CM (30ｇ/㎡ )
B30: 長繊維、プリント加工なし
A32: C/NO. | B32: ART NO. | C32: DESCRIPTION OF GOODS | D32: 原産国
A33: 10-11 | C33: STYLE:cc26ss-52,cc26ss-48,cc26ss-54
B34: used denim pants | C34: WOVEN FABRIC
B35: COTTON 100%
B36: 古着
B37: made in USA | D37: MADE IN U.S.A
D38: MADE IN JAPAN
C39: STYLE:cc26ss-22 | D39: SHUNYA CO., LTD.
B40: used lace cloth | C40: KNIT FABRIC
B41: COTTON 100%
B42: 古着
B43: made in JAPAN
A45: C/NO. | B45: ART NO. | C45: DESCRIPTION OF GOODS | D45: 原産国
A46: 12-14 | C46: STYLE: bd26-001/bd26-004
B47: 5001-01 | C47: KNIT FABRIC | D47: MADE IN CHINA
...
