Workbook
Name pricetable: #REF!
Name pricetable: #REF!
Name pricetable: #REF!
Name pricetable: #REF!
Name pricetable: #REF!

Sheet shipper master
A1: 1 | B1: S/CODE | C1: SHIPPER NAME
A2: =A1+1 -> 2 | B2: SHIPPER | C2: SHUNYA CO., LTD.
A3: =A2+1 -> 3 | B3: SHIPPER ADDRESS 1 | C3: KENSHIN BLDG., 1F, 1-22-10 DOUGENZAKA,
A4: =A3+1 -> 4 | B4: SHIPPER ADDRESS 2 | C4: SHIBUYA-KU 150-0043
A5: =A4+1 -> 5 | B5: SHIPPER ADDRESS 3 | C5: TEL : +81(0)3-5459-1177
A6: =A5+1 -> 6 | B6: TEL
A7: =A6+1 -> 7 | B7: FAX
A8: =A7+1 -> 8 | B8: ATTN OR VAT NO.
A9: =A8+1 -> 9 | B9: BUYER | C9: VIVAN GARMENTS VIET NAM COMPANY LIMITED
A10: =A9+1 -> 10 | B10: BUYER ADDRESS1 | C10: D17 Street , Sai Gon South Residential Area
A11: =A10+1 -> 11 | B11: BUYER ADDRESS2 | C11: Hamlet 3 , Long Hau Commune , Can Giuoc District,
A12: =A11+1 -> 12 | B12: BUYER ADDRESS3 | C12: Long An Province , VietNam
A13: =A12+1 -> 13 | B13: TEL/FAX | C13: TEL : ( 084 ) 097 22 00 798 ATTN : MR. TUAN
A14: =A13+1 -> 14 | B14: ATTN
A15: =A14+1 -> 15 | B15: CONSIGNEE : | C15: - SAME AS BUYER -
A16: =A15+1 -> 16 | B16: CONSIGNEE ADDRESS1
A17: =A16+1 -> 17 | B17: CONSIGNEE ADDRESS2
A18: =A17+1 -> 18 | B18: CONSIGNEE ADDRESS3
A19: =A18+1 -> 19 | B19: TEL
A20: =A19+1 -> 20 | B20: FAX
A21: =A20+1 -> 21 | B21: ATTN | C21: NO COMMERCIAL
A22: =A21+1 -> 22 | B22: PAYMENT 1
A23: =A22+1 -> 23 | B23: PAYMENT 2
A24: =A23+1 -> 24 | B24: SHIPPER PER | C24: AIRCRAFT
A25: =A24+1 -> 25 | B25: INVOICE DATE | C25: Mar, 12 2026
A26: =A25+1 -> 26 | B26: INVOICE NO. | C26: SY-8000312-VT-DD-01
A27: =A26+1 -> 27 | B27: CONTRACT NO. | C27: =C26 -> SY-8000312-VT-DD-01
A28: =A27+1 -> 28 | B28: CONTRACT DATE
A29: =A28+1 -> 29 | B29: ORDER DATE
A30: =A29+1 -> 30 | B30: ORDER NO.
A31: =A30+1 -> 31 | B31: L/C DATE
A32: =A31+1 -> 32 | B32: FROM | C32: TOKYO, JAPAN
A33: =A32+1 -> 33 | B33: TO | C33: HOCHIMINH-CITY, VIETNAM
A34: =A33+1 -> 34 | B34: VIA
A35: =A34+1 -> 35 | B35: SHIPPING TERMS | C35: F.O.B. TOKYO IN YEN
A36: =A35+1 -> 36 | B36: TITTLE 1 | C36: FABRIC & PARTS FOR WEAR & SAMPLE CLOTHES
A37: =A36+1 -> 37 | B37: TITTLE 2
A38: =A37+1 -> 38 | B38: ATTACHE | C38: - DETAILS AS PER ATTACHED SHEET -
A39: =A38+1 -> 39 | B39: C/NO.
A40: =A39+1 -> 40 | B40: STYLE NO.
...

Sheet case mark 
A2: ='shipper master'!C26 -> SY-8000312-VT-DD-01 | I2: ='shipper master'!C26 -> SY-8000312-VT-DD-01
A3: ='[1]shipper master'!C50 -> VIVAN GARMENTS VIET NAM | I3: ='[1]shipper master'!C50 -> VIVAN GARMENTS VIET NAM
A4: ='[1]shipper master'!C51 -> COMPANY LIMITED | I4: ='[1]shipper master'!C51 -> COMPANY LIMITED
A5: ='[1]shipper master'!C52 -> HOCHIMINH-CITY, VIETNAM | I5: ='[1]shipper master'!C52 -> HOCHIMINH-CITY, VIETNAM
A6: C/NO. | C6: 1 | I6: C/NO. | K6: 2
A7: ='[1]shipper master'!C54 -> MADE IN JAPAN | I7: ='[1]shipper master'!C54 -> MADE IN JAPAN
A13: ='shipper master'!C26 -> SY-8000312-VT-DD-01 | I13: ='shipper master'!C26 -> SY-8000312-VT-DD-01
A14: ='[1]shipper master'!C50 -> VIVAN GARMENTS VIET NAM | I14: ='[1]shipper master'!C50 -> VIVAN GARMENTS VIET NAM
A15: ='[1]shipper master'!C51 -> COMPANY LIMITED | I15: ='[1]shipper master'!C51 -> COMPANY LIMITED
A16: ='[1]shipper master'!C52 -> HOCHIMINH-CITY, VIETNAM | I16: ='[1]shipper master'!C52 -> HOCHIMINH-CITY, VIETNAM
A17: C/NO. | C17: 3 | I17: C/NO. | K17: 4
A18: ='[1]shipper master'!C54 -> MADE IN JAPAN | I18: ='[1]shipper master'!C54 -> MADE IN JAPAN

Sheet invoice
A1: INVOICE
A2: ='[2]shipper master'!C2 -> SHUNYA CO., LTD.
A3: ='[2]shipper master'!C3 -> KENSHIN BLDG., 1F, 1-22-10 DOUGENZAKA,
A4: ='[2]shipper master'!C4 -> SHIBUYA-KU 150-0043 | N4: ='[2]shipper master'!C6 -> 0
A5: ='[2]shipper master'!C5 -> TEL : +81(0)3-5459-1177 | N5: ='[2]shipper master'!C7 -> 0
A6: IMPORTER | F6: INVOICE NO. | N6: CASE MARK
A7: ='[2]shipper master'!C9 -> VIVAN GARMENTS VIET NAM COMPANY LIMITED | F7: ='shipper master'!C26 -> SY-8000312-VT-DD-01
A8: ='[2]shipper master'!C10 -> D17 Street , Sai Gon South Residential Area | F8: INVOICE DATE | N8: ='shipper master'!C26 -> SY-8000312-VT-DD-01
A9: ='[2]shipper master'!C11 -> Hamlet 3 , Long Hau Commune , Can Giuoc District, | F9: ='shipper master'!C25 -> Mar, 12 2026 | N9: ='[1]shipper master'!C50 -> VIVAN GARMENTS VIET NAM
A10: ='[2]shipper master'!C12 -> Long An Province , VietNam | F10: CONTRACT NO. | N10: ='[1]shipper master'!C51 -> COMPANY LIMITED
A11: ='[2]shipper master'!C13 -> TEL : ( 084 ) 097 22 00 798 ATTN : MR. TUAN | F11: ='shipper master'!C26 -> SY-8000312-VT-DD-01 | N11: ='[1]shipper master'!C52 -> HOCHIMINH-CITY, VIETNAM
A12: CONSIGNEE | F12: ORDER NO. | N12: C/NO. 1-3
A13: ='[2]shipper master'!C15 -> - SAME AS BUYER - | F13: ='[2]shipper master'!C30 -> 0 | N13: MADE IN JAPAN
A14: ='[2]shipper master'!C16 -> 0 | F14: ORDER DATE | N14: MADE IN CHINA
A15: ='[2]shipper master'!C17 -> 0 | F15: ='[2]shipper master'!C29 -> 0
A16: ='[2]shipper master'!C18 -> 0 | F16: L/C NO.
A17: ='[2]shipper master'!C19 -> 0
A18: PAYMENT METHOD
A19: ='[2]shipper master'!C21 -> NO COMMERCIAL
A20: SHIPPED PER | D20: FROM | F20: TO | N20: VIA
A21: ='[2]shipper master'!C24 -> AIRCRAFT | D21: ='[2]shipper master'!C32 -> TOKYO, JAPAN | G21: ='[2]shipper master'!C33 -> HOCHIMINH-CITY, VIETNAM
A22: C/NO. | B22: ART NO. | D22: DESCRIPTION OF GOODS | E22: COLOR | H22: SIZE | M22: Q'TY | N22: U/PRICE | O22: AMOUNT
B24: ='[2]shipper master'!C36 -> FABRIC & PARTS FOR WEAR & SAMPLE CLOTHES | N24: ='[2]shipper master'!C48 -> F.O.B. TOKYO IN YEN
B26: ='[2]shipper master'!C37 -> 0 | M26: ='NARITA '!E20 -> 0 | N26: M. | O26: ='NARITA '!H20 -> 0
M27: ='NARITA '!E21 -> 481 | N27: PCS. | O27: ='NARITA '!H21 -> 76978
B31: ='[2]shipper master'!C38 -> - DETAILS AS PER ATTACHED SHEET -
A33: TOTAL : | B33: =M26 -> 0 | C33: M. | D33: =M27 -> 481 | E33: PCS. | F33: =M28 -> 0 | I33: PCS. | J33: KG. | K33: =M29 -> 0 | L33: =N29 -> 0 | M33: =M30 -> 0 | N33: ROLL. | O33: =SUM(O26:O32) -> 76978
A36: ='[2]shipper master'!C63 -> " THESE GOODS WILL BE RETURN TO JAPAN | I36: " NO COMMER VALUE | M36: " NO COMMERCIAL VALUE
A37: ='[2]shipper master'!C64 -> AFTER MANUFACTURED AT VIET NAM " | I37: VALUE FOR CUSTOMS PURPOSE ONLY " | M37: VALUE FOR CUSTOMS PURPOSE ONLY "
D38: ='[2]shipper master'!C58 -> 0
A39: ='[2]shipper master'!C60 -> COUNTRY OF ORIGIN : JAPAN
A41: TOTAL CARTONS : | D41: 3CARTONS
A42: TOTAL GROSS WEIGHT : | D42: KGS

Sheet NARITA 
A2: - ATTACHED SHEET -
A4: C/NO. | B4: ART NO. | C4: COLOR | D4: DESCRIPTION OF GOODS | E4: Q'TY | F4: U/PRICE | H4: AMOUNT | I4: 佐川伝票・明細 | J4: 搬入日 | K4: 伝票NO | L4: 搬入内容 | M4: 数量 | N4: 箱数
B6: (H.S. CODE) | D6: =[3]invoice!B24 -> FABRIC & PARTS FOR WEAR & SAMPLE CLOTHES | G6: ='[1]shipper master'!C48 -> F.O.B. TOKYO IN YEN
D7: MADE IN JAPAN
A8: 1-2 | D8: STYLE: bd26-005 | N8: 2
B9: 5001-01 | C9: C/#001 WHITE | D9: KNIT FABRIC | E9: 46 | F9: PCS. | G9: 462 | H9: =E9*G9 -> 21252
B10: men's crew neck T-shirt | C10: C/#086 NAVY | D10: COTTON 100% | E10: 36 | F10: PCS. | G10: 462 | H10: =E10*G10 -> 16632 | I10: 入庫NO.22079579 | J10: 3/4
B11: KNIT FABRIC | C11: C/#369 YELLOW | D11: made in CHINA | E11: 37 | F11: PCS. | G11: 462 | H11: =E11*G11 -> 17094
B12: 短繊維 天竺 テクスチャード加工無し
A14: 3 | D14: STYLE: bd26-005 | N14: 1
B15: bardog woven name | D15: bardog woven name | E15: 120 | F15: PCS. | G15: 50 | H15: =E15*G15 -> 6000
B16: badog paper hang tag | D16: badog paper hang tag | E16: 240 | F16: PCS. | G16: 50 | H16: =E16*G16 -> 12000 | I16: 入庫NO.22079798 | J16: 12/9
B17: men's T-shirt SAMPLE CLOTHES | D17: bd26-005 sample | E17: 2 | F17: PCS. | G17: 2000 | H17: =E17*G17 -> 4000
E20: =SUMIF($F$8:$F$19,"M.",$E$8:$E$19) -> 0 | F20: M. | H20: =SUMIF($F$8:$F$19,"M.",$H$8:$H$19) -> 0
E21: =SUMIF($F$8:$F$19,"PCS.",$E$8:$E$19) -> 481 | F21: PCS. | H21: =SUMIF($F$8:$F$19,"PCS.",$H$8:$H$19) -> 76978
B22: TOTAL : | C22: 3CARTONS | G22: TOTAL | H22: =SUM(H8:H19) -> 76978

Sheet サンプル製品カタログ
D1: ITEM
B2: NAME | C2: color | E2: lady's or men's | F2: WOVEN or KNIT | G2: picture | H2: Composition | I2: packingNo.
B3: men's T-shirt SAMPLE CLOTHES | C3: C/#WHITE c/#YELLOW | D3: bd26-005 sample | E3: men's | F3: KNITFABRIC | H3: COTTON 100% | I3: 3

Sheet LABEL
A2: LABEL SHEET -
A4: C/NO. | B4: ART NO. | C4: DESCRIPTION OF GOODS | D4: 原産国
A5: 1-2 | C5: STYLE: bd26-005
B6: 5001-01 | C6: KNIT FABRIC | D6: MADE IN CHINA
B7: men's crew neck T-shirt | C7: COTTON 100% | D7: SHUNYA CO., LTD.
B8: KNIT FABRIC | C8: made in CHINA
B9: 短繊維 天竺 テクスチャード加工無し
A11: C/NO. | B11: ART NO. | C11: DESCRIPTION OF GOODS | D11: 原産国
A12: 3 | C12: STYLE: bd26-005
B13: bardog woven name | C13: bardog woven name | D13: MADE IN JAPAN
B14: badog paper hang tag | C14: badog paper hang tag | D14: SHUNYA CO., LTD.
B15: men's T-shirt SAMPLE CLOTHES | C15: bd26-005 sample
