Workbook
Name pricetable: #REF!
Name pricetable: #REF!
Name pricetable: #REF!
Name pricetable: #REF!
Name pricetable: #REF!

Sheet shipper master
A1: 1 | B1: S/CODE | C1: SHIPPER NAME
A2: =A1+1 -> 2 | B2: SHIPPER | C2: SHUNYA CO., LTD.
A3: =A2+1 -> 3 | B3: SHIPPER ADDRESS 1 | C3: KENSHIN BLDG., 1F, 1-22-10 DOUGENZAKA,
A4: =A3+1 -> 4 | B4: SHIPPER ADDRESS 2 | C4: SHIBUYA-KU 150-0043
A5: =A4+1 -> 5 | B5: SHIPPER ADDRESS 3 | C5: TEL : +81(0)3-5459-1177
A6: =A5+1 -> 6 | B6: TEL
A7: =A6+1 -> 7 | B7: FAX
A8: =A7+1 -> 8 | B8: ATTN OR VAT NO.
A9: =A8+1 -> 9 | B9: BUYER | C9: VIVAN GARMENTS VIET NAM COMPANY LIMITED
A10: =A9+1 -> 10 | B10: BUYER ADDRESS1 | C10: D17 Street , Sai Gon South Residential Area
A11: =A10+1 -> 11 | B11: BUYER ADDRESS2 | C11: Hamlet 3 , Long Hau Commune , Can Giuoc District,
A12: =A11+1 -> 12 | B12: BUYER ADDRESS3 | C12: Long An Province , VietNam
A13: =A12+1 -> 13 | B13: TEL/FAX | C13: TEL : ( 084 ) 097 22 00 798 ATTN : MR. TUAN
A14: =A13+1 -> 14 | B14: ATTN
A15: =A14+1 -> 15 | B15: CONSIGNEE : | C15: - SAME AS BUYER -
A16: =A15+1 -> 16 | B16: CONSIGNEE ADDRESS1
A17: =A16+1 -> 17 | B17: CONSIGNEE ADDRESS2
A18: =A17+1 -> 18 | B18: CONSIGNEE ADDRESS3
A19: =A18+1 -> 19 | B19: TEL
A20: =A19+1 -> 20 | B20: FAX
A21: =A20+1 -> 21 | B21: ATTN | C21: NO COMMERCIAL
A22: =A21+1 -> 22 | B22: PAYMENT 1
A23: =A22+1 -> 23 | B23: PAYMENT 2
A24: =A23+1 -> 24 | B24: SHIPPER PER | C24: AIRCRAFT
A25: =A24+1 -> 25 | B25: INVOICE DATE | C25: JUN, 4 2026
A26: =A25+1 -> 26 | B26: INVOICE NO. | C26: SY-8100604VT-DD-01
A27: =A26+1 -> 27 | B27: CONTRACT NO. | C27: =C26 -> SY-8100604VT-DD-01
A28: =A27+1 -> 28 | B28: CONTRACT DATE
A29: =A28+1 -> 29 | B29: ORDER DATE
A30: =A29+1 -> 30 | B30: ORDER NO.
A31: =A30+1 -> 31 | B31: L/C DATE
A32: =A31+1 -> 32 | B32: FROM | C32: TOKYO, JAPAN
A33: =A32+1 -> 33 | B33: TO | C33: HOCHIMINH-CITY, VIETNAM
A34: =A33+1 -> 34 | B34: VIA
A35: =A34+1 -> 35 | B35: SHIPPING TERMS | C35: F.O.B. TOKYO IN YEN
A36: =A35+1 -> 36 | B36: TITTLE 1 | C36: FABRIC & PARTS FOR WEAR & SAMPLE CLOTHES
A37: =A36+1 -> 37 | B37: TITTLE 2
A38: =A37+1 -> 38 | B38: ATTACHE | C38: - DETAILS AS PER ATTACHED SHEET -
A39: =A38+1 -> 39 | B39: C/NO.
A40: =A39+1 -> 40 | B40: STYLE NO.
...

Sheet case mark 
A2: ='shipper master'!C26 -> SY-8100604VT-DD-01 | I2: ='shipper master'!C26 -> SY-8100604VT-DD-01
A3: ='[2]shipper master'!C50 -> VIVAN GARMENTS VIET NAM | I3: ='[2]shipper master'!C50 -> VIVAN GARMENTS VIET NAM
A4: ='[2]shipper master'!C51 -> COMPANY LIMITED | I4: ='[2]shipper master'!C51 -> COMPANY LIMITED
A5: ='[2]shipper master'!C52 -> HOCHIMINH-CITY, VIETNAM | I5: ='[2]shipper master'!C52 -> HOCHIMINH-CITY, VIETNAM
A6: C/NO. | C6: 1 | I6: C/NO. | K6: 2
A7: ='[2]shipper master'!C54 -> MADE IN JAPAN | I7: ='[2]shipper master'!C54 -> MADE IN JAPAN
A13: ='shipper master'!C26 -> SY-8100604VT-DD-01 | I13: ='shipper master'!C26 -> SY-8100604VT-DD-01
A14: ='[2]shipper master'!C50 -> VIVAN GARMENTS VIET NAM | I14: ='[2]shipper master'!C50 -> VIVAN GARMENTS VIET NAM
A15: ='[2]shipper master'!C51 -> COMPANY LIMITED | I15: ='[2]shipper master'!C51 -> COMPANY LIMITED
A16: ='[2]shipper master'!C52 -> HOCHIMINH-CITY, VIETNAM | I16: ='[2]shipper master'!C52 -> HOCHIMINH-CITY, VIETNAM
A17: C/NO. | C17: 3 | I17: C/NO. | K17: 4
A18: ='[2]shipper master'!C54 -> MADE IN JAPAN | I18: ='[2]shipper master'!C54 -> MADE IN JAPAN

Sheet invoice
A1: INVOICE
A2: ='[3]shipper master'!C2 -> SHUNYA CO., LTD.
A3: ='[3]shipper master'!C3 -> KENSHIN BLDG., 1F, 1-22-10 DOUGENZAKA,
A4: ='[3]shipper master'!C4 -> SHIBUYA-KU 150-0043 | N4: ='[3]shipper master'!C6 -> 0
A5: ='[3]shipper master'!C5 -> TEL : +81(0)3-5459-1177 | N5: ='[3]shipper master'!C7 -> 0
A6: IMPORTER | F6: INVOICE NO. | N6: CASE MARK
A7: ='[3]shipper master'!C9 -> VIVAN GARMENTS VIET NAM COMPANY LIMITED | F7: ='shipper master'!C26 -> SY-8100604VT-DD-01
A8: ='[3]shipper master'!C10 -> D17 Street , Sai Gon South Residential Area | F8: INVOICE DATE | N8: =F7 -> SY-8100604VT-DD-01
A9: ='[3]shipper master'!C11 -> Hamlet 3 , Long Hau Commune , Can Giuoc District, | F9: ='shipper master'!C25 -> JUN, 4 2026 | N9: VIVAN GARMENTS VIET NAM
A10: ='[3]shipper master'!C12 -> Long An Province , VietNam | F10: CONTRACT NO. | N10: COMPANY LIMITED
A11: ='[3]shipper master'!C13 -> TEL : ( 084 ) 097 22 00 798 ATTN : MR. TUAN | F11: ='shipper master'!C26 -> SY-8100604VT-DD-01 | N11: ='[2]shipper master'!C52 -> HOCHIMINH-CITY, VIETNAM
A12: CONSIGNEE | F12: ORDER NO. | N12: C/NO. 1-10
A13: ='[3]shipper master'!C15 -> - SAME AS BUYER - | F13: ='[3]shipper master'!C30 -> 0 | N13: MADE IN JAPAN
A14: ='[3]shipper master'!C16 -> 0 | F14: ORDER DATE
A15: ='[3]shipper master'!C17 -> 0 | F15: ='[3]shipper master'!C29 -> 0
A16: ='[3]shipper master'!C18 -> 0 | F16: L/C NO.
A17: ='[3]shipper master'!C19 -> 0
A18: PAYMENT METHOD
A19: ='[3]shipper master'!C21 -> NO COMMERCIAL
A20: SHIPPED PER | D20: FROM | F20: TO | N20: VIA
A21: ='[3]shipper master'!C24 -> AIRCRAFT | D21: ='[3]shipper master'!C32 -> TOKYO, JAPAN | G21: ='[3]shipper master'!C33 -> HOCHIMINH-CITY, VIETNAM
A22: C/NO. | B22: ART NO. | D22: DESCRIPTION OF GOODS | E22: COLOR | H22: SIZE | M22: Q'TY | N22: U/PRICE | O22: AMOUNT
B24: ='[3]shipper master'!C36 -> FABRIC & PARTS FOR WEAR & SAMPLE CLOTHES | N24: ='[3]shipper master'!C48 -> F.O.B. TOKYO IN YEN
B26: - DETAILS AS PER ATTACHED SHEET - | M26: =SUM(ATTACHED!E116) -> 296.5 | N26: M. | O26: =SUM(ATTACHED!H116) -> 120205
M27: =SUM(ATTACHED!E117) -> 3426 | N27: PCS. | O27: =SUM(ATTACHED!H117) -> 372754
M28: =ATTACHED!E118 -> 0 | O28: =ATTACHED!H118 -> 0
B31: TOTAL : | E31: =M26 -> 296.5 | J31: M. | K31: =K29 -> 0 | L31: =M27 -> 3426 | M31: PCS. | O31: =SUM(O26:O30) -> 492959
A34: ='[3]shipper master'!C63 -> " THESE GOODS WILL BE RETURN TO JAPAN | I34: " NO COMMER VALUE | M34: " NO COMMERCIAL VALUE
A35: ='[3]shipper master'!C64 -> AFTER MANUFACTURED AT VIET NAM " | I35: VALUE FOR CUSTOMS PURPOSE ONLY " | M35: VALUE FOR CUSTOMS PURPOSE ONLY "
D36: ='[3]shipper master'!C58 -> 0
A37: ='shipper master'!C60 -> COUNTRY OF ORIGIN : JAPAN
A39: TOTAL CARTONS : | D39: 10 CARTONS
A40: TOTAL GROSS WEIGHT : | D40: KGS

Sheet ATTACHED
A2: - ATTACHED SHEET -
A4: C/NO. | B4: ART NO. | C4: COLOR | D4: DESCRIPTION OF GOODS | E4: Q'TY | F4: U/PRICE | H4: AMOUNT | I4: 佐川伝票・明細 | J4: 搬入日 | K4: 伝票NO | L4: 搬入内容 | M4: 数量 | N4: 箱数
B5: (H.S. CODE) | D5: =[1]invoice!B24 -> FABRIC & PARTS FOR WEAR & SAMPLE CLOTHES | F5: ='[2]shipper master'!C48 -> F.O.B. TOKYO IN YEN
D6: MADE IN JAPAN
A7: 1-3 | D7: STYLE:26SY-11 | N7: 3
B8: 11487 | C8: C/#801 ベビーピンク | D8: WOVEN FABRIC | E8: 52 | F8: M. | G8: 390 | H8: =E8*G8 -> 20280 | I8: 入庫NO.22081274 | J8: 5/27
B9: WOVEN FABRIC | C9: C/#503 スカイブルー | D9: COTTON 100% | E9: 52 | F9: M. | G9: 390 | H9: =E9*G9 -> 20280
B10: 平織 ツイル 後染め | C10: C/#301 イエロー | D10: WIDTH:110CM (155ｇ/㎡ ) | E10: 53 | F10: M. | G10: 390 | H10: =E10*G10 -> 20670
B11: 短繊維 プリント加工なし
A13: 4-5 | D13: STYLE:bd26-009 | N13: 2
B14: 5001-01 | C14: C/#001 WHITE | D14: KNIT FABRIC | E14: 44 | F14: PCS. | G14: 672 | H14: =E14*G14 -> 29568 | I14: 入庫NO.22081349 | J14: 5/29
B15: men's crew neck T-shirt | C15: C/#165 BLACK | D15: COTTON 100% | E15: 32 | F15: PCS. | G15: 747 | H15: =E15*G15 -> 23904
B16: KNIT FABRIC | C16: C/#086 NAVY | D16: MADE IN CHINA | E16: 29 | F16: PCS. | G16: 747 | H16: =E16*G16 -> 21663
B17: 短繊維 天竺 テクスチャード加工無し
A19: 6-7 | D19: STYLE:bd26-008 | N19: 2
B20: 4488-01 | C20: C/#002 BLACK | D20: KNIT FABRIC | E20: 35 | F20: PCS. | G20: 1867 | H20: =E20*G20 -> 65345 | I20: 入庫NO.22081349 | J20: 5/29
B21: men's cardigan | C21: C/#005 GRAY | D21: COTTON 100% | E21: 32 | F21: PCS. | G21: 1867 | H21: =E21*G21 -> 59744
B22: KNIT FABRIC | C22: C/#086 NAVY | D22: MADE IN CHINA | E22: 20 | F22: PCS. | G22: 1867 | H22: =E22*G22 -> 37340
B23: 短繊維 天竺 テクスチャード加工無し
A25: 8 | D25: STYLE:25I-CS02 | I25: 入庫NO.2208448 | J25: 6/4 | N25: 1
B26: YG1001 | C26: C/#1 WHITE | D26: KNIT FABRIC | E26: 1 | F26: M. | G26: 1210 | H26: =E26*G26 -> 1210
B27: KNIT FABRIC | D27: COTTON 100%
B28: 丸編み フレンチパイル編み 後染め | D28: WIDTH:180CM (590ｇ/㎡ )
B29: 短繊維、プリント加工なし
D30: STYLE:25I-CS02
B31: YG1002 | C31: C/#1 WHITE | D31: KNIT FABRIC | E31: 0.5 | F31: M. | G31: 990 | H31: =E31*G31 -> 495
B32: KNIT FABRIC | D32: COTTON 95% PU 5%
B33: 丸編み リブ編み 後染め | D33: WIDTH:42WCM (300ｇ/㎡ )
B34: 短繊維、プリント加工なし
D35: STYLE:26A-AC09
B36: GN-13-16 | C36: C/#NICKEL | D36: Metal O-Ring | E36: 100 | F36: PCS. | G36: 170 | H36: =E36*G36 -> 17000
B37: 材質：メタル | D37: 16mm
D39: STYLE:26A-PT-01,26A-PT-02,26A-SH-01,26A-SH-02,26A-JK-01,26A-JK-02,26A-AC-04
B40: PRESTIGE Product bags | C40: c/#CLEAR | D40: PRESTIGE Product bags | E40: 399 | F40: PCS. | G40: 100 | H40: =E40*G40 -> 39900
B41: 材質：ポリエチレン
B42: PRESTIGE Product hang tag | D42: PRESTIGE Product hang tag | E42: 399 | F42: PCS. | G42: 50 | H42: =E42*G42 -> 19950
B44: 26SY-07(26A-SH01) sample | D44: men's cotton shirt SAMPLE CLOTHES | E44: 1 | F44: PCS. | G44: 2000 | H44: =E44*G44 -> 2000
B45: 26SY-06(26A-JK04) sample | D45: men's Velour jacket SAMPLE CLOTHES | E45: 1 | F45: PCS. | G45: 2000 | H45: =E45*G45 -> 2000
A47: 9-10 | D47: EN-22SY-66 | I47: 入庫NO.2208447 | N47: 2
B48: SB17 | C48: C/#BK | D48: BUTTONS 13MM | E48: 246 | F48: PCS. | G48: 18 | H48: =E48*G48 -> 4428
...

Sheet サンプル製品カタログ
D1: ITEM
B2: NAME | C2: color | E2: lady's or men's | F2: WOVEN or KNIT | G2: picture | H2: Composition | I2: packingNo.
B3: men's cotton shirt SAMPLE CLOTHES | C3: BLUE | D3: 26SY-07(26A-SH01) sample | E3: men's | F3: WOVEN | H3: COTTON 100% | I3: 8
B4: men's Velour jacket SAMPLE CLOTHES | C4: BLACK | D4: 26SY-06(26A-JK04) sample | E4: men's | F4: WOVEN | H4: COTTON 70% POLYESTER 30%

Sheet LABEL
A2: LABEL SHEET -
A4: C/NO. | B4: ART NO. | C4: DESCRIPTION OF GOODS | D4: 原産国
A5: 1-3 | C5: STYLE:26SY-11
B6: 11487 | C6: WOVEN FABRIC | D6: MADE IN JAPAN SHUNYA CO., LTD.
B7: WOVEN FABRIC | C7: COTTON 100%
B8: 平織 ツイル 後染め | C8: WIDTH:110CM (155ｇ/㎡ )
B9: 短繊維 プリント加工なし
A11: C/NO. | B11: ART NO. | C11: DESCRIPTION OF GOODS | D11: 原産国
A12: 4-5 | C12: STYLE:bd26-009
B13: 5001-01 | C13: KNIT FABRIC | D13: MADE IN JAPAN SHUNYA CO., LTD.
B14: men's crew neck T-shirt | C14: COTTON 100%
B15: KNIT FABRIC
B16: 短繊維 天竺 テクスチャード加工無し
A18: C/NO. | B18: ART NO. | C18: DESCRIPTION OF GOODS | D18: 原産国
A19: 6-7 | C19: STYLE:bd26-008
B20: 4488-01 | C20: KNIT FABRIC | D20: MADE IN JAPAN SHUNYA CO., LTD.
B21: men's cardigan | C21: COTTON 100%
B22: KNIT FABRIC
B23: 短繊維 天竺 テクスチャード加工無し
A25: C/NO. | B25: ART NO. | C25: DESCRIPTION OF GOODS | D25: 原産国
A26: 8 | C26: STYLE:25I-CS02
B27: YG1001 | C27: KNIT FABRIC | D27: MADE IN JAPAN SHUNYA CO., LTD.
B28: KNIT FABRIC | C28: COTTON 100%
B29: 丸編み フレンチパイル編み 後染め | C29: WIDTH:180CM (590ｇ/㎡ )
B30: 短繊維、プリント加工なし
A32: C/NO. | B32: ART NO. | C32: DESCRIPTION OF GOODS | D32: 原産国
A33: 8 | C33: STYLE:25I-CS02
B34: YG1002 | C34: KNIT FABRIC | D34: MADE IN JAPAN SHUNYA CO., LTD.
B35: KNIT FABRIC | C35: COTTON 95% PU 5%
B36: 丸編み リブ編み 後染め | C36: WIDTH:42WCM (300ｇ/㎡ )
B37: 短繊維、プリント加工なし
A39: C/NO. | B39: ART NO. | C39: DESCRIPTION OF GOODS | D39: 原産国
A40: 8 | C40: STYLE:26A-AC09
B41: GN-13-16 | C41: Metal O-Ring | D41: MADE IN JAPAN SHUNYA CO., LTD.
B42: 材質：メタル | C42: 16mm
A46: C/NO. | B46: ART NO. | C46: DESCRIPTION OF GOODS | D46: 原産国
A47: 8 | C47: STYLE:26A-PT-01,26A-PT-02,26A-SH-01,26A-SH-02,26A-JK-01,26A-JK-02,26A-AC-04
B48: PRESTIGE Product bags | C48: PRESTIGE Product bags | D48: MADE IN JAPAN SHUNYA CO., LTD.
B49: PRESTIGE Product hang tag | C49: PRESTIGE Product hang tag
A53: C/NO. | B53: ART NO. | C53: DESCRIPTION OF GOODS | D53: 原産国
...
