Workbook
Name Excel_BuiltIn_Print_Area: 'サイズ表(PANTS)'!$A$1:$W$41
Name Excel_BuiltIn_Print_Area: '縫製仕様書(PANTS)'!$A$1:$AL$41
Name Excel_BuiltIn_Print_Area: '縫製仕様書 '!$A$1:$AP$45

Sheet 縫製仕様書 
F2: 御中 | J2: 縫製仕様書
B3: 担当者： | F3: 様
B4: 気付： | F4: 様分
B5: ブランド | F5: 品名 | G5: パンツ | J5: 製品NO | U5: 型紙枚数 | Z5: 担当 | AF5: 数量 | AJ5: サンプル・量産
B6: 亀井造園 | F6: パターンNO | G6: EN-22SY-65-量産 | J6: 仮品番 | U6: 22PT | AF6: 納期 | AJ6: 職出し
Z7: 芯使用箇所 | AF7: PM | AJ7: G
Z8: 前PKフラップ 後PKフラップ 見返し 持出し ウエストベルト | AF8: 生地品番 | AJ8: 裁断 | AL8: サイズ
AF9: 仕入先 | AL9: S | AM9: M | AN9: L | AO9: XL | AP9: 計
AF10: A | AH10: 黒 | AK10: A | AL10: 10 | AM10: 5 | AN10: 15 | AO10: 10 | AP10: =SUM(AL10:AO10) -> 40
AF11: B | AK11: B | AP11: =SUM(AL11:AO11) -> 0
AF12: C | AK12: C | AP12: =SUM(AL12:AO12) -> 0
AF13: D | AK13: D | AP13: =SUM(AL13:AO13) -> 0
AF14: 巾×巻M数
AF15: 混率
W16: 縫製注意点 | AF16: ネーム位置 | AH16: なし
AF17: 洗濯ネーム位置 | AH17: 左脇 ベルト付け～15㎝
AF18: 仕上げ方法 | AH18: プレス・たたみ袋入れ・クワハラ検品
AF19: 製品後加工 | AH19: ワンウォッシュ
AF20: 下げ札 | AH20: なし
AF21: 縫製 | AG21: ウエスト | AH21: ベルト高 コバ+0.6cmST
B22: 附属 | D22: 表地 | E22: 芯地 | F22: 別布 | G22: フロントスナップ | H22: 隠しスナップ | K22: オープンファスナー | N22: フロントファスナー | Q22: スレキ | T22: STテープ | W22: 縫製糸 | Z22: ステッチ糸 | AC22: ピスネーム | AG22: 前股ぐり | AH22: ロック 左高
B23: A | D23: 柴屋 | F23: 柴屋 | G23: YKK | H23: YKK | K23: YKK | N23: YKK | AG23: 後股ぐり | AH23: 巻き縫い 右高 コバ+0.6cmST
C24: 黒 | D24: SB2030 | E24: 333 | F24: SB2030 | G24: パーメックスLセット | H24: パーメックスLセット | K24: 5RGK-OP | N24: 5RGK-C | Q24: 9900 | T24: 芯地切って使用 | W24: 同色 | Z24: 30番手 | AC24: c/#青 | AG24: 脇 | AH24: 巻き縫い 後高 コバ+0.6cmst
D25: c/#5 | E25: c/#黒 | F25: c/#5 | G25: ライン24 プレーンキャップ | H25: ライン24 プレーンキャップ | K25: DA8 | N25: DA8 | Q25: c/#258 | Z25: 同色 | AG25: 股下 | AH25: 巻き縫い 後高 コバ+0.6cmst
D26: 黒 | F26: 黒 | G26: c/#2610 BOX | H26: c/#2610 BOX | K26: C/#黒 | N26: C/#黒 | Q26: キナリ | AG26: 裾 | AH26: 三つ折り 1.0cm巾st
B27: 附属 | D27: 2.17 | F27: 0.53 | Q27: 0.5
B32: 附属 | AG32: 裏 | AH32: 裏無し
B33: 発注 | K33: OP c/#580 | N33: 止め c/#580 | AG33: 糸 | AH33: 地色
K34: 38c：20本 | N34: 16c：10本 | AG34: ステッチ | AH34: 30番手
G35: c/#2610 BOX | K35: 39c：10本 | N35: 17c：5本 | Q35: 20M
G36: 200セット | K36: 40c：30本 | N36: 17c：15本
K37: 41ｃ：20本 | N37: 18ｃ：10本 | AG37: 釦穴
AG38: 柄合せ | AH38: 無
B39: 附属 | AG39: さしこみ | AH39: 可 不可 組合せ 一方向 着内一方
E40: 上記参照 | F40: 前当て布 | G40: 前あき | H40: 前PK/HIP PK用 | K40: 後身頃 | N40: フロント開き | Q40: 腰ＰＫ 袋布 | T40: PK口 | AG40: 生地方向 | AH40: 並・逆
F41: 後当て布 | K41: S：38c | N41: S：16c | T41: 15mm巾 | Z41: 30番手 | AC41: 後ろ右フラップ
K42: M：39c | N42: M：17c
K43: L：40c | N43: L：17c
G44: 15.8mm | K44: XL：41ｃ | N44: XL：18ｃ
G45: 1セット | H45: 4セット | K45: 2本 | N45: 1本 | T45: 0.5M
...

Sheet 縫製仕様書(PANTS)
E2: 御中 | I2: 縫製仕様書
B3: 担当者： | E3: 様
B4: 気付： | E4: 様分
B5: ブランド | E5: 品名 | F5: パンツ | I5: 製品NO | Q5: 型紙枚数 | V5: 担当 | AB5: 数量 | AF5: サンプル・量産
B6: 亀井造園 | E6: パターンNO | F6: 22SY-65-2026量産 | I6: 仮品番 | Q6: 25PT | AB6: 納期 | AF6: 職出し
V7: 芯使用箇所 | AB7: PM | AF7: G
V8: 前PKフラップ 後PKフラップ 見返し 持出し ウエストベルト | AB8: 生地品番 | AF8: 裁断 | AH8: サイズ
AB9: 仕入先 | AL9: 計
AB10: A | AG10: A | AL10: =SUM(AH10:AK10) -> 0
AB11: B | AG11: B | AL11: =SUM(AH11:AK11) -> 0
AB12: C | AG12: C | AL12: =SUM(AH12:AK12) -> 0
AB13: D | AG13: D | AL13: =SUM(AH13:AK13) -> 0
AB14: 巾×巻M数
AB15: 混率
S16: 縫製注意点 | AB16: ネーム位置
AB17: 洗濯ネーム位置 | AD17: 左脇 ベルト付け～15㎝
AB18: 仕上げ方法
AB19: 製品後加工
AB20: 下げ札
AB21: 縫製 | AC21: ウエスト | AD21: ベルト高 コバ+0.6cmST
B22: 附属 | C22: 表地 | D22: 芯地 | E22: 別布 | F22: ドット釦 | G22: パッキン | J22: 止めＺＩＰ | M22: オープンファスナー | S22: STテープ | V22: 縫製糸 | Y22: ステッチ糸 | AC22: 前股ぐり | AD22: ロック 左高
D23: 上記参照 | E23: 前当て布 | F23: 前あき | G23: ドット釦用 | J23: 前あき | M23: 後身頃 | S23: PK口 | AC23: 後股ぐり | AD23: 巻き縫い 右高 コバ+0.6cmST
E24: 後当て布 | S24: 15mm巾 | AC24: 脇 | AD24: 巻き縫い 後高 コバ+0.6cmst
E25: 中綿キルト生地 | F25: 15.8mm | J25: ※サイズ表参照 | M25: ※サイズ表参照 | S25: 0.5M | Y25: 30番手 | AC25: 股下 | AD25: 巻き縫い 後高 コバ+0.6cmst
F26: 1セット | G26: 10個 | J26: 1本 | M26: 2本 | AC26: 裾 | AD26: 三つ折り 1.0cm巾st
B27: 附属 | C27: スレキ | E27: 隠しドット
C28: 腰ＰＫ 袋布 | E28: 前PK/HIP PK用
E31: 4セット
B32: 附属 | AC32: 裏 | AD32: 裏無し
AC33: 糸 | AD33: 地色
AC34: ステッチ | AD34: 30番手
AC35: 釦穴
AC36: 柄合せ | AD36: 無
B37: 附属 | AC37: さしこみ | AD37: 可 不可 組合せ 一方向 着内一方
AC38: 生地方向 | AD38: 並・逆

Sheet サイズ表(PANTS)
G2: 御中 | J2: 縫製仕様書
B3: 担当者： | G3: 様
B4: 気付： | G4: 様分
B5: ブランド | G5: 品名 | I5: ='縫製仕様書(PANTS)'!F5 -> パンツ | K5: 製品NO | N5: ='縫製仕様書(PANTS)'!L5 | P5: 型紙枚数 | R5: 担当 | S5: 数量 | V5: サンプル・量産
B6: ='縫製仕様書(PANTS)'!B6 -> 亀井造園 | G6: パターンNO | I6: ='縫製仕様書(PANTS)'!F6 -> 22SY-65-2026量産 | K6: 仮品番 | N6: ='縫製仕様書(PANTS)'!L6 | P6: ='縫製仕様書(PANTS)'!Q6 -> 25PT | S6: 納期 | V6: 職出し
B22: 寸法 | C22: サイズ | G22: 1ST / L | J22: 2nd | M22: S | O22: M | Q22: L(マスター) | S22: XL | V22: ピッチ
G23: 指示寸 | J23: 指示寸 | L23: 検寸 | M23: 指示寸 | N23: 検寸 | O23: 指示寸 | P23: 検寸 | Q23: 指示寸 | R23: 検寸 | S23: 指示寸 | T23: 検寸
C24: ウエスト | E24: (ゴム上がり周囲) | G24: 82 | J24: 89 | M24: 81 | O24: 85 | Q24: 89 | S24: =Q24+V24 -> 93 | V24: 4
C25: ウエスト | E25: （ゴムなし） | G25: 105
C26: ベルト巾 | G26: 4 | J26: 4 | M26: 4 | O26: 4 | Q26: 4 | S26: =Q26+V26 -> 4 | V26: 0
C27: 股上前 | E27: (ベルト抜き縫い目) | G27: 25.3 | J27: 25.3 | M27: 24.1 | O27: 24.7 | Q27: 25.3 | S27: =Q27+V27 -> 25.9 | V27: 0.6
C28: 股上後 | E28: (ベルト抜き縫い目) | G28: 43 | J28: 43 | M28: 41.4 | O28: 42.2 | Q28: 43 | S28: =Q28+V28 -> 43.8 | V28: 0.8
C29: 股上 | E29: (ベルト抜き) | G29: 23.5 | J29: 23.5 | M29: 22.5 | O29: 23 | Q29: 23.5 | S29: =Q29+V29 -> 24 | V29: 0.5
C30: ヒップ | E30: ( CL～8 ) | G30: 118 | J30: 118 | M30: 110 | O30: 114 | Q30: 118 | S30: =Q30+V30 -> 122 | V30: 4
C31: 渡り | E31: (巾寸) | G31: 39 | J31: 39 | M31: 36.4 | O31: 37.7 | Q31: 39 | S31: =Q31+V31 -> 40.3 | V31: 1.3
C32: 膝巾/最大 | E32: (巾寸)CL-36.5cm | G32: 22 | J32: 24.3/22 | M32: 22.9 | O32: 23.6 | Q32: 24.3 | S32: =Q32+V32 -> 25 | V32: 0.7
C33: 膝巾/最小 | M33: 17.6 | O33: 18.3 | Q33: 19 | S33: =Q33+V33 -> 19.7 | V33: 0.7
C34: 裾巾/最大 | E34: (巾寸) | G34: 16/13.7 | J34: 16/13.7 | M34: 15 | O34: 15.5 | Q34: 16 | S34: =Q34+V34 -> 16.5 | V34: 0.5
C35: 裾巾/最小 | E35: (巾寸) | G35: 16/13.7 | J35: 16/13.7 | M35: 12.7 | O35: 13.2 | Q35: 13.7 | S35: =Q35+V35 -> 14.2 | V35: 0.5
C36: 股下 | E36: (縫い目） | G36: 80 | J36: 80 | M36: 77 | O36: 78.5 | Q36: 80 | S36: =Q36+V36 -> 81.5 | V36: 1.5
C37: ベルトループ巾 | G37: 1.2 | S37: =Q37+V37 -> 0
C38: ベルトループ丈 | G38: 6 | S38: =Q38+V38 -> 0
C39: 後パンツオープンZIP | M39: 38 | O39: 39 | Q39: 40 | S39: =Q39+V39 -> 41 | V39: 1
C40: 前あきZIP | M40: 16 | O40: 17 | Q40: 17 | S40: 18 | V40: 1/0/1

Sheet 縫製仕様書_詳細図_2
F2: 御中 | I2: 縫製仕様書
B3: 担当者： | F3: 様
B4: 気付： | F4: 様分
B5: ブランド | F5: 品名 | G5: ='縫製仕様書(PANTS)'!F5 -> パンツ | I5: 製品NO | J5: ='縫製仕様書(PANTS)'!L5 | L5: 型紙枚数 | O5: 担当 | S5: 数量 | W5: サンプル・量産
B6: ='縫製仕様書(PANTS)'!B6 -> 亀井造園 | F6: パターンNO | G6: ='縫製仕様書(PANTS)'!F6 -> 22SY-65-2026量産 | I6: 仮品番 | J6: ='縫製仕様書(PANTS)'!L6 | L6: ='縫製仕様書(PANTS)'!Q6 -> 25PT | S6: 納期 | W6: 職出し
